2023-04-03 15:49:47,653 INFO: errors [in /Users/mnann/Documents/Code/PulseFi/src/flask/app.py:187]
2023-04-03 15:50:43,359 INFO: errors [in /Users/mnann/Documents/Code/PulseFi/src/flask/app.py:155]
2023-04-03 15:51:11,288 ERROR: Exception on /fitbit_auth [GET] [in /Users/mnann/Documents/Code/PulseFi/venv/lib/python3.8/site-packages/flask/app.py:1744]
Traceback (most recent call last):
  File "/Users/mnann/Documents/Code/PulseFi/venv/lib/python3.8/site-packages/flask/app.py", line 1823, in full_dispatch_request
    rv = self.dispatch_request()
  File "/Users/mnann/Documents/Code/PulseFi/venv/lib/python3.8/site-packages/flask/app.py", line 1788, in dispatch_request
    self.raise_routing_exception(req)
  File "/Users/mnann/Documents/Code/PulseFi/venv/lib/python3.8/site-packages/flask/app.py", line 1770, in raise_routing_exception
    raise request.routing_exception  # type: ignore
  File "/Users/mnann/Documents/Code/PulseFi/venv/lib/python3.8/site-packages/flask/ctx.py", line 351, in match_request
    result = self.url_adapter.match(return_rule=True)  # type: ignore
  File "/Users/mnann/Documents/Code/PulseFi/venv/lib/python3.8/site-packages/werkzeug/routing/map.py", line 624, in match
    raise NotFound() from None
werkzeug.exceptions.NotFound: 404 Not Found: The requested URL was not found on the server. If you entered the URL manually please check your spelling and try again.

During handling of the above exception, another exception occurred:

Traceback (most recent call last):
  File "/Users/mnann/Documents/Code/PulseFi/venv/lib/python3.8/site-packages/flask/app.py", line 2528, in wsgi_app
    response = self.full_dispatch_request()
  File "/Users/mnann/Documents/Code/PulseFi/venv/lib/python3.8/site-packages/flask/app.py", line 1825, in full_dispatch_request
    rv = self.handle_user_exception(e)
  File "/Users/mnann/Documents/Code/PulseFi/venv/lib/python3.8/site-packages/flask/app.py", line 1669, in handle_user_exception
    return self.handle_http_exception(e)
  File "/Users/mnann/Documents/Code/PulseFi/venv/lib/python3.8/site-packages/flask/app.py", line 1609, in handle_http_exception
    return self.ensure_sync(handler)(e)
  File "/Users/mnann/Documents/Code/PulseFi/src/flask/app.py", line 145, in not_found_error
    return render_template('errors/404.html'), 404
  File "/Users/mnann/Documents/Code/PulseFi/venv/lib/python3.8/site-packages/flask/templating.py", line 147, in render_template
    return _render(app, template, context)
  File "/Users/mnann/Documents/Code/PulseFi/venv/lib/python3.8/site-packages/flask/templating.py", line 130, in _render
    rv = template.render(context)
  File "/Users/mnann/Documents/Code/PulseFi/venv/lib/python3.8/site-packages/jinja2/environment.py", line 1301, in render
    self.environment.handle_exception()
  File "/Users/mnann/Documents/Code/PulseFi/venv/lib/python3.8/site-packages/jinja2/environment.py", line 936, in handle_exception
    raise rewrite_traceback_stack(source=source)
  File "/Users/mnann/Documents/Code/PulseFi/src/flask/templates/errors/404.html", line 1, in top-level template code
    {% extends 'layouts/main.html' %}
  File "/Users/mnann/Documents/Code/PulseFi/src/flask/templates/layouts/main.html", line 99, in top-level template code
    {% block content %}{% endblock %}
  File "/Users/mnann/Documents/Code/PulseFi/src/flask/templates/errors/404.html", line 5, in block 'content'
    <p><a href="{{url_for('index')}}">Back</a></p>
  File "/Users/mnann/Documents/Code/PulseFi/venv/lib/python3.8/site-packages/flask/app.py", line 2034, in url_for
    return self.handle_url_build_error(error, endpoint, values)
  File "/Users/mnann/Documents/Code/PulseFi/venv/lib/python3.8/site-packages/flask/app.py", line 2023, in url_for
    rv = url_adapter.build(  # type: ignore[union-attr]
  File "/Users/mnann/Documents/Code/PulseFi/venv/lib/python3.8/site-packages/werkzeug/routing/map.py", line 917, in build
    raise BuildError(endpoint, values, method, self)
werkzeug.routing.exceptions.BuildError: Could not build url for endpoint 'index'. Did you mean 'login' instead?
2023-04-03 15:51:21,267 ERROR: Exception on /fitbit_auth [GET] [in /Users/mnann/Documents/Code/PulseFi/venv/lib/python3.8/site-packages/flask/app.py:1744]
Traceback (most recent call last):
  File "/Users/mnann/Documents/Code/PulseFi/venv/lib/python3.8/site-packages/flask/app.py", line 1823, in full_dispatch_request
    rv = self.dispatch_request()
  File "/Users/mnann/Documents/Code/PulseFi/venv/lib/python3.8/site-packages/flask/app.py", line 1788, in dispatch_request
    self.raise_routing_exception(req)
  File "/Users/mnann/Documents/Code/PulseFi/venv/lib/python3.8/site-packages/flask/app.py", line 1770, in raise_routing_exception
    raise request.routing_exception  # type: ignore
  File "/Users/mnann/Documents/Code/PulseFi/venv/lib/python3.8/site-packages/flask/ctx.py", line 351, in match_request
    result = self.url_adapter.match(return_rule=True)  # type: ignore
  File "/Users/mnann/Documents/Code/PulseFi/venv/lib/python3.8/site-packages/werkzeug/routing/map.py", line 624, in match
    raise NotFound() from None
werkzeug.exceptions.NotFound: 404 Not Found: The requested URL was not found on the server. If you entered the URL manually please check your spelling and try again.

During handling of the above exception, another exception occurred:

Traceback (most recent call last):
  File "/Users/mnann/Documents/Code/PulseFi/venv/lib/python3.8/site-packages/flask/app.py", line 2528, in wsgi_app
    response = self.full_dispatch_request()
  File "/Users/mnann/Documents/Code/PulseFi/venv/lib/python3.8/site-packages/flask/app.py", line 1825, in full_dispatch_request
    rv = self.handle_user_exception(e)
  File "/Users/mnann/Documents/Code/PulseFi/venv/lib/python3.8/site-packages/flask/app.py", line 1669, in handle_user_exception
    return self.handle_http_exception(e)
  File "/Users/mnann/Documents/Code/PulseFi/venv/lib/python3.8/site-packages/flask/app.py", line 1609, in handle_http_exception
    return self.ensure_sync(handler)(e)
  File "/Users/mnann/Documents/Code/PulseFi/src/flask/app.py", line 145, in not_found_error
    return render_template('errors/404.html'), 404
  File "/Users/mnann/Documents/Code/PulseFi/venv/lib/python3.8/site-packages/flask/templating.py", line 147, in render_template
    return _render(app, template, context)
  File "/Users/mnann/Documents/Code/PulseFi/venv/lib/python3.8/site-packages/flask/templating.py", line 130, in _render
    rv = template.render(context)
  File "/Users/mnann/Documents/Code/PulseFi/venv/lib/python3.8/site-packages/jinja2/environment.py", line 1301, in render
    self.environment.handle_exception()
  File "/Users/mnann/Documents/Code/PulseFi/venv/lib/python3.8/site-packages/jinja2/environment.py", line 936, in handle_exception
    raise rewrite_traceback_stack(source=source)
  File "/Users/mnann/Documents/Code/PulseFi/src/flask/templates/errors/404.html", line 1, in top-level template code
    {% extends 'layouts/main.html' %}
  File "/Users/mnann/Documents/Code/PulseFi/src/flask/templates/layouts/main.html", line 99, in top-level template code
    {% block content %}{% endblock %}
  File "/Users/mnann/Documents/Code/PulseFi/src/flask/templates/errors/404.html", line 5, in block 'content'
    <p><a href="{{url_for('index')}}">Back</a></p>
  File "/Users/mnann/Documents/Code/PulseFi/venv/lib/python3.8/site-packages/flask/app.py", line 2034, in url_for
    return self.handle_url_build_error(error, endpoint, values)
  File "/Users/mnann/Documents/Code/PulseFi/venv/lib/python3.8/site-packages/flask/app.py", line 2023, in url_for
    rv = url_adapter.build(  # type: ignore[union-attr]
  File "/Users/mnann/Documents/Code/PulseFi/venv/lib/python3.8/site-packages/werkzeug/routing/map.py", line 917, in build
    raise BuildError(endpoint, values, method, self)
werkzeug.routing.exceptions.BuildError: Could not build url for endpoint 'index'. Did you mean 'login' instead?
2023-04-03 15:51:24,188 ERROR: Exception on /fitbit_auth [GET] [in /Users/mnann/Documents/Code/PulseFi/venv/lib/python3.8/site-packages/flask/app.py:1744]
Traceback (most recent call last):
  File "/Users/mnann/Documents/Code/PulseFi/venv/lib/python3.8/site-packages/flask/app.py", line 1823, in full_dispatch_request
    rv = self.dispatch_request()
  File "/Users/mnann/Documents/Code/PulseFi/venv/lib/python3.8/site-packages/flask/app.py", line 1788, in dispatch_request
    self.raise_routing_exception(req)
  File "/Users/mnann/Documents/Code/PulseFi/venv/lib/python3.8/site-packages/flask/app.py", line 1770, in raise_routing_exception
    raise request.routing_exception  # type: ignore
  File "/Users/mnann/Documents/Code/PulseFi/venv/lib/python3.8/site-packages/flask/ctx.py", line 351, in match_request
    result = self.url_adapter.match(return_rule=True)  # type: ignore
  File "/Users/mnann/Documents/Code/PulseFi/venv/lib/python3.8/site-packages/werkzeug/routing/map.py", line 624, in match
    raise NotFound() from None
werkzeug.exceptions.NotFound: 404 Not Found: The requested URL was not found on the server. If you entered the URL manually please check your spelling and try again.

During handling of the above exception, another exception occurred:

Traceback (most recent call last):
  File "/Users/mnann/Documents/Code/PulseFi/venv/lib/python3.8/site-packages/flask/app.py", line 2528, in wsgi_app
    response = self.full_dispatch_request()
  File "/Users/mnann/Documents/Code/PulseFi/venv/lib/python3.8/site-packages/flask/app.py", line 1825, in full_dispatch_request
    rv = self.handle_user_exception(e)
  File "/Users/mnann/Documents/Code/PulseFi/venv/lib/python3.8/site-packages/flask/app.py", line 1669, in handle_user_exception
    return self.handle_http_exception(e)
  File "/Users/mnann/Documents/Code/PulseFi/venv/lib/python3.8/site-packages/flask/app.py", line 1609, in handle_http_exception
    return self.ensure_sync(handler)(e)
  File "/Users/mnann/Documents/Code/PulseFi/src/flask/app.py", line 145, in not_found_error
    return render_template('errors/404.html'), 404
  File "/Users/mnann/Documents/Code/PulseFi/venv/lib/python3.8/site-packages/flask/templating.py", line 147, in render_template
    return _render(app, template, context)
  File "/Users/mnann/Documents/Code/PulseFi/venv/lib/python3.8/site-packages/flask/templating.py", line 130, in _render
    rv = template.render(context)
  File "/Users/mnann/Documents/Code/PulseFi/venv/lib/python3.8/site-packages/jinja2/environment.py", line 1301, in render
    self.environment.handle_exception()
  File "/Users/mnann/Documents/Code/PulseFi/venv/lib/python3.8/site-packages/jinja2/environment.py", line 936, in handle_exception
    raise rewrite_traceback_stack(source=source)
  File "/Users/mnann/Documents/Code/PulseFi/src/flask/templates/errors/404.html", line 1, in top-level template code
    {% extends 'layouts/main.html' %}
  File "/Users/mnann/Documents/Code/PulseFi/src/flask/templates/layouts/main.html", line 99, in top-level template code
    {% block content %}{% endblock %}
  File "/Users/mnann/Documents/Code/PulseFi/src/flask/templates/errors/404.html", line 5, in block 'content'
    <p><a href="{{url_for('index')}}">Back</a></p>
  File "/Users/mnann/Documents/Code/PulseFi/venv/lib/python3.8/site-packages/flask/app.py", line 2034, in url_for
    return self.handle_url_build_error(error, endpoint, values)
  File "/Users/mnann/Documents/Code/PulseFi/venv/lib/python3.8/site-packages/flask/app.py", line 2023, in url_for
    rv = url_adapter.build(  # type: ignore[union-attr]
  File "/Users/mnann/Documents/Code/PulseFi/venv/lib/python3.8/site-packages/werkzeug/routing/map.py", line 917, in build
    raise BuildError(endpoint, values, method, self)
werkzeug.routing.exceptions.BuildError: Could not build url for endpoint 'index'. Did you mean 'login' instead?
2023-04-03 15:51:46,486 INFO: errors [in /Users/mnann/Documents/Code/PulseFi/src/flask/app.py:155]
2023-04-03 15:59:11,962 INFO: errors [in /Users/mnann/Documents/Code/PulseFi/src/flask/app.py:145]
2023-04-03 15:59:40,103 INFO: errors [in /Users/mnann/Documents/Code/PulseFi/src/flask/app.py:145]
2023-04-03 15:59:55,806 ERROR: Exception on /heartRate [GET] [in /Users/mnann/Documents/Code/PulseFi/venv/lib/python3.8/site-packages/flask/app.py:1744]
Traceback (most recent call last):
  File "/Users/mnann/Documents/Code/PulseFi/venv/lib/python3.8/site-packages/flask/app.py", line 2528, in wsgi_app
    response = self.full_dispatch_request()
  File "/Users/mnann/Documents/Code/PulseFi/venv/lib/python3.8/site-packages/flask/app.py", line 1825, in full_dispatch_request
    rv = self.handle_user_exception(e)
  File "/Users/mnann/Documents/Code/PulseFi/venv/lib/python3.8/site-packages/flask/app.py", line 1823, in full_dispatch_request
    rv = self.dispatch_request()
  File "/Users/mnann/Documents/Code/PulseFi/venv/lib/python3.8/site-packages/flask/app.py", line 1799, in dispatch_request
    return self.ensure_sync(self.view_functions[rule.endpoint])(**view_args)
  File "/Users/mnann/Documents/Code/PulseFi/src/data/callbacks.py", line 101, in heartRate
    df_heartRate = self.getHeartRateData()
  File "/Users/mnann/Documents/Code/PulseFi/src/data/callbacks.py", line 64, in getHeartRateData
    ACCESS_TOKEN=str(self.fitbit.client.session.token['access_token'])
KeyError: 'access_token'
2023-04-03 16:00:07,549 ERROR: Exception on /heartRate [GET] [in /Users/mnann/Documents/Code/PulseFi/venv/lib/python3.8/site-packages/flask/app.py:1744]
Traceback (most recent call last):
  File "/Users/mnann/Documents/Code/PulseFi/venv/lib/python3.8/site-packages/flask/app.py", line 2528, in wsgi_app
    response = self.full_dispatch_request()
  File "/Users/mnann/Documents/Code/PulseFi/venv/lib/python3.8/site-packages/flask/app.py", line 1825, in full_dispatch_request
    rv = self.handle_user_exception(e)
  File "/Users/mnann/Documents/Code/PulseFi/venv/lib/python3.8/site-packages/flask/app.py", line 1823, in full_dispatch_request
    rv = self.dispatch_request()
  File "/Users/mnann/Documents/Code/PulseFi/venv/lib/python3.8/site-packages/flask/app.py", line 1799, in dispatch_request
    return self.ensure_sync(self.view_functions[rule.endpoint])(**view_args)
  File "/Users/mnann/Documents/Code/PulseFi/src/data/callbacks.py", line 101, in heartRate
    df_heartRate = self.getHeartRateData()
  File "/Users/mnann/Documents/Code/PulseFi/src/data/callbacks.py", line 64, in getHeartRateData
    ACCESS_TOKEN=str(self.fitbit.client.session.token['access_token'])
KeyError: 'access_token'
2023-04-03 16:00:58,304 INFO: errors [in /Users/mnann/Documents/Code/PulseFi/src/flask/app.py:145]
2023-04-03 16:01:05,880 ERROR: Exception on /heartRate [GET] [in /Users/mnann/Documents/Code/PulseFi/venv/lib/python3.8/site-packages/flask/app.py:1744]
Traceback (most recent call last):
  File "/Users/mnann/Documents/Code/PulseFi/venv/lib/python3.8/site-packages/flask/app.py", line 2528, in wsgi_app
    response = self.full_dispatch_request()
  File "/Users/mnann/Documents/Code/PulseFi/venv/lib/python3.8/site-packages/flask/app.py", line 1825, in full_dispatch_request
    rv = self.handle_user_exception(e)
  File "/Users/mnann/Documents/Code/PulseFi/venv/lib/python3.8/site-packages/flask/app.py", line 1823, in full_dispatch_request
    rv = self.dispatch_request()
  File "/Users/mnann/Documents/Code/PulseFi/venv/lib/python3.8/site-packages/flask/app.py", line 1799, in dispatch_request
    return self.ensure_sync(self.view_functions[rule.endpoint])(**view_args)
  File "/Users/mnann/Documents/Code/PulseFi/src/data/callbacks.py", line 104, in heartRate
    df_heartRate = self.getHeartRateData()
  File "/Users/mnann/Documents/Code/PulseFi/src/data/callbacks.py", line 66, in getHeartRateData
    ACCESS_TOKEN=str(self.fitbit.client.session.token['access_token'])
KeyError: 'access_token'
2023-04-03 16:02:54,164 INFO: errors [in /Users/mnann/Documents/Code/PulseFi/src/flask/app.py:145]
2023-04-03 16:03:18,069 ERROR: Exception on /heartRate [GET] [in /Users/mnann/Documents/Code/PulseFi/venv/lib/python3.8/site-packages/flask/app.py:1744]
Traceback (most recent call last):
  File "/Users/mnann/Documents/Code/PulseFi/venv/lib/python3.8/site-packages/flask/app.py", line 2528, in wsgi_app
    response = self.full_dispatch_request()
  File "/Users/mnann/Documents/Code/PulseFi/venv/lib/python3.8/site-packages/flask/app.py", line 1825, in full_dispatch_request
    rv = self.handle_user_exception(e)
  File "/Users/mnann/Documents/Code/PulseFi/venv/lib/python3.8/site-packages/flask/app.py", line 1823, in full_dispatch_request
    rv = self.dispatch_request()
  File "/Users/mnann/Documents/Code/PulseFi/venv/lib/python3.8/site-packages/flask/app.py", line 1799, in dispatch_request
    return self.ensure_sync(self.view_functions[rule.endpoint])(**view_args)
  File "/Users/mnann/Documents/Code/PulseFi/src/data/callbacks.py", line 105, in heartRate
    df_heartRate = self.getHeartRateData()
  File "/Users/mnann/Documents/Code/PulseFi/src/data/callbacks.py", line 66, in getHeartRateData
    ACCESS_TOKEN=str(self.fitbit.client.session.token['access_token'])
KeyError: 'access_token'
2023-04-03 16:03:57,232 INFO: errors [in /Users/mnann/Documents/Code/PulseFi/src/flask/app.py:145]
2023-04-03 16:04:05,928 ERROR: Exception on /heartRate [GET] [in /Users/mnann/Documents/Code/PulseFi/venv/lib/python3.8/site-packages/flask/app.py:1744]
Traceback (most recent call last):
  File "/Users/mnann/Documents/Code/PulseFi/venv/lib/python3.8/site-packages/flask/app.py", line 2528, in wsgi_app
    response = self.full_dispatch_request()
  File "/Users/mnann/Documents/Code/PulseFi/venv/lib/python3.8/site-packages/flask/app.py", line 1825, in full_dispatch_request
    rv = self.handle_user_exception(e)
  File "/Users/mnann/Documents/Code/PulseFi/venv/lib/python3.8/site-packages/flask/app.py", line 1823, in full_dispatch_request
    rv = self.dispatch_request()
  File "/Users/mnann/Documents/Code/PulseFi/venv/lib/python3.8/site-packages/flask/app.py", line 1799, in dispatch_request
    return self.ensure_sync(self.view_functions[rule.endpoint])(**view_args)
  File "/Users/mnann/Documents/Code/PulseFi/src/data/callbacks.py", line 108, in heartRate
    df_heartRate = self.getHeartRateData()
  File "/Users/mnann/Documents/Code/PulseFi/src/data/callbacks.py", line 66, in getHeartRateData
    ACCESS_TOKEN=str(self.fitbit.client.session.token['access_token'])
KeyError: 'access_token'
2023-04-03 16:06:07,018 INFO: errors [in /Users/mnann/Documents/Code/PulseFi/src/flask/app.py:145]
2023-04-03 16:06:17,058 ERROR: Exception on /heartRate [GET] [in /Users/mnann/Documents/Code/PulseFi/venv/lib/python3.8/site-packages/flask/app.py:1744]
Traceback (most recent call last):
  File "/Users/mnann/Documents/Code/PulseFi/venv/lib/python3.8/site-packages/flask/app.py", line 2528, in wsgi_app
    response = self.full_dispatch_request()
  File "/Users/mnann/Documents/Code/PulseFi/venv/lib/python3.8/site-packages/flask/app.py", line 1825, in full_dispatch_request
    rv = self.handle_user_exception(e)
  File "/Users/mnann/Documents/Code/PulseFi/venv/lib/python3.8/site-packages/flask/app.py", line 1823, in full_dispatch_request
    rv = self.dispatch_request()
  File "/Users/mnann/Documents/Code/PulseFi/venv/lib/python3.8/site-packages/flask/app.py", line 1799, in dispatch_request
    return self.ensure_sync(self.view_functions[rule.endpoint])(**view_args)
  File "/Users/mnann/Documents/Code/PulseFi/src/data/callbacks.py", line 113, in heartRate
    df_heartRate = self.getHeartRateData()
  File "/Users/mnann/Documents/Code/PulseFi/src/data/callbacks.py", line 66, in getHeartRateData
    ACCESS_TOKEN=str(self.fitbit.client.session.token['access_token'])
KeyError: 'access_token'
2023-04-03 16:07:25,854 INFO: errors [in /Users/mnann/Documents/Code/PulseFi/src/flask/app.py:145]
2023-04-03 16:07:31,335 ERROR: Exception on /heartRate [GET] [in /Users/mnann/Documents/Code/PulseFi/venv/lib/python3.8/site-packages/flask/app.py:1744]
Traceback (most recent call last):
  File "/Users/mnann/Documents/Code/PulseFi/venv/lib/python3.8/site-packages/flask/app.py", line 2528, in wsgi_app
    response = self.full_dispatch_request()
  File "/Users/mnann/Documents/Code/PulseFi/venv/lib/python3.8/site-packages/flask/app.py", line 1825, in full_dispatch_request
    rv = self.handle_user_exception(e)
  File "/Users/mnann/Documents/Code/PulseFi/venv/lib/python3.8/site-packages/flask/app.py", line 1823, in full_dispatch_request
    rv = self.dispatch_request()
  File "/Users/mnann/Documents/Code/PulseFi/venv/lib/python3.8/site-packages/flask/app.py", line 1799, in dispatch_request
    return self.ensure_sync(self.view_functions[rule.endpoint])(**view_args)
  File "/Users/mnann/Documents/Code/PulseFi/src/data/callbacks.py", line 110, in heartRate
    df_heartRate = self.getHeartRateData()
  File "/Users/mnann/Documents/Code/PulseFi/src/data/callbacks.py", line 68, in getHeartRateData
    auth2_client=Fitbit(self.client_id,self.client_secret,oauth2=True,access_token=self.ACCESS_TOKEN,refresh_token=self.REFRESH_TOKEN)
AttributeError: 'FitbitAuth' object has no attribute 'ACCESS_TOKEN'
2023-04-03 16:11:34,620 INFO: errors [in /Users/mnann/Documents/Code/PulseFi/src/flask/app.py:145]
2023-04-03 16:11:43,413 ERROR: Exception on /heartRate [GET] [in /Users/mnann/Documents/Code/PulseFi/venv/lib/python3.8/site-packages/flask/app.py:1744]
Traceback (most recent call last):
  File "/Users/mnann/Documents/Code/PulseFi/venv/lib/python3.8/site-packages/flask/app.py", line 2528, in wsgi_app
    response = self.full_dispatch_request()
  File "/Users/mnann/Documents/Code/PulseFi/venv/lib/python3.8/site-packages/flask/app.py", line 1825, in full_dispatch_request
    rv = self.handle_user_exception(e)
  File "/Users/mnann/Documents/Code/PulseFi/venv/lib/python3.8/site-packages/flask/app.py", line 1823, in full_dispatch_request
    rv = self.dispatch_request()
  File "/Users/mnann/Documents/Code/PulseFi/venv/lib/python3.8/site-packages/flask/app.py", line 1799, in dispatch_request
    return self.ensure_sync(self.view_functions[rule.endpoint])(**view_args)
  File "/Users/mnann/Documents/Code/PulseFi/src/data/callbacks.py", line 109, in heartRate
    df_heartRate = self.getHeartRateData()
  File "/Users/mnann/Documents/Code/PulseFi/src/data/callbacks.py", line 68, in getHeartRateData
    auth2_client=Fitbit(self.client_id,self.client_secret,oauth2=True,access_token=self.ACCESS_TOKEN,refresh_token=self.REFRESH_TOKEN)
AttributeError: 'FitbitAuth' object has no attribute 'ACCESS_TOKEN'
2023-04-03 16:13:37,090 INFO: errors [in /Users/mnann/Documents/Code/PulseFi/src/flask/app.py:145]
2023-04-03 16:13:42,090 ERROR: Exception on /heartRate [GET] [in /Users/mnann/Documents/Code/PulseFi/venv/lib/python3.8/site-packages/flask/app.py:1744]
Traceback (most recent call last):
  File "/Users/mnann/Documents/Code/PulseFi/venv/lib/python3.8/site-packages/flask/app.py", line 2528, in wsgi_app
    response = self.full_dispatch_request()
  File "/Users/mnann/Documents/Code/PulseFi/venv/lib/python3.8/site-packages/flask/app.py", line 1825, in full_dispatch_request
    rv = self.handle_user_exception(e)
  File "/Users/mnann/Documents/Code/PulseFi/venv/lib/python3.8/site-packages/flask/app.py", line 1823, in full_dispatch_request
    rv = self.dispatch_request()
  File "/Users/mnann/Documents/Code/PulseFi/venv/lib/python3.8/site-packages/flask/app.py", line 1799, in dispatch_request
    return self.ensure_sync(self.view_functions[rule.endpoint])(**view_args)
  File "/Users/mnann/Documents/Code/PulseFi/src/data/callbacks.py", line 110, in heartRate
    df_heartRate = self.getHeartRateData()
  File "/Users/mnann/Documents/Code/PulseFi/src/data/callbacks.py", line 68, in getHeartRateData
    auth2_client=Fitbit(self.client_id,self.client_secret,oauth2=True,access_token=self.ACCESS_TOKEN,refresh_token=self.REFRESH_TOKEN)
AttributeError: 'FitbitAuth' object has no attribute 'ACCESS_TOKEN'
2023-04-03 16:14:51,716 INFO: errors [in /Users/mnann/Documents/Code/PulseFi/src/flask/app.py:145]
2023-04-03 16:14:54,362 ERROR: Exception on /heartRate [GET] [in /Users/mnann/Documents/Code/PulseFi/venv/lib/python3.8/site-packages/flask/app.py:1744]
Traceback (most recent call last):
  File "/Users/mnann/Documents/Code/PulseFi/venv/lib/python3.8/site-packages/flask/app.py", line 2528, in wsgi_app
    response = self.full_dispatch_request()
  File "/Users/mnann/Documents/Code/PulseFi/venv/lib/python3.8/site-packages/flask/app.py", line 1825, in full_dispatch_request
    rv = self.handle_user_exception(e)
  File "/Users/mnann/Documents/Code/PulseFi/venv/lib/python3.8/site-packages/flask/app.py", line 1823, in full_dispatch_request
    rv = self.dispatch_request()
  File "/Users/mnann/Documents/Code/PulseFi/venv/lib/python3.8/site-packages/flask/app.py", line 1799, in dispatch_request
    return self.ensure_sync(self.view_functions[rule.endpoint])(**view_args)
  File "/Users/mnann/Documents/Code/PulseFi/src/data/callbacks.py", line 109, in heartRate
    df_heartRate = self.getHeartRateData()
  File "/Users/mnann/Documents/Code/PulseFi/src/data/callbacks.py", line 68, in getHeartRateData
    auth2_client=Fitbit(self.client_id,self.client_secret,oauth2=True,access_token=self.ACCESS_TOKEN,refresh_token=self.REFRESH_TOKEN)
AttributeError: 'FitbitAuth' object has no attribute 'ACCESS_TOKEN'
2023-04-03 16:15:20,490 INFO: errors [in /Users/mnann/Documents/Code/PulseFi/src/flask/app.py:145]
2023-04-03 16:15:23,804 ERROR: Exception on /heartRate [GET] [in /Users/mnann/Documents/Code/PulseFi/venv/lib/python3.8/site-packages/flask/app.py:1744]
Traceback (most recent call last):
  File "/Users/mnann/Documents/Code/PulseFi/venv/lib/python3.8/site-packages/flask/app.py", line 2528, in wsgi_app
    response = self.full_dispatch_request()
  File "/Users/mnann/Documents/Code/PulseFi/venv/lib/python3.8/site-packages/flask/app.py", line 1825, in full_dispatch_request
    rv = self.handle_user_exception(e)
  File "/Users/mnann/Documents/Code/PulseFi/venv/lib/python3.8/site-packages/flask/app.py", line 1823, in full_dispatch_request
    rv = self.dispatch_request()
  File "/Users/mnann/Documents/Code/PulseFi/venv/lib/python3.8/site-packages/flask/app.py", line 1799, in dispatch_request
    return self.ensure_sync(self.view_functions[rule.endpoint])(**view_args)
  File "/Users/mnann/Documents/Code/PulseFi/src/data/callbacks.py", line 110, in heartRate
    df_heartRate = self.getHeartRateData()
  File "/Users/mnann/Documents/Code/PulseFi/src/data/callbacks.py", line 68, in getHeartRateData
    auth2_client=Fitbit(self.client_id,self.client_secret,oauth2=True,access_token=self.ACCESS_TOKEN,refresh_token=self.REFRESH_TOKEN)
AttributeError: 'FitbitAuth' object has no attribute 'ACCESS_TOKEN'
2023-04-03 16:16:08,365 INFO: errors [in /Users/mnann/Documents/Code/PulseFi/src/flask/app.py:145]
2023-04-03 16:16:09,659 ERROR: Exception on /heartRate [GET] [in /Users/mnann/Documents/Code/PulseFi/venv/lib/python3.8/site-packages/flask/app.py:1744]
Traceback (most recent call last):
  File "/Users/mnann/Documents/Code/PulseFi/venv/lib/python3.8/site-packages/flask/app.py", line 2528, in wsgi_app
    response = self.full_dispatch_request()
  File "/Users/mnann/Documents/Code/PulseFi/venv/lib/python3.8/site-packages/flask/app.py", line 1825, in full_dispatch_request
    rv = self.handle_user_exception(e)
  File "/Users/mnann/Documents/Code/PulseFi/venv/lib/python3.8/site-packages/flask/app.py", line 1823, in full_dispatch_request
    rv = self.dispatch_request()
  File "/Users/mnann/Documents/Code/PulseFi/venv/lib/python3.8/site-packages/flask/app.py", line 1799, in dispatch_request
    return self.ensure_sync(self.view_functions[rule.endpoint])(**view_args)
  File "/Users/mnann/Documents/Code/PulseFi/src/data/callbacks.py", line 111, in heartRate
    df_heartRate = self.getHeartRateData()
  File "/Users/mnann/Documents/Code/PulseFi/src/data/callbacks.py", line 68, in getHeartRateData
    auth2_client=Fitbit(self.client_id,self.client_secret,oauth2=True,access_token=self.ACCESS_TOKEN,refresh_token=self.REFRESH_TOKEN)
AttributeError: 'FitbitAuth' object has no attribute 'ACCESS_TOKEN'
2023-04-03 16:18:58,350 INFO: errors [in /Users/mnann/Documents/Code/PulseFi/src/flask/app.py:145]
2023-04-03 16:19:00,217 ERROR: Exception on /heartRate [GET] [in /Users/mnann/Documents/Code/PulseFi/venv/lib/python3.8/site-packages/flask/app.py:1744]
Traceback (most recent call last):
  File "/Users/mnann/Documents/Code/PulseFi/venv/lib/python3.8/site-packages/flask/app.py", line 2528, in wsgi_app
    response = self.full_dispatch_request()
  File "/Users/mnann/Documents/Code/PulseFi/venv/lib/python3.8/site-packages/flask/app.py", line 1825, in full_dispatch_request
    rv = self.handle_user_exception(e)
  File "/Users/mnann/Documents/Code/PulseFi/venv/lib/python3.8/site-packages/flask/app.py", line 1823, in full_dispatch_request
    rv = self.dispatch_request()
  File "/Users/mnann/Documents/Code/PulseFi/venv/lib/python3.8/site-packages/flask/app.py", line 1799, in dispatch_request
    return self.ensure_sync(self.view_functions[rule.endpoint])(**view_args)
  File "/Users/mnann/Documents/Code/PulseFi/src/data/callbacks.py", line 111, in heartRate
    df_heartRate = self.getHeartRateData()
  File "/Users/mnann/Documents/Code/PulseFi/src/data/callbacks.py", line 68, in getHeartRateData
    auth2_client=Fitbit(self.client_id,self.client_secret,oauth2=True,access_token=self.ACCESS_TOKEN,refresh_token=self.REFRESH_TOKEN)
AttributeError: 'FitbitAuth' object has no attribute 'ACCESS_TOKEN'
2023-04-03 16:19:02,008 ERROR: Exception on /heartRate [GET] [in /Users/mnann/Documents/Code/PulseFi/venv/lib/python3.8/site-packages/flask/app.py:1744]
Traceback (most recent call last):
  File "/Users/mnann/Documents/Code/PulseFi/venv/lib/python3.8/site-packages/flask/app.py", line 2528, in wsgi_app
    response = self.full_dispatch_request()
  File "/Users/mnann/Documents/Code/PulseFi/venv/lib/python3.8/site-packages/flask/app.py", line 1825, in full_dispatch_request
    rv = self.handle_user_exception(e)
  File "/Users/mnann/Documents/Code/PulseFi/venv/lib/python3.8/site-packages/flask/app.py", line 1823, in full_dispatch_request
    rv = self.dispatch_request()
  File "/Users/mnann/Documents/Code/PulseFi/venv/lib/python3.8/site-packages/flask/app.py", line 1799, in dispatch_request
    return self.ensure_sync(self.view_functions[rule.endpoint])(**view_args)
  File "/Users/mnann/Documents/Code/PulseFi/src/data/callbacks.py", line 111, in heartRate
    df_heartRate = self.getHeartRateData()
  File "/Users/mnann/Documents/Code/PulseFi/src/data/callbacks.py", line 70, in getHeartRateData
    heart_rate_data = auth2_client.intraday_time_series('activities/heart', detail_level='1sec', base_date='2023-04-02')
  File "/Users/mnann/Documents/Code/PulseFi/venv/lib/python3.8/site-packages/fitbit/api.py", line 592, in intraday_time_series
    return self.make_request(url)
  File "/Users/mnann/Documents/Code/PulseFi/venv/lib/python3.8/site-packages/fitbit/api.py", line 256, in make_request
    response = self.client.make_request(*args, **kwargs)
  File "/Users/mnann/Documents/Code/PulseFi/venv/lib/python3.8/site-packages/fitbit/api.py", line 99, in make_request
    exceptions.detect_and_raise_error(response)
  File "/Users/mnann/Documents/Code/PulseFi/venv/lib/python3.8/site-packages/fitbit/exceptions.py", line 82, in detect_and_raise_error
    raise HTTPUnauthorized(response)
fitbit.exceptions.HTTPUnauthorized: Access token invalid: e95784e6c1e33adf677f396e8356eaaf68df639d. Visit https://dev.fitbit.com/docs/oauth2 for more information on the Fitbit Web API authorization process.
2023-04-03 16:19:03,507 ERROR: Exception on /heartRate [GET] [in /Users/mnann/Documents/Code/PulseFi/venv/lib/python3.8/site-packages/flask/app.py:1744]
Traceback (most recent call last):
  File "/Users/mnann/Documents/Code/PulseFi/venv/lib/python3.8/site-packages/flask/app.py", line 2528, in wsgi_app
    response = self.full_dispatch_request()
  File "/Users/mnann/Documents/Code/PulseFi/venv/lib/python3.8/site-packages/flask/app.py", line 1825, in full_dispatch_request
    rv = self.handle_user_exception(e)
  File "/Users/mnann/Documents/Code/PulseFi/venv/lib/python3.8/site-packages/flask/app.py", line 1823, in full_dispatch_request
    rv = self.dispatch_request()
  File "/Users/mnann/Documents/Code/PulseFi/venv/lib/python3.8/site-packages/flask/app.py", line 1799, in dispatch_request
    return self.ensure_sync(self.view_functions[rule.endpoint])(**view_args)
  File "/Users/mnann/Documents/Code/PulseFi/src/data/callbacks.py", line 111, in heartRate
    df_heartRate = self.getHeartRateData()
  File "/Users/mnann/Documents/Code/PulseFi/src/data/callbacks.py", line 70, in getHeartRateData
    heart_rate_data = auth2_client.intraday_time_series('activities/heart', detail_level='1sec', base_date='2023-04-02')
  File "/Users/mnann/Documents/Code/PulseFi/venv/lib/python3.8/site-packages/fitbit/api.py", line 592, in intraday_time_series
    return self.make_request(url)
  File "/Users/mnann/Documents/Code/PulseFi/venv/lib/python3.8/site-packages/fitbit/api.py", line 256, in make_request
    response = self.client.make_request(*args, **kwargs)
  File "/Users/mnann/Documents/Code/PulseFi/venv/lib/python3.8/site-packages/fitbit/api.py", line 99, in make_request
    exceptions.detect_and_raise_error(response)
  File "/Users/mnann/Documents/Code/PulseFi/venv/lib/python3.8/site-packages/fitbit/exceptions.py", line 82, in detect_and_raise_error
    raise HTTPUnauthorized(response)
fitbit.exceptions.HTTPUnauthorized: Access token invalid: 4536514192d9fd55e31d5cfccc8e40b278b5d4f7. Visit https://dev.fitbit.com/docs/oauth2 for more information on the Fitbit Web API authorization process.
2023-04-03 16:19:05,009 ERROR: Exception on /heartRate [GET] [in /Users/mnann/Documents/Code/PulseFi/venv/lib/python3.8/site-packages/flask/app.py:1744]
Traceback (most recent call last):
  File "/Users/mnann/Documents/Code/PulseFi/venv/lib/python3.8/site-packages/flask/app.py", line 2528, in wsgi_app
    response = self.full_dispatch_request()
  File "/Users/mnann/Documents/Code/PulseFi/venv/lib/python3.8/site-packages/flask/app.py", line 1825, in full_dispatch_request
    rv = self.handle_user_exception(e)
  File "/Users/mnann/Documents/Code/PulseFi/venv/lib/python3.8/site-packages/flask/app.py", line 1823, in full_dispatch_request
    rv = self.dispatch_request()
  File "/Users/mnann/Documents/Code/PulseFi/venv/lib/python3.8/site-packages/flask/app.py", line 1799, in dispatch_request
    return self.ensure_sync(self.view_functions[rule.endpoint])(**view_args)
  File "/Users/mnann/Documents/Code/PulseFi/src/data/callbacks.py", line 111, in heartRate
    df_heartRate = self.getHeartRateData()
  File "/Users/mnann/Documents/Code/PulseFi/src/data/callbacks.py", line 70, in getHeartRateData
    heart_rate_data = auth2_client.intraday_time_series('activities/heart', detail_level='1sec', base_date='2023-04-02')
  File "/Users/mnann/Documents/Code/PulseFi/venv/lib/python3.8/site-packages/fitbit/api.py", line 592, in intraday_time_series
    return self.make_request(url)
  File "/Users/mnann/Documents/Code/PulseFi/venv/lib/python3.8/site-packages/fitbit/api.py", line 256, in make_request
    response = self.client.make_request(*args, **kwargs)
  File "/Users/mnann/Documents/Code/PulseFi/venv/lib/python3.8/site-packages/fitbit/api.py", line 99, in make_request
    exceptions.detect_and_raise_error(response)
  File "/Users/mnann/Documents/Code/PulseFi/venv/lib/python3.8/site-packages/fitbit/exceptions.py", line 82, in detect_and_raise_error
    raise HTTPUnauthorized(response)
fitbit.exceptions.HTTPUnauthorized: Access token invalid: 00867a5c1a963b45bb5fa70b0218897a87cfc708. Visit https://dev.fitbit.com/docs/oauth2 for more information on the Fitbit Web API authorization process.
2023-04-03 16:19:06,603 ERROR: Exception on /heartRate [GET] [in /Users/mnann/Documents/Code/PulseFi/venv/lib/python3.8/site-packages/flask/app.py:1744]
Traceback (most recent call last):
  File "/Users/mnann/Documents/Code/PulseFi/venv/lib/python3.8/site-packages/flask/app.py", line 2528, in wsgi_app
    response = self.full_dispatch_request()
  File "/Users/mnann/Documents/Code/PulseFi/venv/lib/python3.8/site-packages/flask/app.py", line 1825, in full_dispatch_request
    rv = self.handle_user_exception(e)
  File "/Users/mnann/Documents/Code/PulseFi/venv/lib/python3.8/site-packages/flask/app.py", line 1823, in full_dispatch_request
    rv = self.dispatch_request()
  File "/Users/mnann/Documents/Code/PulseFi/venv/lib/python3.8/site-packages/flask/app.py", line 1799, in dispatch_request
    return self.ensure_sync(self.view_functions[rule.endpoint])(**view_args)
  File "/Users/mnann/Documents/Code/PulseFi/src/data/callbacks.py", line 111, in heartRate
    df_heartRate = self.getHeartRateData()
  File "/Users/mnann/Documents/Code/PulseFi/src/data/callbacks.py", line 70, in getHeartRateData
    heart_rate_data = auth2_client.intraday_time_series('activities/heart', detail_level='1sec', base_date='2023-04-02')
  File "/Users/mnann/Documents/Code/PulseFi/venv/lib/python3.8/site-packages/fitbit/api.py", line 592, in intraday_time_series
    return self.make_request(url)
  File "/Users/mnann/Documents/Code/PulseFi/venv/lib/python3.8/site-packages/fitbit/api.py", line 256, in make_request
    response = self.client.make_request(*args, **kwargs)
  File "/Users/mnann/Documents/Code/PulseFi/venv/lib/python3.8/site-packages/fitbit/api.py", line 99, in make_request
    exceptions.detect_and_raise_error(response)
  File "/Users/mnann/Documents/Code/PulseFi/venv/lib/python3.8/site-packages/fitbit/exceptions.py", line 82, in detect_and_raise_error
    raise HTTPUnauthorized(response)
fitbit.exceptions.HTTPUnauthorized: Access token invalid: 52195f1f9c0d62262b19c57e82a2740f3ac06ecb. Visit https://dev.fitbit.com/docs/oauth2 for more information on the Fitbit Web API authorization process.
2023-04-03 16:19:08,108 ERROR: Exception on /heartRate [GET] [in /Users/mnann/Documents/Code/PulseFi/venv/lib/python3.8/site-packages/flask/app.py:1744]
Traceback (most recent call last):
  File "/Users/mnann/Documents/Code/PulseFi/venv/lib/python3.8/site-packages/flask/app.py", line 2528, in wsgi_app
    response = self.full_dispatch_request()
  File "/Users/mnann/Documents/Code/PulseFi/venv/lib/python3.8/site-packages/flask/app.py", line 1825, in full_dispatch_request
    rv = self.handle_user_exception(e)
  File "/Users/mnann/Documents/Code/PulseFi/venv/lib/python3.8/site-packages/flask/app.py", line 1823, in full_dispatch_request
    rv = self.dispatch_request()
  File "/Users/mnann/Documents/Code/PulseFi/venv/lib/python3.8/site-packages/flask/app.py", line 1799, in dispatch_request
    return self.ensure_sync(self.view_functions[rule.endpoint])(**view_args)
  File "/Users/mnann/Documents/Code/PulseFi/src/data/callbacks.py", line 111, in heartRate
    df_heartRate = self.getHeartRateData()
  File "/Users/mnann/Documents/Code/PulseFi/src/data/callbacks.py", line 70, in getHeartRateData
    heart_rate_data = auth2_client.intraday_time_series('activities/heart', detail_level='1sec', base_date='2023-04-02')
  File "/Users/mnann/Documents/Code/PulseFi/venv/lib/python3.8/site-packages/fitbit/api.py", line 592, in intraday_time_series
    return self.make_request(url)
  File "/Users/mnann/Documents/Code/PulseFi/venv/lib/python3.8/site-packages/fitbit/api.py", line 256, in make_request
    response = self.client.make_request(*args, **kwargs)
  File "/Users/mnann/Documents/Code/PulseFi/venv/lib/python3.8/site-packages/fitbit/api.py", line 99, in make_request
    exceptions.detect_and_raise_error(response)
  File "/Users/mnann/Documents/Code/PulseFi/venv/lib/python3.8/site-packages/fitbit/exceptions.py", line 82, in detect_and_raise_error
    raise HTTPUnauthorized(response)
fitbit.exceptions.HTTPUnauthorized: Access token invalid: 21f1ed4ad092fbf0cd21a41acf2e7fb4b0636b64. Visit https://dev.fitbit.com/docs/oauth2 for more information on the Fitbit Web API authorization process.
2023-04-03 16:19:09,691 ERROR: Exception on /heartRate [GET] [in /Users/mnann/Documents/Code/PulseFi/venv/lib/python3.8/site-packages/flask/app.py:1744]
Traceback (most recent call last):
  File "/Users/mnann/Documents/Code/PulseFi/venv/lib/python3.8/site-packages/flask/app.py", line 2528, in wsgi_app
    response = self.full_dispatch_request()
  File "/Users/mnann/Documents/Code/PulseFi/venv/lib/python3.8/site-packages/flask/app.py", line 1825, in full_dispatch_request
    rv = self.handle_user_exception(e)
  File "/Users/mnann/Documents/Code/PulseFi/venv/lib/python3.8/site-packages/flask/app.py", line 1823, in full_dispatch_request
    rv = self.dispatch_request()
  File "/Users/mnann/Documents/Code/PulseFi/venv/lib/python3.8/site-packages/flask/app.py", line 1799, in dispatch_request
    return self.ensure_sync(self.view_functions[rule.endpoint])(**view_args)
  File "/Users/mnann/Documents/Code/PulseFi/src/data/callbacks.py", line 111, in heartRate
    df_heartRate = self.getHeartRateData()
  File "/Users/mnann/Documents/Code/PulseFi/src/data/callbacks.py", line 70, in getHeartRateData
    heart_rate_data = auth2_client.intraday_time_series('activities/heart', detail_level='1sec', base_date='2023-04-02')
  File "/Users/mnann/Documents/Code/PulseFi/venv/lib/python3.8/site-packages/fitbit/api.py", line 592, in intraday_time_series
    return self.make_request(url)
  File "/Users/mnann/Documents/Code/PulseFi/venv/lib/python3.8/site-packages/fitbit/api.py", line 256, in make_request
    response = self.client.make_request(*args, **kwargs)
  File "/Users/mnann/Documents/Code/PulseFi/venv/lib/python3.8/site-packages/fitbit/api.py", line 99, in make_request
    exceptions.detect_and_raise_error(response)
  File "/Users/mnann/Documents/Code/PulseFi/venv/lib/python3.8/site-packages/fitbit/exceptions.py", line 82, in detect_and_raise_error
    raise HTTPUnauthorized(response)
fitbit.exceptions.HTTPUnauthorized: Access token invalid: e507d400465f6d542fcd6e0aa8a8efdc47b0cc12. Visit https://dev.fitbit.com/docs/oauth2 for more information on the Fitbit Web API authorization process.
2023-04-03 16:19:11,228 ERROR: Exception on /heartRate [GET] [in /Users/mnann/Documents/Code/PulseFi/venv/lib/python3.8/site-packages/flask/app.py:1744]
Traceback (most recent call last):
  File "/Users/mnann/Documents/Code/PulseFi/venv/lib/python3.8/site-packages/flask/app.py", line 2528, in wsgi_app
    response = self.full_dispatch_request()
  File "/Users/mnann/Documents/Code/PulseFi/venv/lib/python3.8/site-packages/flask/app.py", line 1825, in full_dispatch_request
    rv = self.handle_user_exception(e)
  File "/Users/mnann/Documents/Code/PulseFi/venv/lib/python3.8/site-packages/flask/app.py", line 1823, in full_dispatch_request
    rv = self.dispatch_request()
  File "/Users/mnann/Documents/Code/PulseFi/venv/lib/python3.8/site-packages/flask/app.py", line 1799, in dispatch_request
    return self.ensure_sync(self.view_functions[rule.endpoint])(**view_args)
  File "/Users/mnann/Documents/Code/PulseFi/src/data/callbacks.py", line 111, in heartRate
    df_heartRate = self.getHeartRateData()
  File "/Users/mnann/Documents/Code/PulseFi/src/data/callbacks.py", line 70, in getHeartRateData
    heart_rate_data = auth2_client.intraday_time_series('activities/heart', detail_level='1sec', base_date='2023-04-02')
  File "/Users/mnann/Documents/Code/PulseFi/venv/lib/python3.8/site-packages/fitbit/api.py", line 592, in intraday_time_series
    return self.make_request(url)
  File "/Users/mnann/Documents/Code/PulseFi/venv/lib/python3.8/site-packages/fitbit/api.py", line 256, in make_request
    response = self.client.make_request(*args, **kwargs)
  File "/Users/mnann/Documents/Code/PulseFi/venv/lib/python3.8/site-packages/fitbit/api.py", line 99, in make_request
    exceptions.detect_and_raise_error(response)
  File "/Users/mnann/Documents/Code/PulseFi/venv/lib/python3.8/site-packages/fitbit/exceptions.py", line 82, in detect_and_raise_error
    raise HTTPUnauthorized(response)
fitbit.exceptions.HTTPUnauthorized: Access token invalid: 59a80b8e3ab4cad0f48466d83127075830f14c81. Visit https://dev.fitbit.com/docs/oauth2 for more information on the Fitbit Web API authorization process.
2023-04-03 16:32:58,788 INFO: errors [in /Users/mnann/Documents/Code/PulseFi/src/flask/app.py:145]
2023-04-03 16:33:55,190 INFO: errors [in /Users/mnann/Documents/Code/PulseFi/src/flask/app.py:145]
2023-04-03 16:34:04,202 ERROR: Exception on /heartRate [GET] [in /Users/mnann/Documents/Code/PulseFi/venv/lib/python3.8/site-packages/flask/app.py:1744]
Traceback (most recent call last):
  File "/Users/mnann/Documents/Code/PulseFi/venv/lib/python3.8/site-packages/flask/app.py", line 2528, in wsgi_app
    response = self.full_dispatch_request()
  File "/Users/mnann/Documents/Code/PulseFi/venv/lib/python3.8/site-packages/flask/app.py", line 1825, in full_dispatch_request
    rv = self.handle_user_exception(e)
  File "/Users/mnann/Documents/Code/PulseFi/venv/lib/python3.8/site-packages/flask/app.py", line 1823, in full_dispatch_request
    rv = self.dispatch_request()
  File "/Users/mnann/Documents/Code/PulseFi/venv/lib/python3.8/site-packages/flask/app.py", line 1799, in dispatch_request
    return self.ensure_sync(self.view_functions[rule.endpoint])(**view_args)
  File "/Users/mnann/Documents/Code/PulseFi/src/data/callbacks.py", line 65, in heartRate
    auth2_client=Fitbit(self.client_id,self.client_secret,oauth2=True,access_token=ACCESS_TOKEN,refresh_token=REFRESH_TOKEN)
AttributeError: 'FitbitAuth' object has no attribute 'client_id'
2023-04-03 16:35:58,984 INFO: errors [in /Users/mnann/Documents/Code/PulseFi/src/flask/app.py:145]
2023-04-03 16:36:28,710 ERROR: Exception on /heartRate [GET] [in /Users/mnann/Documents/Code/PulseFi/venv/lib/python3.8/site-packages/flask/app.py:1744]
Traceback (most recent call last):
  File "/Users/mnann/Documents/Code/PulseFi/venv/lib/python3.8/site-packages/flask/app.py", line 2528, in wsgi_app
    response = self.full_dispatch_request()
  File "/Users/mnann/Documents/Code/PulseFi/venv/lib/python3.8/site-packages/flask/app.py", line 1825, in full_dispatch_request
    rv = self.handle_user_exception(e)
  File "/Users/mnann/Documents/Code/PulseFi/venv/lib/python3.8/site-packages/flask/app.py", line 1823, in full_dispatch_request
    rv = self.dispatch_request()
  File "/Users/mnann/Documents/Code/PulseFi/venv/lib/python3.8/site-packages/flask/app.py", line 1799, in dispatch_request
    return self.ensure_sync(self.view_functions[rule.endpoint])(**view_args)
  File "/Users/mnann/Documents/Code/PulseFi/src/data/callbacks.py", line 67, in heartRate
    ACCESS_TOKEN, REFRESH_TOKEN = retrieve_OAuth_FitBit_Tokens()
  File "/Users/mnann/Documents/Code/PulseFi/src/data/gather_keys_oauth2.py", line 90, in retrieve_OAuth_FitBit_Tokens
    ACCESS_TOKEN=str(server.fitbit.client.session.token['access_token'])
KeyError: 'access_token'
2023-04-03 16:41:31,168 INFO: errors [in /Users/mnann/Documents/Code/PulseFi/src/flask/app.py:145]
2023-04-03 16:41:58,644 ERROR: Exception on /heartRate [GET] [in /Users/mnann/Documents/Code/PulseFi/venv/lib/python3.8/site-packages/flask/app.py:1744]
Traceback (most recent call last):
  File "/Users/mnann/Documents/Code/PulseFi/venv/lib/python3.8/site-packages/flask/app.py", line 2528, in wsgi_app
    response = self.full_dispatch_request()
  File "/Users/mnann/Documents/Code/PulseFi/venv/lib/python3.8/site-packages/flask/app.py", line 1825, in full_dispatch_request
    rv = self.handle_user_exception(e)
  File "/Users/mnann/Documents/Code/PulseFi/venv/lib/python3.8/site-packages/flask/app.py", line 1823, in full_dispatch_request
    rv = self.dispatch_request()
  File "/Users/mnann/Documents/Code/PulseFi/venv/lib/python3.8/site-packages/flask/app.py", line 1799, in dispatch_request
    return self.ensure_sync(self.view_functions[rule.endpoint])(**view_args)
  File "/Users/mnann/Documents/Code/PulseFi/src/data/callbacks.py", line 68, in heartRate
    ACCESS_TOKEN, REFRESH_TOKEN = retrieve_OAuth_FitBit_Tokens()
  File "/Users/mnann/Documents/Code/PulseFi/src/data/gather_keys_oauth2.py", line 90, in retrieve_OAuth_FitBit_Tokens
    ACCESS_TOKEN=str(server.fitbit.client.session.token['access_token'])
KeyError: 'access_token'
2023-04-03 16:43:59,607 INFO: errors [in /Users/mnann/Documents/Code/PulseFi/src/flask/app.py:145]
2023-04-03 16:48:47,305 ERROR: Exception on /heartRate [GET] [in /Users/mnann/Documents/Code/PulseFi/venv/lib/python3.8/site-packages/flask/app.py:1744]
Traceback (most recent call last):
  File "/Users/mnann/Documents/Code/PulseFi/venv/lib/python3.8/site-packages/flask/app.py", line 2528, in wsgi_app
    response = self.full_dispatch_request()
  File "/Users/mnann/Documents/Code/PulseFi/venv/lib/python3.8/site-packages/flask/app.py", line 1825, in full_dispatch_request
    rv = self.handle_user_exception(e)
  File "/Users/mnann/Documents/Code/PulseFi/venv/lib/python3.8/site-packages/flask/app.py", line 1823, in full_dispatch_request
    rv = self.dispatch_request()
  File "/Users/mnann/Documents/Code/PulseFi/venv/lib/python3.8/site-packages/flask/app.py", line 1799, in dispatch_request
    return self.ensure_sync(self.view_functions[rule.endpoint])(**view_args)
  File "/Users/mnann/Documents/Code/PulseFi/src/data/callbacks.py", line 68, in heartRate
    ACCESS_TOKEN, REFRESH_TOKEN = retrieve_OAuth_FitBit_Tokens()
  File "/Users/mnann/Documents/Code/PulseFi/src/data/gather_keys_oauth2.py", line 90, in retrieve_OAuth_FitBit_Tokens
    ACCESS_TOKEN=str(server.fitbit.client.session.token['access_token'])
KeyError: 'access_token'
2023-04-03 16:48:55,287 ERROR: Exception on /heartRate [GET] [in /Users/mnann/Documents/Code/PulseFi/venv/lib/python3.8/site-packages/flask/app.py:1744]
Traceback (most recent call last):
  File "/Users/mnann/Documents/Code/PulseFi/venv/lib/python3.8/site-packages/flask/app.py", line 2528, in wsgi_app
    response = self.full_dispatch_request()
  File "/Users/mnann/Documents/Code/PulseFi/venv/lib/python3.8/site-packages/flask/app.py", line 1825, in full_dispatch_request
    rv = self.handle_user_exception(e)
  File "/Users/mnann/Documents/Code/PulseFi/venv/lib/python3.8/site-packages/flask/app.py", line 1823, in full_dispatch_request
    rv = self.dispatch_request()
  File "/Users/mnann/Documents/Code/PulseFi/venv/lib/python3.8/site-packages/flask/app.py", line 1799, in dispatch_request
    return self.ensure_sync(self.view_functions[rule.endpoint])(**view_args)
  File "/Users/mnann/Documents/Code/PulseFi/src/data/callbacks.py", line 68, in heartRate
    ACCESS_TOKEN, REFRESH_TOKEN = retrieve_OAuth_FitBit_Tokens()
  File "/Users/mnann/Documents/Code/PulseFi/src/data/gather_keys_oauth2.py", line 90, in retrieve_OAuth_FitBit_Tokens
    ACCESS_TOKEN=str(server.fitbit.client.session.token['access_token'])
KeyError: 'access_token'
2023-04-03 16:49:40,323 INFO: errors [in /Users/mnann/Documents/Code/PulseFi/src/flask/app.py:145]
2023-04-03 16:50:11,268 ERROR: Exception on /heartRate [GET] [in /Users/mnann/Documents/Code/PulseFi/venv/lib/python3.8/site-packages/flask/app.py:1744]
Traceback (most recent call last):
  File "/Users/mnann/Documents/Code/PulseFi/venv/lib/python3.8/site-packages/flask/app.py", line 2528, in wsgi_app
    response = self.full_dispatch_request()
  File "/Users/mnann/Documents/Code/PulseFi/venv/lib/python3.8/site-packages/flask/app.py", line 1825, in full_dispatch_request
    rv = self.handle_user_exception(e)
  File "/Users/mnann/Documents/Code/PulseFi/venv/lib/python3.8/site-packages/flask/app.py", line 1823, in full_dispatch_request
    rv = self.dispatch_request()
  File "/Users/mnann/Documents/Code/PulseFi/venv/lib/python3.8/site-packages/flask/app.py", line 1799, in dispatch_request
    return self.ensure_sync(self.view_functions[rule.endpoint])(**view_args)
  File "/Users/mnann/Documents/Code/PulseFi/src/data/callbacks.py", line 68, in heartRate
    ACCESS_TOKEN, REFRESH_TOKEN = retrieve_OAuth_FitBit_Tokens()
  File "/Users/mnann/Documents/Code/PulseFi/src/data/gather_keys_oauth2.py", line 91, in retrieve_OAuth_FitBit_Tokens
    ACCESS_TOKEN=str(server.fitbit.client.session.token['access_token'])
KeyError: 'access_token'
2023-04-03 16:53:20,689 INFO: errors [in /Users/mnann/Documents/Code/PulseFi/src/flask/app.py:145]
2023-04-03 16:56:07,942 INFO: errors [in /Users/mnann/Documents/Code/PulseFi/src/flask/app.py:145]
2023-04-03 16:56:30,825 ERROR: Exception on /heartRate [GET] [in /Users/mnann/Documents/Code/PulseFi/venv/lib/python3.8/site-packages/flask/app.py:1744]
Traceback (most recent call last):
  File "/Users/mnann/Documents/Code/PulseFi/venv/lib/python3.8/site-packages/flask/app.py", line 2528, in wsgi_app
    response = self.full_dispatch_request()
  File "/Users/mnann/Documents/Code/PulseFi/venv/lib/python3.8/site-packages/flask/app.py", line 1825, in full_dispatch_request
    rv = self.handle_user_exception(e)
  File "/Users/mnann/Documents/Code/PulseFi/venv/lib/python3.8/site-packages/flask/app.py", line 1823, in full_dispatch_request
    rv = self.dispatch_request()
  File "/Users/mnann/Documents/Code/PulseFi/venv/lib/python3.8/site-packages/flask/app.py", line 1799, in dispatch_request
    return self.ensure_sync(self.view_functions[rule.endpoint])(**view_args)
  File "/Users/mnann/Documents/Code/PulseFi/src/data/callbacks.py", line 68, in heartRate
    ACCESS_TOKEN, REFRESH_TOKEN = retrieve_OAuth_FitBit_Tokens()
  File "/Users/mnann/Documents/Code/PulseFi/src/data/gather_keys_oauth2.py", line 91, in retrieve_OAuth_FitBit_Tokens
    ACCESS_TOKEN=str(server.fitbit.client.session.token['access_token'])
KeyError: 'access_token'
2023-04-03 16:58:32,478 INFO: errors [in /Users/mnann/Documents/Code/PulseFi/src/flask/app.py:145]
2023-04-03 16:58:38,565 ERROR: Exception on /heartRate [GET] [in /Users/mnann/Documents/Code/PulseFi/venv/lib/python3.8/site-packages/flask/app.py:1744]
Traceback (most recent call last):
  File "/Users/mnann/Documents/Code/PulseFi/venv/lib/python3.8/site-packages/flask/app.py", line 2528, in wsgi_app
    response = self.full_dispatch_request()
  File "/Users/mnann/Documents/Code/PulseFi/venv/lib/python3.8/site-packages/flask/app.py", line 1825, in full_dispatch_request
    rv = self.handle_user_exception(e)
  File "/Users/mnann/Documents/Code/PulseFi/venv/lib/python3.8/site-packages/flask/app.py", line 1823, in full_dispatch_request
    rv = self.dispatch_request()
  File "/Users/mnann/Documents/Code/PulseFi/venv/lib/python3.8/site-packages/flask/app.py", line 1799, in dispatch_request
    return self.ensure_sync(self.view_functions[rule.endpoint])(**view_args)
  File "/Users/mnann/Documents/Code/PulseFi/src/data/callbacks.py", line 77, in heartRate
    ACCESS_TOKEN, REFRESH_TOKEN = retrieve_OAuth_FitBit_Tokens()
NameError: name 'retrieve_OAuth_FitBit_Tokens' is not defined
2023-04-03 16:58:43,678 ERROR: Exception on /heartRate [GET] [in /Users/mnann/Documents/Code/PulseFi/venv/lib/python3.8/site-packages/flask/app.py:1744]
Traceback (most recent call last):
  File "/Users/mnann/Documents/Code/PulseFi/venv/lib/python3.8/site-packages/flask/app.py", line 2528, in wsgi_app
    response = self.full_dispatch_request()
  File "/Users/mnann/Documents/Code/PulseFi/venv/lib/python3.8/site-packages/flask/app.py", line 1825, in full_dispatch_request
    rv = self.handle_user_exception(e)
  File "/Users/mnann/Documents/Code/PulseFi/venv/lib/python3.8/site-packages/flask/app.py", line 1823, in full_dispatch_request
    rv = self.dispatch_request()
  File "/Users/mnann/Documents/Code/PulseFi/venv/lib/python3.8/site-packages/flask/app.py", line 1799, in dispatch_request
    return self.ensure_sync(self.view_functions[rule.endpoint])(**view_args)
  File "/Users/mnann/Documents/Code/PulseFi/src/data/callbacks.py", line 77, in heartRate
    ACCESS_TOKEN, REFRESH_TOKEN = retrieve_OAuth_FitBit_Tokens()
NameError: name 'retrieve_OAuth_FitBit_Tokens' is not defined
2023-04-03 16:58:47,794 ERROR: Exception on /heartRate [GET] [in /Users/mnann/Documents/Code/PulseFi/venv/lib/python3.8/site-packages/flask/app.py:1744]
Traceback (most recent call last):
  File "/Users/mnann/Documents/Code/PulseFi/venv/lib/python3.8/site-packages/flask/app.py", line 2528, in wsgi_app
    response = self.full_dispatch_request()
  File "/Users/mnann/Documents/Code/PulseFi/venv/lib/python3.8/site-packages/flask/app.py", line 1825, in full_dispatch_request
    rv = self.handle_user_exception(e)
  File "/Users/mnann/Documents/Code/PulseFi/venv/lib/python3.8/site-packages/flask/app.py", line 1823, in full_dispatch_request
    rv = self.dispatch_request()
  File "/Users/mnann/Documents/Code/PulseFi/venv/lib/python3.8/site-packages/flask/app.py", line 1799, in dispatch_request
    return self.ensure_sync(self.view_functions[rule.endpoint])(**view_args)
  File "/Users/mnann/Documents/Code/PulseFi/src/data/callbacks.py", line 77, in heartRate
    ACCESS_TOKEN, REFRESH_TOKEN = retrieve_OAuth_FitBit_Tokens()
NameError: name 'retrieve_OAuth_FitBit_Tokens' is not defined
2023-04-03 16:59:02,153 INFO: errors [in /Users/mnann/Documents/Code/PulseFi/src/flask/app.py:145]
2023-04-03 16:59:36,217 INFO: errors [in /Users/mnann/Documents/Code/PulseFi/src/flask/app.py:145]
2023-04-03 17:00:49,139 INFO: errors [in /Users/mnann/Documents/Code/PulseFi/src/flask/app.py:145]
2023-04-03 17:01:13,708 INFO: errors [in /Users/mnann/Documents/Code/PulseFi/src/flask/app.py:145]
2023-04-03 17:03:17,355 ERROR: Exception on /fitbit_auth [GET] [in /Users/mnann/Documents/Code/PulseFi/venv/lib/python3.8/site-packages/flask/app.py:1744]
Traceback (most recent call last):
  File "/Users/mnann/Documents/Code/PulseFi/venv/lib/python3.8/site-packages/flask/app.py", line 1823, in full_dispatch_request
    rv = self.dispatch_request()
  File "/Users/mnann/Documents/Code/PulseFi/venv/lib/python3.8/site-packages/flask/app.py", line 1788, in dispatch_request
    self.raise_routing_exception(req)
  File "/Users/mnann/Documents/Code/PulseFi/venv/lib/python3.8/site-packages/flask/app.py", line 1770, in raise_routing_exception
    raise request.routing_exception  # type: ignore
  File "/Users/mnann/Documents/Code/PulseFi/venv/lib/python3.8/site-packages/flask/ctx.py", line 351, in match_request
    result = self.url_adapter.match(return_rule=True)  # type: ignore
  File "/Users/mnann/Documents/Code/PulseFi/venv/lib/python3.8/site-packages/werkzeug/routing/map.py", line 624, in match
    raise NotFound() from None
werkzeug.exceptions.NotFound: 404 Not Found: The requested URL was not found on the server. If you entered the URL manually please check your spelling and try again.

During handling of the above exception, another exception occurred:

Traceback (most recent call last):
  File "/Users/mnann/Documents/Code/PulseFi/venv/lib/python3.8/site-packages/flask/app.py", line 2528, in wsgi_app
    response = self.full_dispatch_request()
  File "/Users/mnann/Documents/Code/PulseFi/venv/lib/python3.8/site-packages/flask/app.py", line 1825, in full_dispatch_request
    rv = self.handle_user_exception(e)
  File "/Users/mnann/Documents/Code/PulseFi/venv/lib/python3.8/site-packages/flask/app.py", line 1669, in handle_user_exception
    return self.handle_http_exception(e)
  File "/Users/mnann/Documents/Code/PulseFi/venv/lib/python3.8/site-packages/flask/app.py", line 1609, in handle_http_exception
    return self.ensure_sync(handler)(e)
  File "/Users/mnann/Documents/Code/PulseFi/src/flask/app.py", line 130, in not_found_error
    return render_template('errors/404.html'), 404
  File "/Users/mnann/Documents/Code/PulseFi/venv/lib/python3.8/site-packages/flask/templating.py", line 147, in render_template
    return _render(app, template, context)
  File "/Users/mnann/Documents/Code/PulseFi/venv/lib/python3.8/site-packages/flask/templating.py", line 130, in _render
    rv = template.render(context)
  File "/Users/mnann/Documents/Code/PulseFi/venv/lib/python3.8/site-packages/jinja2/environment.py", line 1301, in render
    self.environment.handle_exception()
  File "/Users/mnann/Documents/Code/PulseFi/venv/lib/python3.8/site-packages/jinja2/environment.py", line 936, in handle_exception
    raise rewrite_traceback_stack(source=source)
  File "/Users/mnann/Documents/Code/PulseFi/src/flask/templates/errors/404.html", line 1, in top-level template code
    {% extends 'layouts/main.html' %}
  File "/Users/mnann/Documents/Code/PulseFi/src/flask/templates/layouts/main.html", line 99, in top-level template code
    {% block content %}{% endblock %}
  File "/Users/mnann/Documents/Code/PulseFi/src/flask/templates/errors/404.html", line 5, in block 'content'
    <p><a href="{{url_for('index')}}">Back</a></p>
  File "/Users/mnann/Documents/Code/PulseFi/venv/lib/python3.8/site-packages/flask/app.py", line 2034, in url_for
    return self.handle_url_build_error(error, endpoint, values)
  File "/Users/mnann/Documents/Code/PulseFi/venv/lib/python3.8/site-packages/flask/app.py", line 2023, in url_for
    rv = url_adapter.build(  # type: ignore[union-attr]
  File "/Users/mnann/Documents/Code/PulseFi/venv/lib/python3.8/site-packages/werkzeug/routing/map.py", line 917, in build
    raise BuildError(endpoint, values, method, self)
werkzeug.routing.exceptions.BuildError: Could not build url for endpoint 'index'. Did you mean 'login' instead?
2023-04-03 17:03:32,587 ERROR: Exception on /fitbit_auth [GET] [in /Users/mnann/Documents/Code/PulseFi/venv/lib/python3.8/site-packages/flask/app.py:1744]
Traceback (most recent call last):
  File "/Users/mnann/Documents/Code/PulseFi/venv/lib/python3.8/site-packages/flask/app.py", line 1823, in full_dispatch_request
    rv = self.dispatch_request()
  File "/Users/mnann/Documents/Code/PulseFi/venv/lib/python3.8/site-packages/flask/app.py", line 1788, in dispatch_request
    self.raise_routing_exception(req)
  File "/Users/mnann/Documents/Code/PulseFi/venv/lib/python3.8/site-packages/flask/app.py", line 1770, in raise_routing_exception
    raise request.routing_exception  # type: ignore
  File "/Users/mnann/Documents/Code/PulseFi/venv/lib/python3.8/site-packages/flask/ctx.py", line 351, in match_request
    result = self.url_adapter.match(return_rule=True)  # type: ignore
  File "/Users/mnann/Documents/Code/PulseFi/venv/lib/python3.8/site-packages/werkzeug/routing/map.py", line 624, in match
    raise NotFound() from None
werkzeug.exceptions.NotFound: 404 Not Found: The requested URL was not found on the server. If you entered the URL manually please check your spelling and try again.

During handling of the above exception, another exception occurred:

Traceback (most recent call last):
  File "/Users/mnann/Documents/Code/PulseFi/venv/lib/python3.8/site-packages/flask/app.py", line 2528, in wsgi_app
    response = self.full_dispatch_request()
  File "/Users/mnann/Documents/Code/PulseFi/venv/lib/python3.8/site-packages/flask/app.py", line 1825, in full_dispatch_request
    rv = self.handle_user_exception(e)
  File "/Users/mnann/Documents/Code/PulseFi/venv/lib/python3.8/site-packages/flask/app.py", line 1669, in handle_user_exception
    return self.handle_http_exception(e)
  File "/Users/mnann/Documents/Code/PulseFi/venv/lib/python3.8/site-packages/flask/app.py", line 1609, in handle_http_exception
    return self.ensure_sync(handler)(e)
  File "/Users/mnann/Documents/Code/PulseFi/src/flask/app.py", line 130, in not_found_error
    return render_template('errors/404.html'), 404
  File "/Users/mnann/Documents/Code/PulseFi/venv/lib/python3.8/site-packages/flask/templating.py", line 147, in render_template
    return _render(app, template, context)
  File "/Users/mnann/Documents/Code/PulseFi/venv/lib/python3.8/site-packages/flask/templating.py", line 130, in _render
    rv = template.render(context)
  File "/Users/mnann/Documents/Code/PulseFi/venv/lib/python3.8/site-packages/jinja2/environment.py", line 1301, in render
    self.environment.handle_exception()
  File "/Users/mnann/Documents/Code/PulseFi/venv/lib/python3.8/site-packages/jinja2/environment.py", line 936, in handle_exception
    raise rewrite_traceback_stack(source=source)
  File "/Users/mnann/Documents/Code/PulseFi/src/flask/templates/errors/404.html", line 1, in top-level template code
    {% extends 'layouts/main.html' %}
  File "/Users/mnann/Documents/Code/PulseFi/src/flask/templates/layouts/main.html", line 99, in top-level template code
    {% block content %}{% endblock %}
  File "/Users/mnann/Documents/Code/PulseFi/src/flask/templates/errors/404.html", line 5, in block 'content'
    <p><a href="{{url_for('index')}}">Back</a></p>
  File "/Users/mnann/Documents/Code/PulseFi/venv/lib/python3.8/site-packages/flask/app.py", line 2034, in url_for
    return self.handle_url_build_error(error, endpoint, values)
  File "/Users/mnann/Documents/Code/PulseFi/venv/lib/python3.8/site-packages/flask/app.py", line 2023, in url_for
    rv = url_adapter.build(  # type: ignore[union-attr]
  File "/Users/mnann/Documents/Code/PulseFi/venv/lib/python3.8/site-packages/werkzeug/routing/map.py", line 917, in build
    raise BuildError(endpoint, values, method, self)
werkzeug.routing.exceptions.BuildError: Could not build url for endpoint 'index'. Did you mean 'login' instead?
2023-04-03 17:03:35,095 ERROR: Exception on /fitbit_auth [GET] [in /Users/mnann/Documents/Code/PulseFi/venv/lib/python3.8/site-packages/flask/app.py:1744]
Traceback (most recent call last):
  File "/Users/mnann/Documents/Code/PulseFi/venv/lib/python3.8/site-packages/flask/app.py", line 1823, in full_dispatch_request
    rv = self.dispatch_request()
  File "/Users/mnann/Documents/Code/PulseFi/venv/lib/python3.8/site-packages/flask/app.py", line 1788, in dispatch_request
    self.raise_routing_exception(req)
  File "/Users/mnann/Documents/Code/PulseFi/venv/lib/python3.8/site-packages/flask/app.py", line 1770, in raise_routing_exception
    raise request.routing_exception  # type: ignore
  File "/Users/mnann/Documents/Code/PulseFi/venv/lib/python3.8/site-packages/flask/ctx.py", line 351, in match_request
    result = self.url_adapter.match(return_rule=True)  # type: ignore
  File "/Users/mnann/Documents/Code/PulseFi/venv/lib/python3.8/site-packages/werkzeug/routing/map.py", line 624, in match
    raise NotFound() from None
werkzeug.exceptions.NotFound: 404 Not Found: The requested URL was not found on the server. If you entered the URL manually please check your spelling and try again.

During handling of the above exception, another exception occurred:

Traceback (most recent call last):
  File "/Users/mnann/Documents/Code/PulseFi/venv/lib/python3.8/site-packages/flask/app.py", line 2528, in wsgi_app
    response = self.full_dispatch_request()
  File "/Users/mnann/Documents/Code/PulseFi/venv/lib/python3.8/site-packages/flask/app.py", line 1825, in full_dispatch_request
    rv = self.handle_user_exception(e)
  File "/Users/mnann/Documents/Code/PulseFi/venv/lib/python3.8/site-packages/flask/app.py", line 1669, in handle_user_exception
    return self.handle_http_exception(e)
  File "/Users/mnann/Documents/Code/PulseFi/venv/lib/python3.8/site-packages/flask/app.py", line 1609, in handle_http_exception
    return self.ensure_sync(handler)(e)
  File "/Users/mnann/Documents/Code/PulseFi/src/flask/app.py", line 130, in not_found_error
    return render_template('errors/404.html'), 404
  File "/Users/mnann/Documents/Code/PulseFi/venv/lib/python3.8/site-packages/flask/templating.py", line 147, in render_template
    return _render(app, template, context)
  File "/Users/mnann/Documents/Code/PulseFi/venv/lib/python3.8/site-packages/flask/templating.py", line 130, in _render
    rv = template.render(context)
  File "/Users/mnann/Documents/Code/PulseFi/venv/lib/python3.8/site-packages/jinja2/environment.py", line 1301, in render
    self.environment.handle_exception()
  File "/Users/mnann/Documents/Code/PulseFi/venv/lib/python3.8/site-packages/jinja2/environment.py", line 936, in handle_exception
    raise rewrite_traceback_stack(source=source)
  File "/Users/mnann/Documents/Code/PulseFi/src/flask/templates/errors/404.html", line 1, in top-level template code
    {% extends 'layouts/main.html' %}
  File "/Users/mnann/Documents/Code/PulseFi/src/flask/templates/layouts/main.html", line 99, in top-level template code
    {% block content %}{% endblock %}
  File "/Users/mnann/Documents/Code/PulseFi/src/flask/templates/errors/404.html", line 5, in block 'content'
    <p><a href="{{url_for('index')}}">Back</a></p>
  File "/Users/mnann/Documents/Code/PulseFi/venv/lib/python3.8/site-packages/flask/app.py", line 2034, in url_for
    return self.handle_url_build_error(error, endpoint, values)
  File "/Users/mnann/Documents/Code/PulseFi/venv/lib/python3.8/site-packages/flask/app.py", line 2023, in url_for
    rv = url_adapter.build(  # type: ignore[union-attr]
  File "/Users/mnann/Documents/Code/PulseFi/venv/lib/python3.8/site-packages/werkzeug/routing/map.py", line 917, in build
    raise BuildError(endpoint, values, method, self)
werkzeug.routing.exceptions.BuildError: Could not build url for endpoint 'index'. Did you mean 'login' instead?
2023-04-03 17:03:38,050 ERROR: Exception on /fitbit_auth [GET] [in /Users/mnann/Documents/Code/PulseFi/venv/lib/python3.8/site-packages/flask/app.py:1744]
Traceback (most recent call last):
  File "/Users/mnann/Documents/Code/PulseFi/venv/lib/python3.8/site-packages/flask/app.py", line 1823, in full_dispatch_request
    rv = self.dispatch_request()
  File "/Users/mnann/Documents/Code/PulseFi/venv/lib/python3.8/site-packages/flask/app.py", line 1788, in dispatch_request
    self.raise_routing_exception(req)
  File "/Users/mnann/Documents/Code/PulseFi/venv/lib/python3.8/site-packages/flask/app.py", line 1770, in raise_routing_exception
    raise request.routing_exception  # type: ignore
  File "/Users/mnann/Documents/Code/PulseFi/venv/lib/python3.8/site-packages/flask/ctx.py", line 351, in match_request
    result = self.url_adapter.match(return_rule=True)  # type: ignore
  File "/Users/mnann/Documents/Code/PulseFi/venv/lib/python3.8/site-packages/werkzeug/routing/map.py", line 624, in match
    raise NotFound() from None
werkzeug.exceptions.NotFound: 404 Not Found: The requested URL was not found on the server. If you entered the URL manually please check your spelling and try again.

During handling of the above exception, another exception occurred:

Traceback (most recent call last):
  File "/Users/mnann/Documents/Code/PulseFi/venv/lib/python3.8/site-packages/flask/app.py", line 2528, in wsgi_app
    response = self.full_dispatch_request()
  File "/Users/mnann/Documents/Code/PulseFi/venv/lib/python3.8/site-packages/flask/app.py", line 1825, in full_dispatch_request
    rv = self.handle_user_exception(e)
  File "/Users/mnann/Documents/Code/PulseFi/venv/lib/python3.8/site-packages/flask/app.py", line 1669, in handle_user_exception
    return self.handle_http_exception(e)
  File "/Users/mnann/Documents/Code/PulseFi/venv/lib/python3.8/site-packages/flask/app.py", line 1609, in handle_http_exception
    return self.ensure_sync(handler)(e)
  File "/Users/mnann/Documents/Code/PulseFi/src/flask/app.py", line 130, in not_found_error
    return render_template('errors/404.html'), 404
  File "/Users/mnann/Documents/Code/PulseFi/venv/lib/python3.8/site-packages/flask/templating.py", line 147, in render_template
    return _render(app, template, context)
  File "/Users/mnann/Documents/Code/PulseFi/venv/lib/python3.8/site-packages/flask/templating.py", line 130, in _render
    rv = template.render(context)
  File "/Users/mnann/Documents/Code/PulseFi/venv/lib/python3.8/site-packages/jinja2/environment.py", line 1301, in render
    self.environment.handle_exception()
  File "/Users/mnann/Documents/Code/PulseFi/venv/lib/python3.8/site-packages/jinja2/environment.py", line 936, in handle_exception
    raise rewrite_traceback_stack(source=source)
  File "/Users/mnann/Documents/Code/PulseFi/src/flask/templates/errors/404.html", line 1, in top-level template code
    {% extends 'layouts/main.html' %}
  File "/Users/mnann/Documents/Code/PulseFi/src/flask/templates/layouts/main.html", line 99, in top-level template code
    {% block content %}{% endblock %}
  File "/Users/mnann/Documents/Code/PulseFi/src/flask/templates/errors/404.html", line 5, in block 'content'
    <p><a href="{{url_for('index')}}">Back</a></p>
  File "/Users/mnann/Documents/Code/PulseFi/venv/lib/python3.8/site-packages/flask/app.py", line 2034, in url_for
    return self.handle_url_build_error(error, endpoint, values)
  File "/Users/mnann/Documents/Code/PulseFi/venv/lib/python3.8/site-packages/flask/app.py", line 2023, in url_for
    rv = url_adapter.build(  # type: ignore[union-attr]
  File "/Users/mnann/Documents/Code/PulseFi/venv/lib/python3.8/site-packages/werkzeug/routing/map.py", line 917, in build
    raise BuildError(endpoint, values, method, self)
werkzeug.routing.exceptions.BuildError: Could not build url for endpoint 'index'. Did you mean 'login' instead?
2023-04-03 17:04:04,869 ERROR: Exception on /d [GET] [in /Users/mnann/Documents/Code/PulseFi/venv/lib/python3.8/site-packages/flask/app.py:1744]
Traceback (most recent call last):
  File "/Users/mnann/Documents/Code/PulseFi/venv/lib/python3.8/site-packages/flask/app.py", line 1823, in full_dispatch_request
    rv = self.dispatch_request()
  File "/Users/mnann/Documents/Code/PulseFi/venv/lib/python3.8/site-packages/flask/app.py", line 1788, in dispatch_request
    self.raise_routing_exception(req)
  File "/Users/mnann/Documents/Code/PulseFi/venv/lib/python3.8/site-packages/flask/app.py", line 1770, in raise_routing_exception
    raise request.routing_exception  # type: ignore
  File "/Users/mnann/Documents/Code/PulseFi/venv/lib/python3.8/site-packages/flask/ctx.py", line 351, in match_request
    result = self.url_adapter.match(return_rule=True)  # type: ignore
  File "/Users/mnann/Documents/Code/PulseFi/venv/lib/python3.8/site-packages/werkzeug/routing/map.py", line 624, in match
    raise NotFound() from None
werkzeug.exceptions.NotFound: 404 Not Found: The requested URL was not found on the server. If you entered the URL manually please check your spelling and try again.

During handling of the above exception, another exception occurred:

Traceback (most recent call last):
  File "/Users/mnann/Documents/Code/PulseFi/venv/lib/python3.8/site-packages/flask/app.py", line 2528, in wsgi_app
    response = self.full_dispatch_request()
  File "/Users/mnann/Documents/Code/PulseFi/venv/lib/python3.8/site-packages/flask/app.py", line 1825, in full_dispatch_request
    rv = self.handle_user_exception(e)
  File "/Users/mnann/Documents/Code/PulseFi/venv/lib/python3.8/site-packages/flask/app.py", line 1669, in handle_user_exception
    return self.handle_http_exception(e)
  File "/Users/mnann/Documents/Code/PulseFi/venv/lib/python3.8/site-packages/flask/app.py", line 1609, in handle_http_exception
    return self.ensure_sync(handler)(e)
  File "/Users/mnann/Documents/Code/PulseFi/src/flask/app.py", line 130, in not_found_error
    return render_template('errors/404.html'), 404
  File "/Users/mnann/Documents/Code/PulseFi/venv/lib/python3.8/site-packages/flask/templating.py", line 147, in render_template
    return _render(app, template, context)
  File "/Users/mnann/Documents/Code/PulseFi/venv/lib/python3.8/site-packages/flask/templating.py", line 130, in _render
    rv = template.render(context)
  File "/Users/mnann/Documents/Code/PulseFi/venv/lib/python3.8/site-packages/jinja2/environment.py", line 1301, in render
    self.environment.handle_exception()
  File "/Users/mnann/Documents/Code/PulseFi/venv/lib/python3.8/site-packages/jinja2/environment.py", line 936, in handle_exception
    raise rewrite_traceback_stack(source=source)
  File "/Users/mnann/Documents/Code/PulseFi/src/flask/templates/errors/404.html", line 1, in top-level template code
    {% extends 'layouts/main.html' %}
  File "/Users/mnann/Documents/Code/PulseFi/src/flask/templates/layouts/main.html", line 99, in top-level template code
    {% block content %}{% endblock %}
  File "/Users/mnann/Documents/Code/PulseFi/src/flask/templates/errors/404.html", line 5, in block 'content'
    <p><a href="{{url_for('index')}}">Back</a></p>
  File "/Users/mnann/Documents/Code/PulseFi/venv/lib/python3.8/site-packages/flask/app.py", line 2034, in url_for
    return self.handle_url_build_error(error, endpoint, values)
  File "/Users/mnann/Documents/Code/PulseFi/venv/lib/python3.8/site-packages/flask/app.py", line 2023, in url_for
    rv = url_adapter.build(  # type: ignore[union-attr]
  File "/Users/mnann/Documents/Code/PulseFi/venv/lib/python3.8/site-packages/werkzeug/routing/map.py", line 917, in build
    raise BuildError(endpoint, values, method, self)
werkzeug.routing.exceptions.BuildError: Could not build url for endpoint 'index'. Did you mean 'login' instead?
2023-04-03 17:04:07,931 ERROR: Exception on /fitbit_auth [GET] [in /Users/mnann/Documents/Code/PulseFi/venv/lib/python3.8/site-packages/flask/app.py:1744]
Traceback (most recent call last):
  File "/Users/mnann/Documents/Code/PulseFi/venv/lib/python3.8/site-packages/flask/app.py", line 1823, in full_dispatch_request
    rv = self.dispatch_request()
  File "/Users/mnann/Documents/Code/PulseFi/venv/lib/python3.8/site-packages/flask/app.py", line 1788, in dispatch_request
    self.raise_routing_exception(req)
  File "/Users/mnann/Documents/Code/PulseFi/venv/lib/python3.8/site-packages/flask/app.py", line 1770, in raise_routing_exception
    raise request.routing_exception  # type: ignore
  File "/Users/mnann/Documents/Code/PulseFi/venv/lib/python3.8/site-packages/flask/ctx.py", line 351, in match_request
    result = self.url_adapter.match(return_rule=True)  # type: ignore
  File "/Users/mnann/Documents/Code/PulseFi/venv/lib/python3.8/site-packages/werkzeug/routing/map.py", line 624, in match
    raise NotFound() from None
werkzeug.exceptions.NotFound: 404 Not Found: The requested URL was not found on the server. If you entered the URL manually please check your spelling and try again.

During handling of the above exception, another exception occurred:

Traceback (most recent call last):
  File "/Users/mnann/Documents/Code/PulseFi/venv/lib/python3.8/site-packages/flask/app.py", line 2528, in wsgi_app
    response = self.full_dispatch_request()
  File "/Users/mnann/Documents/Code/PulseFi/venv/lib/python3.8/site-packages/flask/app.py", line 1825, in full_dispatch_request
    rv = self.handle_user_exception(e)
  File "/Users/mnann/Documents/Code/PulseFi/venv/lib/python3.8/site-packages/flask/app.py", line 1669, in handle_user_exception
    return self.handle_http_exception(e)
  File "/Users/mnann/Documents/Code/PulseFi/venv/lib/python3.8/site-packages/flask/app.py", line 1609, in handle_http_exception
    return self.ensure_sync(handler)(e)
  File "/Users/mnann/Documents/Code/PulseFi/src/flask/app.py", line 130, in not_found_error
    return render_template('errors/404.html'), 404
  File "/Users/mnann/Documents/Code/PulseFi/venv/lib/python3.8/site-packages/flask/templating.py", line 147, in render_template
    return _render(app, template, context)
  File "/Users/mnann/Documents/Code/PulseFi/venv/lib/python3.8/site-packages/flask/templating.py", line 130, in _render
    rv = template.render(context)
  File "/Users/mnann/Documents/Code/PulseFi/venv/lib/python3.8/site-packages/jinja2/environment.py", line 1301, in render
    self.environment.handle_exception()
  File "/Users/mnann/Documents/Code/PulseFi/venv/lib/python3.8/site-packages/jinja2/environment.py", line 936, in handle_exception
    raise rewrite_traceback_stack(source=source)
  File "/Users/mnann/Documents/Code/PulseFi/src/flask/templates/errors/404.html", line 1, in top-level template code
    {% extends 'layouts/main.html' %}
  File "/Users/mnann/Documents/Code/PulseFi/src/flask/templates/layouts/main.html", line 99, in top-level template code
    {% block content %}{% endblock %}
  File "/Users/mnann/Documents/Code/PulseFi/src/flask/templates/errors/404.html", line 5, in block 'content'
    <p><a href="{{url_for('index')}}">Back</a></p>
  File "/Users/mnann/Documents/Code/PulseFi/venv/lib/python3.8/site-packages/flask/app.py", line 2034, in url_for
    return self.handle_url_build_error(error, endpoint, values)
  File "/Users/mnann/Documents/Code/PulseFi/venv/lib/python3.8/site-packages/flask/app.py", line 2023, in url_for
    rv = url_adapter.build(  # type: ignore[union-attr]
  File "/Users/mnann/Documents/Code/PulseFi/venv/lib/python3.8/site-packages/werkzeug/routing/map.py", line 917, in build
    raise BuildError(endpoint, values, method, self)
werkzeug.routing.exceptions.BuildError: Could not build url for endpoint 'index'. Did you mean 'login' instead?
2023-04-03 17:04:08,911 ERROR: Exception on /fitbit_auth [GET] [in /Users/mnann/Documents/Code/PulseFi/venv/lib/python3.8/site-packages/flask/app.py:1744]
Traceback (most recent call last):
  File "/Users/mnann/Documents/Code/PulseFi/venv/lib/python3.8/site-packages/flask/app.py", line 1823, in full_dispatch_request
    rv = self.dispatch_request()
  File "/Users/mnann/Documents/Code/PulseFi/venv/lib/python3.8/site-packages/flask/app.py", line 1788, in dispatch_request
    self.raise_routing_exception(req)
  File "/Users/mnann/Documents/Code/PulseFi/venv/lib/python3.8/site-packages/flask/app.py", line 1770, in raise_routing_exception
    raise request.routing_exception  # type: ignore
  File "/Users/mnann/Documents/Code/PulseFi/venv/lib/python3.8/site-packages/flask/ctx.py", line 351, in match_request
    result = self.url_adapter.match(return_rule=True)  # type: ignore
  File "/Users/mnann/Documents/Code/PulseFi/venv/lib/python3.8/site-packages/werkzeug/routing/map.py", line 624, in match
    raise NotFound() from None
werkzeug.exceptions.NotFound: 404 Not Found: The requested URL was not found on the server. If you entered the URL manually please check your spelling and try again.

During handling of the above exception, another exception occurred:

Traceback (most recent call last):
  File "/Users/mnann/Documents/Code/PulseFi/venv/lib/python3.8/site-packages/flask/app.py", line 2528, in wsgi_app
    response = self.full_dispatch_request()
  File "/Users/mnann/Documents/Code/PulseFi/venv/lib/python3.8/site-packages/flask/app.py", line 1825, in full_dispatch_request
    rv = self.handle_user_exception(e)
  File "/Users/mnann/Documents/Code/PulseFi/venv/lib/python3.8/site-packages/flask/app.py", line 1669, in handle_user_exception
    return self.handle_http_exception(e)
  File "/Users/mnann/Documents/Code/PulseFi/venv/lib/python3.8/site-packages/flask/app.py", line 1609, in handle_http_exception
    return self.ensure_sync(handler)(e)
  File "/Users/mnann/Documents/Code/PulseFi/src/flask/app.py", line 130, in not_found_error
    return render_template('errors/404.html'), 404
  File "/Users/mnann/Documents/Code/PulseFi/venv/lib/python3.8/site-packages/flask/templating.py", line 147, in render_template
    return _render(app, template, context)
  File "/Users/mnann/Documents/Code/PulseFi/venv/lib/python3.8/site-packages/flask/templating.py", line 130, in _render
    rv = template.render(context)
  File "/Users/mnann/Documents/Code/PulseFi/venv/lib/python3.8/site-packages/jinja2/environment.py", line 1301, in render
    self.environment.handle_exception()
  File "/Users/mnann/Documents/Code/PulseFi/venv/lib/python3.8/site-packages/jinja2/environment.py", line 936, in handle_exception
    raise rewrite_traceback_stack(source=source)
  File "/Users/mnann/Documents/Code/PulseFi/src/flask/templates/errors/404.html", line 1, in top-level template code
    {% extends 'layouts/main.html' %}
  File "/Users/mnann/Documents/Code/PulseFi/src/flask/templates/layouts/main.html", line 99, in top-level template code
    {% block content %}{% endblock %}
  File "/Users/mnann/Documents/Code/PulseFi/src/flask/templates/errors/404.html", line 5, in block 'content'
    <p><a href="{{url_for('index')}}">Back</a></p>
  File "/Users/mnann/Documents/Code/PulseFi/venv/lib/python3.8/site-packages/flask/app.py", line 2034, in url_for
    return self.handle_url_build_error(error, endpoint, values)
  File "/Users/mnann/Documents/Code/PulseFi/venv/lib/python3.8/site-packages/flask/app.py", line 2023, in url_for
    rv = url_adapter.build(  # type: ignore[union-attr]
  File "/Users/mnann/Documents/Code/PulseFi/venv/lib/python3.8/site-packages/werkzeug/routing/map.py", line 917, in build
    raise BuildError(endpoint, values, method, self)
werkzeug.routing.exceptions.BuildError: Could not build url for endpoint 'index'. Did you mean 'login' instead?
2023-04-03 17:05:36,841 ERROR: Exception on /favicon.ico [GET] [in /Users/mnann/Documents/Code/PulseFi/venv/lib/python3.8/site-packages/flask/app.py:1744]
Traceback (most recent call last):
  File "/Users/mnann/Documents/Code/PulseFi/venv/lib/python3.8/site-packages/flask/app.py", line 1823, in full_dispatch_request
    rv = self.dispatch_request()
  File "/Users/mnann/Documents/Code/PulseFi/venv/lib/python3.8/site-packages/flask/app.py", line 1788, in dispatch_request
    self.raise_routing_exception(req)
  File "/Users/mnann/Documents/Code/PulseFi/venv/lib/python3.8/site-packages/flask/app.py", line 1770, in raise_routing_exception
    raise request.routing_exception  # type: ignore
  File "/Users/mnann/Documents/Code/PulseFi/venv/lib/python3.8/site-packages/flask/ctx.py", line 351, in match_request
    result = self.url_adapter.match(return_rule=True)  # type: ignore
  File "/Users/mnann/Documents/Code/PulseFi/venv/lib/python3.8/site-packages/werkzeug/routing/map.py", line 624, in match
    raise NotFound() from None
werkzeug.exceptions.NotFound: 404 Not Found: The requested URL was not found on the server. If you entered the URL manually please check your spelling and try again.

During handling of the above exception, another exception occurred:

Traceback (most recent call last):
  File "/Users/mnann/Documents/Code/PulseFi/venv/lib/python3.8/site-packages/flask/app.py", line 2528, in wsgi_app
    response = self.full_dispatch_request()
  File "/Users/mnann/Documents/Code/PulseFi/venv/lib/python3.8/site-packages/flask/app.py", line 1825, in full_dispatch_request
    rv = self.handle_user_exception(e)
  File "/Users/mnann/Documents/Code/PulseFi/venv/lib/python3.8/site-packages/flask/app.py", line 1669, in handle_user_exception
    return self.handle_http_exception(e)
  File "/Users/mnann/Documents/Code/PulseFi/venv/lib/python3.8/site-packages/flask/app.py", line 1609, in handle_http_exception
    return self.ensure_sync(handler)(e)
  File "/Users/mnann/Documents/Code/PulseFi/src/flask/app.py", line 130, in not_found_error
    return render_template('errors/404.html'), 404
  File "/Users/mnann/Documents/Code/PulseFi/venv/lib/python3.8/site-packages/flask/templating.py", line 147, in render_template
    return _render(app, template, context)
  File "/Users/mnann/Documents/Code/PulseFi/venv/lib/python3.8/site-packages/flask/templating.py", line 130, in _render
    rv = template.render(context)
  File "/Users/mnann/Documents/Code/PulseFi/venv/lib/python3.8/site-packages/jinja2/environment.py", line 1301, in render
    self.environment.handle_exception()
  File "/Users/mnann/Documents/Code/PulseFi/venv/lib/python3.8/site-packages/jinja2/environment.py", line 936, in handle_exception
    raise rewrite_traceback_stack(source=source)
  File "/Users/mnann/Documents/Code/PulseFi/src/flask/templates/errors/404.html", line 1, in top-level template code
    {% extends 'layouts/main.html' %}
  File "/Users/mnann/Documents/Code/PulseFi/src/flask/templates/layouts/main.html", line 99, in top-level template code
    {% block content %}{% endblock %}
  File "/Users/mnann/Documents/Code/PulseFi/src/flask/templates/errors/404.html", line 5, in block 'content'
    <p><a href="{{url_for('index')}}">Back</a></p>
  File "/Users/mnann/Documents/Code/PulseFi/venv/lib/python3.8/site-packages/flask/app.py", line 2034, in url_for
    return self.handle_url_build_error(error, endpoint, values)
  File "/Users/mnann/Documents/Code/PulseFi/venv/lib/python3.8/site-packages/flask/app.py", line 2023, in url_for
    rv = url_adapter.build(  # type: ignore[union-attr]
  File "/Users/mnann/Documents/Code/PulseFi/venv/lib/python3.8/site-packages/werkzeug/routing/map.py", line 917, in build
    raise BuildError(endpoint, values, method, self)
werkzeug.routing.exceptions.BuildError: Could not build url for endpoint 'index'. Did you mean 'login' instead?
2023-04-03 17:07:56,187 INFO: errors [in /Users/mnann/Documents/Code/PulseFi/src/flask/app.py:145]
2023-04-03 17:09:39,068 INFO: errors [in /Users/mnann/Documents/Code/PulseFi/src/flask/app.py:145]
2023-04-03 17:11:31,855 INFO: errors [in /Users/mnann/Documents/Code/PulseFi/src/flask/app.py:145]
2023-04-03 17:11:33,343 ERROR: Exception on /heartRat [GET] [in /Users/mnann/Documents/Code/PulseFi/venv/lib/python3.8/site-packages/flask/app.py:1744]
Traceback (most recent call last):
  File "/Users/mnann/Documents/Code/PulseFi/venv/lib/python3.8/site-packages/flask/app.py", line 1823, in full_dispatch_request
    rv = self.dispatch_request()
  File "/Users/mnann/Documents/Code/PulseFi/venv/lib/python3.8/site-packages/flask/app.py", line 1788, in dispatch_request
    self.raise_routing_exception(req)
  File "/Users/mnann/Documents/Code/PulseFi/venv/lib/python3.8/site-packages/flask/app.py", line 1770, in raise_routing_exception
    raise request.routing_exception  # type: ignore
  File "/Users/mnann/Documents/Code/PulseFi/venv/lib/python3.8/site-packages/flask/ctx.py", line 351, in match_request
    result = self.url_adapter.match(return_rule=True)  # type: ignore
  File "/Users/mnann/Documents/Code/PulseFi/venv/lib/python3.8/site-packages/werkzeug/routing/map.py", line 624, in match
    raise NotFound() from None
werkzeug.exceptions.NotFound: 404 Not Found: The requested URL was not found on the server. If you entered the URL manually please check your spelling and try again.

During handling of the above exception, another exception occurred:

Traceback (most recent call last):
  File "/Users/mnann/Documents/Code/PulseFi/venv/lib/python3.8/site-packages/flask/app.py", line 2528, in wsgi_app
    response = self.full_dispatch_request()
  File "/Users/mnann/Documents/Code/PulseFi/venv/lib/python3.8/site-packages/flask/app.py", line 1825, in full_dispatch_request
    rv = self.handle_user_exception(e)
  File "/Users/mnann/Documents/Code/PulseFi/venv/lib/python3.8/site-packages/flask/app.py", line 1669, in handle_user_exception
    return self.handle_http_exception(e)
  File "/Users/mnann/Documents/Code/PulseFi/venv/lib/python3.8/site-packages/flask/app.py", line 1609, in handle_http_exception
    return self.ensure_sync(handler)(e)
  File "/Users/mnann/Documents/Code/PulseFi/src/flask/app.py", line 130, in not_found_error
    return render_template('errors/404.html'), 404
  File "/Users/mnann/Documents/Code/PulseFi/venv/lib/python3.8/site-packages/flask/templating.py", line 147, in render_template
    return _render(app, template, context)
  File "/Users/mnann/Documents/Code/PulseFi/venv/lib/python3.8/site-packages/flask/templating.py", line 130, in _render
    rv = template.render(context)
  File "/Users/mnann/Documents/Code/PulseFi/venv/lib/python3.8/site-packages/jinja2/environment.py", line 1301, in render
    self.environment.handle_exception()
  File "/Users/mnann/Documents/Code/PulseFi/venv/lib/python3.8/site-packages/jinja2/environment.py", line 936, in handle_exception
    raise rewrite_traceback_stack(source=source)
  File "/Users/mnann/Documents/Code/PulseFi/src/flask/templates/errors/404.html", line 1, in top-level template code
    {% extends 'layouts/main.html' %}
  File "/Users/mnann/Documents/Code/PulseFi/src/flask/templates/layouts/main.html", line 99, in top-level template code
    {% block content %}{% endblock %}
  File "/Users/mnann/Documents/Code/PulseFi/src/flask/templates/errors/404.html", line 5, in block 'content'
    <p><a href="{{url_for('index')}}">Back</a></p>
  File "/Users/mnann/Documents/Code/PulseFi/venv/lib/python3.8/site-packages/flask/app.py", line 2034, in url_for
    return self.handle_url_build_error(error, endpoint, values)
  File "/Users/mnann/Documents/Code/PulseFi/venv/lib/python3.8/site-packages/flask/app.py", line 2023, in url_for
    rv = url_adapter.build(  # type: ignore[union-attr]
  File "/Users/mnann/Documents/Code/PulseFi/venv/lib/python3.8/site-packages/werkzeug/routing/map.py", line 917, in build
    raise BuildError(endpoint, values, method, self)
werkzeug.routing.exceptions.BuildError: Could not build url for endpoint 'index'. Did you mean 'login' instead?
2023-04-03 17:11:37,247 ERROR: Exception on /heartRat [GET] [in /Users/mnann/Documents/Code/PulseFi/venv/lib/python3.8/site-packages/flask/app.py:1744]
Traceback (most recent call last):
  File "/Users/mnann/Documents/Code/PulseFi/venv/lib/python3.8/site-packages/flask/app.py", line 1823, in full_dispatch_request
    rv = self.dispatch_request()
  File "/Users/mnann/Documents/Code/PulseFi/venv/lib/python3.8/site-packages/flask/app.py", line 1788, in dispatch_request
    self.raise_routing_exception(req)
  File "/Users/mnann/Documents/Code/PulseFi/venv/lib/python3.8/site-packages/flask/app.py", line 1770, in raise_routing_exception
    raise request.routing_exception  # type: ignore
  File "/Users/mnann/Documents/Code/PulseFi/venv/lib/python3.8/site-packages/flask/ctx.py", line 351, in match_request
    result = self.url_adapter.match(return_rule=True)  # type: ignore
  File "/Users/mnann/Documents/Code/PulseFi/venv/lib/python3.8/site-packages/werkzeug/routing/map.py", line 624, in match
    raise NotFound() from None
werkzeug.exceptions.NotFound: 404 Not Found: The requested URL was not found on the server. If you entered the URL manually please check your spelling and try again.

During handling of the above exception, another exception occurred:

Traceback (most recent call last):
  File "/Users/mnann/Documents/Code/PulseFi/venv/lib/python3.8/site-packages/flask/app.py", line 2528, in wsgi_app
    response = self.full_dispatch_request()
  File "/Users/mnann/Documents/Code/PulseFi/venv/lib/python3.8/site-packages/flask/app.py", line 1825, in full_dispatch_request
    rv = self.handle_user_exception(e)
  File "/Users/mnann/Documents/Code/PulseFi/venv/lib/python3.8/site-packages/flask/app.py", line 1669, in handle_user_exception
    return self.handle_http_exception(e)
  File "/Users/mnann/Documents/Code/PulseFi/venv/lib/python3.8/site-packages/flask/app.py", line 1609, in handle_http_exception
    return self.ensure_sync(handler)(e)
  File "/Users/mnann/Documents/Code/PulseFi/src/flask/app.py", line 130, in not_found_error
    return render_template('errors/404.html'), 404
  File "/Users/mnann/Documents/Code/PulseFi/venv/lib/python3.8/site-packages/flask/templating.py", line 147, in render_template
    return _render(app, template, context)
  File "/Users/mnann/Documents/Code/PulseFi/venv/lib/python3.8/site-packages/flask/templating.py", line 130, in _render
    rv = template.render(context)
  File "/Users/mnann/Documents/Code/PulseFi/venv/lib/python3.8/site-packages/jinja2/environment.py", line 1301, in render
    self.environment.handle_exception()
  File "/Users/mnann/Documents/Code/PulseFi/venv/lib/python3.8/site-packages/jinja2/environment.py", line 936, in handle_exception
    raise rewrite_traceback_stack(source=source)
  File "/Users/mnann/Documents/Code/PulseFi/src/flask/templates/errors/404.html", line 1, in top-level template code
    {% extends 'layouts/main.html' %}
  File "/Users/mnann/Documents/Code/PulseFi/src/flask/templates/layouts/main.html", line 99, in top-level template code
    {% block content %}{% endblock %}
  File "/Users/mnann/Documents/Code/PulseFi/src/flask/templates/errors/404.html", line 5, in block 'content'
    <p><a href="{{url_for('index')}}">Back</a></p>
  File "/Users/mnann/Documents/Code/PulseFi/venv/lib/python3.8/site-packages/flask/app.py", line 2034, in url_for
    return self.handle_url_build_error(error, endpoint, values)
  File "/Users/mnann/Documents/Code/PulseFi/venv/lib/python3.8/site-packages/flask/app.py", line 2023, in url_for
    rv = url_adapter.build(  # type: ignore[union-attr]
  File "/Users/mnann/Documents/Code/PulseFi/venv/lib/python3.8/site-packages/werkzeug/routing/map.py", line 917, in build
    raise BuildError(endpoint, values, method, self)
werkzeug.routing.exceptions.BuildError: Could not build url for endpoint 'index'. Did you mean 'login' instead?
2023-04-03 17:12:22,824 INFO: errors [in /Users/mnann/Documents/Code/PulseFi/src/flask/app.py:145]
2023-04-03 17:12:34,898 ERROR: Exception on /heartRat [GET] [in /Users/mnann/Documents/Code/PulseFi/venv/lib/python3.8/site-packages/flask/app.py:1744]
Traceback (most recent call last):
  File "/Users/mnann/Documents/Code/PulseFi/venv/lib/python3.8/site-packages/flask/app.py", line 1823, in full_dispatch_request
    rv = self.dispatch_request()
  File "/Users/mnann/Documents/Code/PulseFi/venv/lib/python3.8/site-packages/flask/app.py", line 1788, in dispatch_request
    self.raise_routing_exception(req)
  File "/Users/mnann/Documents/Code/PulseFi/venv/lib/python3.8/site-packages/flask/app.py", line 1770, in raise_routing_exception
    raise request.routing_exception  # type: ignore
  File "/Users/mnann/Documents/Code/PulseFi/venv/lib/python3.8/site-packages/flask/ctx.py", line 351, in match_request
    result = self.url_adapter.match(return_rule=True)  # type: ignore
  File "/Users/mnann/Documents/Code/PulseFi/venv/lib/python3.8/site-packages/werkzeug/routing/map.py", line 624, in match
    raise NotFound() from None
werkzeug.exceptions.NotFound: 404 Not Found: The requested URL was not found on the server. If you entered the URL manually please check your spelling and try again.

During handling of the above exception, another exception occurred:

Traceback (most recent call last):
  File "/Users/mnann/Documents/Code/PulseFi/venv/lib/python3.8/site-packages/flask/app.py", line 2528, in wsgi_app
    response = self.full_dispatch_request()
  File "/Users/mnann/Documents/Code/PulseFi/venv/lib/python3.8/site-packages/flask/app.py", line 1825, in full_dispatch_request
    rv = self.handle_user_exception(e)
  File "/Users/mnann/Documents/Code/PulseFi/venv/lib/python3.8/site-packages/flask/app.py", line 1669, in handle_user_exception
    return self.handle_http_exception(e)
  File "/Users/mnann/Documents/Code/PulseFi/venv/lib/python3.8/site-packages/flask/app.py", line 1609, in handle_http_exception
    return self.ensure_sync(handler)(e)
  File "/Users/mnann/Documents/Code/PulseFi/src/flask/app.py", line 130, in not_found_error
    return render_template('errors/404.html'), 404
  File "/Users/mnann/Documents/Code/PulseFi/venv/lib/python3.8/site-packages/flask/templating.py", line 147, in render_template
    return _render(app, template, context)
  File "/Users/mnann/Documents/Code/PulseFi/venv/lib/python3.8/site-packages/flask/templating.py", line 130, in _render
    rv = template.render(context)
  File "/Users/mnann/Documents/Code/PulseFi/venv/lib/python3.8/site-packages/jinja2/environment.py", line 1301, in render
    self.environment.handle_exception()
  File "/Users/mnann/Documents/Code/PulseFi/venv/lib/python3.8/site-packages/jinja2/environment.py", line 936, in handle_exception
    raise rewrite_traceback_stack(source=source)
  File "/Users/mnann/Documents/Code/PulseFi/src/flask/templates/errors/404.html", line 1, in top-level template code
    {% extends 'layouts/main.html' %}
  File "/Users/mnann/Documents/Code/PulseFi/src/flask/templates/layouts/main.html", line 99, in top-level template code
    {% block content %}{% endblock %}
  File "/Users/mnann/Documents/Code/PulseFi/src/flask/templates/errors/404.html", line 5, in block 'content'
    <p><a href="{{url_for('index')}}">Back</a></p>
  File "/Users/mnann/Documents/Code/PulseFi/venv/lib/python3.8/site-packages/flask/app.py", line 2034, in url_for
    return self.handle_url_build_error(error, endpoint, values)
  File "/Users/mnann/Documents/Code/PulseFi/venv/lib/python3.8/site-packages/flask/app.py", line 2023, in url_for
    rv = url_adapter.build(  # type: ignore[union-attr]
  File "/Users/mnann/Documents/Code/PulseFi/venv/lib/python3.8/site-packages/werkzeug/routing/map.py", line 917, in build
    raise BuildError(endpoint, values, method, self)
werkzeug.routing.exceptions.BuildError: Could not build url for endpoint 'index'. Did you mean 'login' instead?
2023-04-03 17:13:33,148 ERROR: Exception on /heartRat [GET] [in /Users/mnann/Documents/Code/PulseFi/venv/lib/python3.8/site-packages/flask/app.py:1744]
Traceback (most recent call last):
  File "/Users/mnann/Documents/Code/PulseFi/venv/lib/python3.8/site-packages/flask/app.py", line 1823, in full_dispatch_request
    rv = self.dispatch_request()
  File "/Users/mnann/Documents/Code/PulseFi/venv/lib/python3.8/site-packages/flask/app.py", line 1788, in dispatch_request
    self.raise_routing_exception(req)
  File "/Users/mnann/Documents/Code/PulseFi/venv/lib/python3.8/site-packages/flask/app.py", line 1770, in raise_routing_exception
    raise request.routing_exception  # type: ignore
  File "/Users/mnann/Documents/Code/PulseFi/venv/lib/python3.8/site-packages/flask/ctx.py", line 351, in match_request
    result = self.url_adapter.match(return_rule=True)  # type: ignore
  File "/Users/mnann/Documents/Code/PulseFi/venv/lib/python3.8/site-packages/werkzeug/routing/map.py", line 624, in match
    raise NotFound() from None
werkzeug.exceptions.NotFound: 404 Not Found: The requested URL was not found on the server. If you entered the URL manually please check your spelling and try again.

During handling of the above exception, another exception occurred:

Traceback (most recent call last):
  File "/Users/mnann/Documents/Code/PulseFi/venv/lib/python3.8/site-packages/flask/app.py", line 2528, in wsgi_app
    response = self.full_dispatch_request()
  File "/Users/mnann/Documents/Code/PulseFi/venv/lib/python3.8/site-packages/flask/app.py", line 1825, in full_dispatch_request
    rv = self.handle_user_exception(e)
  File "/Users/mnann/Documents/Code/PulseFi/venv/lib/python3.8/site-packages/flask/app.py", line 1669, in handle_user_exception
    return self.handle_http_exception(e)
  File "/Users/mnann/Documents/Code/PulseFi/venv/lib/python3.8/site-packages/flask/app.py", line 1609, in handle_http_exception
    return self.ensure_sync(handler)(e)
  File "/Users/mnann/Documents/Code/PulseFi/src/flask/app.py", line 130, in not_found_error
    return render_template('errors/404.html'), 404
  File "/Users/mnann/Documents/Code/PulseFi/venv/lib/python3.8/site-packages/flask/templating.py", line 147, in render_template
    return _render(app, template, context)
  File "/Users/mnann/Documents/Code/PulseFi/venv/lib/python3.8/site-packages/flask/templating.py", line 130, in _render
    rv = template.render(context)
  File "/Users/mnann/Documents/Code/PulseFi/venv/lib/python3.8/site-packages/jinja2/environment.py", line 1301, in render
    self.environment.handle_exception()
  File "/Users/mnann/Documents/Code/PulseFi/venv/lib/python3.8/site-packages/jinja2/environment.py", line 936, in handle_exception
    raise rewrite_traceback_stack(source=source)
  File "/Users/mnann/Documents/Code/PulseFi/src/flask/templates/errors/404.html", line 1, in top-level template code
    {% extends 'layouts/main.html' %}
  File "/Users/mnann/Documents/Code/PulseFi/src/flask/templates/layouts/main.html", line 99, in top-level template code
    {% block content %}{% endblock %}
  File "/Users/mnann/Documents/Code/PulseFi/src/flask/templates/errors/404.html", line 5, in block 'content'
    <p><a href="{{url_for('index')}}">Back</a></p>
  File "/Users/mnann/Documents/Code/PulseFi/venv/lib/python3.8/site-packages/flask/app.py", line 2034, in url_for
    return self.handle_url_build_error(error, endpoint, values)
  File "/Users/mnann/Documents/Code/PulseFi/venv/lib/python3.8/site-packages/flask/app.py", line 2023, in url_for
    rv = url_adapter.build(  # type: ignore[union-attr]
  File "/Users/mnann/Documents/Code/PulseFi/venv/lib/python3.8/site-packages/werkzeug/routing/map.py", line 917, in build
    raise BuildError(endpoint, values, method, self)
werkzeug.routing.exceptions.BuildError: Could not build url for endpoint 'index'. Did you mean 'login' instead?
2023-04-03 17:13:36,760 ERROR: Exception on /heart [GET] [in /Users/mnann/Documents/Code/PulseFi/venv/lib/python3.8/site-packages/flask/app.py:1744]
Traceback (most recent call last):
  File "/Users/mnann/Documents/Code/PulseFi/venv/lib/python3.8/site-packages/flask/app.py", line 1823, in full_dispatch_request
    rv = self.dispatch_request()
  File "/Users/mnann/Documents/Code/PulseFi/venv/lib/python3.8/site-packages/flask/app.py", line 1788, in dispatch_request
    self.raise_routing_exception(req)
  File "/Users/mnann/Documents/Code/PulseFi/venv/lib/python3.8/site-packages/flask/app.py", line 1770, in raise_routing_exception
    raise request.routing_exception  # type: ignore
  File "/Users/mnann/Documents/Code/PulseFi/venv/lib/python3.8/site-packages/flask/ctx.py", line 351, in match_request
    result = self.url_adapter.match(return_rule=True)  # type: ignore
  File "/Users/mnann/Documents/Code/PulseFi/venv/lib/python3.8/site-packages/werkzeug/routing/map.py", line 624, in match
    raise NotFound() from None
werkzeug.exceptions.NotFound: 404 Not Found: The requested URL was not found on the server. If you entered the URL manually please check your spelling and try again.

During handling of the above exception, another exception occurred:

Traceback (most recent call last):
  File "/Users/mnann/Documents/Code/PulseFi/venv/lib/python3.8/site-packages/flask/app.py", line 2528, in wsgi_app
    response = self.full_dispatch_request()
  File "/Users/mnann/Documents/Code/PulseFi/venv/lib/python3.8/site-packages/flask/app.py", line 1825, in full_dispatch_request
    rv = self.handle_user_exception(e)
  File "/Users/mnann/Documents/Code/PulseFi/venv/lib/python3.8/site-packages/flask/app.py", line 1669, in handle_user_exception
    return self.handle_http_exception(e)
  File "/Users/mnann/Documents/Code/PulseFi/venv/lib/python3.8/site-packages/flask/app.py", line 1609, in handle_http_exception
    return self.ensure_sync(handler)(e)
  File "/Users/mnann/Documents/Code/PulseFi/src/flask/app.py", line 130, in not_found_error
    return render_template('errors/404.html'), 404
  File "/Users/mnann/Documents/Code/PulseFi/venv/lib/python3.8/site-packages/flask/templating.py", line 147, in render_template
    return _render(app, template, context)
  File "/Users/mnann/Documents/Code/PulseFi/venv/lib/python3.8/site-packages/flask/templating.py", line 130, in _render
    rv = template.render(context)
  File "/Users/mnann/Documents/Code/PulseFi/venv/lib/python3.8/site-packages/jinja2/environment.py", line 1301, in render
    self.environment.handle_exception()
  File "/Users/mnann/Documents/Code/PulseFi/venv/lib/python3.8/site-packages/jinja2/environment.py", line 936, in handle_exception
    raise rewrite_traceback_stack(source=source)
  File "/Users/mnann/Documents/Code/PulseFi/src/flask/templates/errors/404.html", line 1, in top-level template code
    {% extends 'layouts/main.html' %}
  File "/Users/mnann/Documents/Code/PulseFi/src/flask/templates/layouts/main.html", line 99, in top-level template code
    {% block content %}{% endblock %}
  File "/Users/mnann/Documents/Code/PulseFi/src/flask/templates/errors/404.html", line 5, in block 'content'
    <p><a href="{{url_for('index')}}">Back</a></p>
  File "/Users/mnann/Documents/Code/PulseFi/venv/lib/python3.8/site-packages/flask/app.py", line 2034, in url_for
    return self.handle_url_build_error(error, endpoint, values)
  File "/Users/mnann/Documents/Code/PulseFi/venv/lib/python3.8/site-packages/flask/app.py", line 2023, in url_for
    rv = url_adapter.build(  # type: ignore[union-attr]
  File "/Users/mnann/Documents/Code/PulseFi/venv/lib/python3.8/site-packages/werkzeug/routing/map.py", line 917, in build
    raise BuildError(endpoint, values, method, self)
werkzeug.routing.exceptions.BuildError: Could not build url for endpoint 'index'. Did you mean 'login' instead?
2023-04-03 17:13:39,502 ERROR: Exception on /heart [GET] [in /Users/mnann/Documents/Code/PulseFi/venv/lib/python3.8/site-packages/flask/app.py:1744]
Traceback (most recent call last):
  File "/Users/mnann/Documents/Code/PulseFi/venv/lib/python3.8/site-packages/flask/app.py", line 1823, in full_dispatch_request
    rv = self.dispatch_request()
  File "/Users/mnann/Documents/Code/PulseFi/venv/lib/python3.8/site-packages/flask/app.py", line 1788, in dispatch_request
    self.raise_routing_exception(req)
  File "/Users/mnann/Documents/Code/PulseFi/venv/lib/python3.8/site-packages/flask/app.py", line 1770, in raise_routing_exception
    raise request.routing_exception  # type: ignore
  File "/Users/mnann/Documents/Code/PulseFi/venv/lib/python3.8/site-packages/flask/ctx.py", line 351, in match_request
    result = self.url_adapter.match(return_rule=True)  # type: ignore
  File "/Users/mnann/Documents/Code/PulseFi/venv/lib/python3.8/site-packages/werkzeug/routing/map.py", line 624, in match
    raise NotFound() from None
werkzeug.exceptions.NotFound: 404 Not Found: The requested URL was not found on the server. If you entered the URL manually please check your spelling and try again.

During handling of the above exception, another exception occurred:

Traceback (most recent call last):
  File "/Users/mnann/Documents/Code/PulseFi/venv/lib/python3.8/site-packages/flask/app.py", line 2528, in wsgi_app
    response = self.full_dispatch_request()
  File "/Users/mnann/Documents/Code/PulseFi/venv/lib/python3.8/site-packages/flask/app.py", line 1825, in full_dispatch_request
    rv = self.handle_user_exception(e)
  File "/Users/mnann/Documents/Code/PulseFi/venv/lib/python3.8/site-packages/flask/app.py", line 1669, in handle_user_exception
    return self.handle_http_exception(e)
  File "/Users/mnann/Documents/Code/PulseFi/venv/lib/python3.8/site-packages/flask/app.py", line 1609, in handle_http_exception
    return self.ensure_sync(handler)(e)
  File "/Users/mnann/Documents/Code/PulseFi/src/flask/app.py", line 130, in not_found_error
    return render_template('errors/404.html'), 404
  File "/Users/mnann/Documents/Code/PulseFi/venv/lib/python3.8/site-packages/flask/templating.py", line 147, in render_template
    return _render(app, template, context)
  File "/Users/mnann/Documents/Code/PulseFi/venv/lib/python3.8/site-packages/flask/templating.py", line 130, in _render
    rv = template.render(context)
  File "/Users/mnann/Documents/Code/PulseFi/venv/lib/python3.8/site-packages/jinja2/environment.py", line 1301, in render
    self.environment.handle_exception()
  File "/Users/mnann/Documents/Code/PulseFi/venv/lib/python3.8/site-packages/jinja2/environment.py", line 936, in handle_exception
    raise rewrite_traceback_stack(source=source)
  File "/Users/mnann/Documents/Code/PulseFi/src/flask/templates/errors/404.html", line 1, in top-level template code
    {% extends 'layouts/main.html' %}
  File "/Users/mnann/Documents/Code/PulseFi/src/flask/templates/layouts/main.html", line 99, in top-level template code
    {% block content %}{% endblock %}
  File "/Users/mnann/Documents/Code/PulseFi/src/flask/templates/errors/404.html", line 5, in block 'content'
    <p><a href="{{url_for('index')}}">Back</a></p>
  File "/Users/mnann/Documents/Code/PulseFi/venv/lib/python3.8/site-packages/flask/app.py", line 2034, in url_for
    return self.handle_url_build_error(error, endpoint, values)
  File "/Users/mnann/Documents/Code/PulseFi/venv/lib/python3.8/site-packages/flask/app.py", line 2023, in url_for
    rv = url_adapter.build(  # type: ignore[union-attr]
  File "/Users/mnann/Documents/Code/PulseFi/venv/lib/python3.8/site-packages/werkzeug/routing/map.py", line 917, in build
    raise BuildError(endpoint, values, method, self)
werkzeug.routing.exceptions.BuildError: Could not build url for endpoint 'index'. Did you mean 'login' instead?
2023-04-03 17:13:40,370 ERROR: Exception on /heartRat [GET] [in /Users/mnann/Documents/Code/PulseFi/venv/lib/python3.8/site-packages/flask/app.py:1744]
Traceback (most recent call last):
  File "/Users/mnann/Documents/Code/PulseFi/venv/lib/python3.8/site-packages/flask/app.py", line 1823, in full_dispatch_request
    rv = self.dispatch_request()
  File "/Users/mnann/Documents/Code/PulseFi/venv/lib/python3.8/site-packages/flask/app.py", line 1788, in dispatch_request
    self.raise_routing_exception(req)
  File "/Users/mnann/Documents/Code/PulseFi/venv/lib/python3.8/site-packages/flask/app.py", line 1770, in raise_routing_exception
    raise request.routing_exception  # type: ignore
  File "/Users/mnann/Documents/Code/PulseFi/venv/lib/python3.8/site-packages/flask/ctx.py", line 351, in match_request
    result = self.url_adapter.match(return_rule=True)  # type: ignore
  File "/Users/mnann/Documents/Code/PulseFi/venv/lib/python3.8/site-packages/werkzeug/routing/map.py", line 624, in match
    raise NotFound() from None
werkzeug.exceptions.NotFound: 404 Not Found: The requested URL was not found on the server. If you entered the URL manually please check your spelling and try again.

During handling of the above exception, another exception occurred:

Traceback (most recent call last):
  File "/Users/mnann/Documents/Code/PulseFi/venv/lib/python3.8/site-packages/flask/app.py", line 2528, in wsgi_app
    response = self.full_dispatch_request()
  File "/Users/mnann/Documents/Code/PulseFi/venv/lib/python3.8/site-packages/flask/app.py", line 1825, in full_dispatch_request
    rv = self.handle_user_exception(e)
  File "/Users/mnann/Documents/Code/PulseFi/venv/lib/python3.8/site-packages/flask/app.py", line 1669, in handle_user_exception
    return self.handle_http_exception(e)
  File "/Users/mnann/Documents/Code/PulseFi/venv/lib/python3.8/site-packages/flask/app.py", line 1609, in handle_http_exception
    return self.ensure_sync(handler)(e)
  File "/Users/mnann/Documents/Code/PulseFi/src/flask/app.py", line 130, in not_found_error
    return render_template('errors/404.html'), 404
  File "/Users/mnann/Documents/Code/PulseFi/venv/lib/python3.8/site-packages/flask/templating.py", line 147, in render_template
    return _render(app, template, context)
  File "/Users/mnann/Documents/Code/PulseFi/venv/lib/python3.8/site-packages/flask/templating.py", line 130, in _render
    rv = template.render(context)
  File "/Users/mnann/Documents/Code/PulseFi/venv/lib/python3.8/site-packages/jinja2/environment.py", line 1301, in render
    self.environment.handle_exception()
  File "/Users/mnann/Documents/Code/PulseFi/venv/lib/python3.8/site-packages/jinja2/environment.py", line 936, in handle_exception
    raise rewrite_traceback_stack(source=source)
  File "/Users/mnann/Documents/Code/PulseFi/src/flask/templates/errors/404.html", line 1, in top-level template code
    {% extends 'layouts/main.html' %}
  File "/Users/mnann/Documents/Code/PulseFi/src/flask/templates/layouts/main.html", line 99, in top-level template code
    {% block content %}{% endblock %}
  File "/Users/mnann/Documents/Code/PulseFi/src/flask/templates/errors/404.html", line 5, in block 'content'
    <p><a href="{{url_for('index')}}">Back</a></p>
  File "/Users/mnann/Documents/Code/PulseFi/venv/lib/python3.8/site-packages/flask/app.py", line 2034, in url_for
    return self.handle_url_build_error(error, endpoint, values)
  File "/Users/mnann/Documents/Code/PulseFi/venv/lib/python3.8/site-packages/flask/app.py", line 2023, in url_for
    rv = url_adapter.build(  # type: ignore[union-attr]
  File "/Users/mnann/Documents/Code/PulseFi/venv/lib/python3.8/site-packages/werkzeug/routing/map.py", line 917, in build
    raise BuildError(endpoint, values, method, self)
werkzeug.routing.exceptions.BuildError: Could not build url for endpoint 'index'. Did you mean 'login' instead?
2023-04-03 17:13:52,938 ERROR: Exception on /heartRat [GET] [in /Users/mnann/Documents/Code/PulseFi/venv/lib/python3.8/site-packages/flask/app.py:1744]
Traceback (most recent call last):
  File "/Users/mnann/Documents/Code/PulseFi/venv/lib/python3.8/site-packages/flask/app.py", line 1823, in full_dispatch_request
    rv = self.dispatch_request()
  File "/Users/mnann/Documents/Code/PulseFi/venv/lib/python3.8/site-packages/flask/app.py", line 1788, in dispatch_request
    self.raise_routing_exception(req)
  File "/Users/mnann/Documents/Code/PulseFi/venv/lib/python3.8/site-packages/flask/app.py", line 1770, in raise_routing_exception
    raise request.routing_exception  # type: ignore
  File "/Users/mnann/Documents/Code/PulseFi/venv/lib/python3.8/site-packages/flask/ctx.py", line 351, in match_request
    result = self.url_adapter.match(return_rule=True)  # type: ignore
  File "/Users/mnann/Documents/Code/PulseFi/venv/lib/python3.8/site-packages/werkzeug/routing/map.py", line 624, in match
    raise NotFound() from None
werkzeug.exceptions.NotFound: 404 Not Found: The requested URL was not found on the server. If you entered the URL manually please check your spelling and try again.

During handling of the above exception, another exception occurred:

Traceback (most recent call last):
  File "/Users/mnann/Documents/Code/PulseFi/venv/lib/python3.8/site-packages/flask/app.py", line 2528, in wsgi_app
    response = self.full_dispatch_request()
  File "/Users/mnann/Documents/Code/PulseFi/venv/lib/python3.8/site-packages/flask/app.py", line 1825, in full_dispatch_request
    rv = self.handle_user_exception(e)
  File "/Users/mnann/Documents/Code/PulseFi/venv/lib/python3.8/site-packages/flask/app.py", line 1669, in handle_user_exception
    return self.handle_http_exception(e)
  File "/Users/mnann/Documents/Code/PulseFi/venv/lib/python3.8/site-packages/flask/app.py", line 1609, in handle_http_exception
    return self.ensure_sync(handler)(e)
  File "/Users/mnann/Documents/Code/PulseFi/src/flask/app.py", line 130, in not_found_error
    return render_template('errors/404.html'), 404
  File "/Users/mnann/Documents/Code/PulseFi/venv/lib/python3.8/site-packages/flask/templating.py", line 147, in render_template
    return _render(app, template, context)
  File "/Users/mnann/Documents/Code/PulseFi/venv/lib/python3.8/site-packages/flask/templating.py", line 130, in _render
    rv = template.render(context)
  File "/Users/mnann/Documents/Code/PulseFi/venv/lib/python3.8/site-packages/jinja2/environment.py", line 1301, in render
    self.environment.handle_exception()
  File "/Users/mnann/Documents/Code/PulseFi/venv/lib/python3.8/site-packages/jinja2/environment.py", line 936, in handle_exception
    raise rewrite_traceback_stack(source=source)
  File "/Users/mnann/Documents/Code/PulseFi/src/flask/templates/errors/404.html", line 1, in top-level template code
    {% extends 'layouts/main.html' %}
  File "/Users/mnann/Documents/Code/PulseFi/src/flask/templates/layouts/main.html", line 99, in top-level template code
    {% block content %}{% endblock %}
  File "/Users/mnann/Documents/Code/PulseFi/src/flask/templates/errors/404.html", line 5, in block 'content'
    <p><a href="{{url_for('index')}}">Back</a></p>
  File "/Users/mnann/Documents/Code/PulseFi/venv/lib/python3.8/site-packages/flask/app.py", line 2034, in url_for
    return self.handle_url_build_error(error, endpoint, values)
  File "/Users/mnann/Documents/Code/PulseFi/venv/lib/python3.8/site-packages/flask/app.py", line 2023, in url_for
    rv = url_adapter.build(  # type: ignore[union-attr]
  File "/Users/mnann/Documents/Code/PulseFi/venv/lib/python3.8/site-packages/werkzeug/routing/map.py", line 917, in build
    raise BuildError(endpoint, values, method, self)
werkzeug.routing.exceptions.BuildError: Could not build url for endpoint 'index'. Did you mean 'login' instead?
2023-04-03 17:15:51,272 INFO: errors [in /Users/mnann/Documents/Code/PulseFi/src/flask/app.py:145]
2023-04-03 17:15:58,286 ERROR: Exception on /heart [GET] [in /Users/mnann/Documents/Code/PulseFi/venv/lib/python3.8/site-packages/flask/app.py:1744]
Traceback (most recent call last):
  File "/Users/mnann/Documents/Code/PulseFi/venv/lib/python3.8/site-packages/flask/app.py", line 1823, in full_dispatch_request
    rv = self.dispatch_request()
  File "/Users/mnann/Documents/Code/PulseFi/venv/lib/python3.8/site-packages/flask/app.py", line 1788, in dispatch_request
    self.raise_routing_exception(req)
  File "/Users/mnann/Documents/Code/PulseFi/venv/lib/python3.8/site-packages/flask/app.py", line 1770, in raise_routing_exception
    raise request.routing_exception  # type: ignore
  File "/Users/mnann/Documents/Code/PulseFi/venv/lib/python3.8/site-packages/flask/ctx.py", line 351, in match_request
    result = self.url_adapter.match(return_rule=True)  # type: ignore
  File "/Users/mnann/Documents/Code/PulseFi/venv/lib/python3.8/site-packages/werkzeug/routing/map.py", line 624, in match
    raise NotFound() from None
werkzeug.exceptions.NotFound: 404 Not Found: The requested URL was not found on the server. If you entered the URL manually please check your spelling and try again.

During handling of the above exception, another exception occurred:

Traceback (most recent call last):
  File "/Users/mnann/Documents/Code/PulseFi/venv/lib/python3.8/site-packages/flask/app.py", line 2528, in wsgi_app
    response = self.full_dispatch_request()
  File "/Users/mnann/Documents/Code/PulseFi/venv/lib/python3.8/site-packages/flask/app.py", line 1825, in full_dispatch_request
    rv = self.handle_user_exception(e)
  File "/Users/mnann/Documents/Code/PulseFi/venv/lib/python3.8/site-packages/flask/app.py", line 1669, in handle_user_exception
    return self.handle_http_exception(e)
  File "/Users/mnann/Documents/Code/PulseFi/venv/lib/python3.8/site-packages/flask/app.py", line 1609, in handle_http_exception
    return self.ensure_sync(handler)(e)
  File "/Users/mnann/Documents/Code/PulseFi/src/flask/app.py", line 130, in not_found_error
    return render_template('errors/404.html'), 404
  File "/Users/mnann/Documents/Code/PulseFi/venv/lib/python3.8/site-packages/flask/templating.py", line 147, in render_template
    return _render(app, template, context)
  File "/Users/mnann/Documents/Code/PulseFi/venv/lib/python3.8/site-packages/flask/templating.py", line 130, in _render
    rv = template.render(context)
  File "/Users/mnann/Documents/Code/PulseFi/venv/lib/python3.8/site-packages/jinja2/environment.py", line 1301, in render
    self.environment.handle_exception()
  File "/Users/mnann/Documents/Code/PulseFi/venv/lib/python3.8/site-packages/jinja2/environment.py", line 936, in handle_exception
    raise rewrite_traceback_stack(source=source)
  File "/Users/mnann/Documents/Code/PulseFi/src/flask/templates/errors/404.html", line 1, in top-level template code
    {% extends 'layouts/main.html' %}
  File "/Users/mnann/Documents/Code/PulseFi/src/flask/templates/layouts/main.html", line 99, in top-level template code
    {% block content %}{% endblock %}
  File "/Users/mnann/Documents/Code/PulseFi/src/flask/templates/errors/404.html", line 5, in block 'content'
    <p><a href="{{url_for('index')}}">Back</a></p>
  File "/Users/mnann/Documents/Code/PulseFi/venv/lib/python3.8/site-packages/flask/app.py", line 2034, in url_for
    return self.handle_url_build_error(error, endpoint, values)
  File "/Users/mnann/Documents/Code/PulseFi/venv/lib/python3.8/site-packages/flask/app.py", line 2023, in url_for
    rv = url_adapter.build(  # type: ignore[union-attr]
  File "/Users/mnann/Documents/Code/PulseFi/venv/lib/python3.8/site-packages/werkzeug/routing/map.py", line 917, in build
    raise BuildError(endpoint, values, method, self)
werkzeug.routing.exceptions.BuildError: Could not build url for endpoint 'index'. Did you mean 'login' instead?
2023-04-03 17:16:02,436 ERROR: Exception on /heart [GET] [in /Users/mnann/Documents/Code/PulseFi/venv/lib/python3.8/site-packages/flask/app.py:1744]
Traceback (most recent call last):
  File "/Users/mnann/Documents/Code/PulseFi/venv/lib/python3.8/site-packages/flask/app.py", line 1823, in full_dispatch_request
    rv = self.dispatch_request()
  File "/Users/mnann/Documents/Code/PulseFi/venv/lib/python3.8/site-packages/flask/app.py", line 1788, in dispatch_request
    self.raise_routing_exception(req)
  File "/Users/mnann/Documents/Code/PulseFi/venv/lib/python3.8/site-packages/flask/app.py", line 1770, in raise_routing_exception
    raise request.routing_exception  # type: ignore
  File "/Users/mnann/Documents/Code/PulseFi/venv/lib/python3.8/site-packages/flask/ctx.py", line 351, in match_request
    result = self.url_adapter.match(return_rule=True)  # type: ignore
  File "/Users/mnann/Documents/Code/PulseFi/venv/lib/python3.8/site-packages/werkzeug/routing/map.py", line 624, in match
    raise NotFound() from None
werkzeug.exceptions.NotFound: 404 Not Found: The requested URL was not found on the server. If you entered the URL manually please check your spelling and try again.

During handling of the above exception, another exception occurred:

Traceback (most recent call last):
  File "/Users/mnann/Documents/Code/PulseFi/venv/lib/python3.8/site-packages/flask/app.py", line 2528, in wsgi_app
    response = self.full_dispatch_request()
  File "/Users/mnann/Documents/Code/PulseFi/venv/lib/python3.8/site-packages/flask/app.py", line 1825, in full_dispatch_request
    rv = self.handle_user_exception(e)
  File "/Users/mnann/Documents/Code/PulseFi/venv/lib/python3.8/site-packages/flask/app.py", line 1669, in handle_user_exception
    return self.handle_http_exception(e)
  File "/Users/mnann/Documents/Code/PulseFi/venv/lib/python3.8/site-packages/flask/app.py", line 1609, in handle_http_exception
    return self.ensure_sync(handler)(e)
  File "/Users/mnann/Documents/Code/PulseFi/src/flask/app.py", line 130, in not_found_error
    return render_template('errors/404.html'), 404
  File "/Users/mnann/Documents/Code/PulseFi/venv/lib/python3.8/site-packages/flask/templating.py", line 147, in render_template
    return _render(app, template, context)
  File "/Users/mnann/Documents/Code/PulseFi/venv/lib/python3.8/site-packages/flask/templating.py", line 130, in _render
    rv = template.render(context)
  File "/Users/mnann/Documents/Code/PulseFi/venv/lib/python3.8/site-packages/jinja2/environment.py", line 1301, in render
    self.environment.handle_exception()
  File "/Users/mnann/Documents/Code/PulseFi/venv/lib/python3.8/site-packages/jinja2/environment.py", line 936, in handle_exception
    raise rewrite_traceback_stack(source=source)
  File "/Users/mnann/Documents/Code/PulseFi/src/flask/templates/errors/404.html", line 1, in top-level template code
    {% extends 'layouts/main.html' %}
  File "/Users/mnann/Documents/Code/PulseFi/src/flask/templates/layouts/main.html", line 99, in top-level template code
    {% block content %}{% endblock %}
  File "/Users/mnann/Documents/Code/PulseFi/src/flask/templates/errors/404.html", line 5, in block 'content'
    <p><a href="{{url_for('index')}}">Back</a></p>
  File "/Users/mnann/Documents/Code/PulseFi/venv/lib/python3.8/site-packages/flask/app.py", line 2034, in url_for
    return self.handle_url_build_error(error, endpoint, values)
  File "/Users/mnann/Documents/Code/PulseFi/venv/lib/python3.8/site-packages/flask/app.py", line 2023, in url_for
    rv = url_adapter.build(  # type: ignore[union-attr]
  File "/Users/mnann/Documents/Code/PulseFi/venv/lib/python3.8/site-packages/werkzeug/routing/map.py", line 917, in build
    raise BuildError(endpoint, values, method, self)
werkzeug.routing.exceptions.BuildError: Could not build url for endpoint 'index'. Did you mean 'login' instead?
2023-04-03 17:16:04,107 ERROR: Exception on /heartRat [GET] [in /Users/mnann/Documents/Code/PulseFi/venv/lib/python3.8/site-packages/flask/app.py:1744]
Traceback (most recent call last):
  File "/Users/mnann/Documents/Code/PulseFi/venv/lib/python3.8/site-packages/flask/app.py", line 1823, in full_dispatch_request
    rv = self.dispatch_request()
  File "/Users/mnann/Documents/Code/PulseFi/venv/lib/python3.8/site-packages/flask/app.py", line 1788, in dispatch_request
    self.raise_routing_exception(req)
  File "/Users/mnann/Documents/Code/PulseFi/venv/lib/python3.8/site-packages/flask/app.py", line 1770, in raise_routing_exception
    raise request.routing_exception  # type: ignore
  File "/Users/mnann/Documents/Code/PulseFi/venv/lib/python3.8/site-packages/flask/ctx.py", line 351, in match_request
    result = self.url_adapter.match(return_rule=True)  # type: ignore
  File "/Users/mnann/Documents/Code/PulseFi/venv/lib/python3.8/site-packages/werkzeug/routing/map.py", line 624, in match
    raise NotFound() from None
werkzeug.exceptions.NotFound: 404 Not Found: The requested URL was not found on the server. If you entered the URL manually please check your spelling and try again.

During handling of the above exception, another exception occurred:

Traceback (most recent call last):
  File "/Users/mnann/Documents/Code/PulseFi/venv/lib/python3.8/site-packages/flask/app.py", line 2528, in wsgi_app
    response = self.full_dispatch_request()
  File "/Users/mnann/Documents/Code/PulseFi/venv/lib/python3.8/site-packages/flask/app.py", line 1825, in full_dispatch_request
    rv = self.handle_user_exception(e)
  File "/Users/mnann/Documents/Code/PulseFi/venv/lib/python3.8/site-packages/flask/app.py", line 1669, in handle_user_exception
    return self.handle_http_exception(e)
  File "/Users/mnann/Documents/Code/PulseFi/venv/lib/python3.8/site-packages/flask/app.py", line 1609, in handle_http_exception
    return self.ensure_sync(handler)(e)
  File "/Users/mnann/Documents/Code/PulseFi/src/flask/app.py", line 130, in not_found_error
    return render_template('errors/404.html'), 404
  File "/Users/mnann/Documents/Code/PulseFi/venv/lib/python3.8/site-packages/flask/templating.py", line 147, in render_template
    return _render(app, template, context)
  File "/Users/mnann/Documents/Code/PulseFi/venv/lib/python3.8/site-packages/flask/templating.py", line 130, in _render
    rv = template.render(context)
  File "/Users/mnann/Documents/Code/PulseFi/venv/lib/python3.8/site-packages/jinja2/environment.py", line 1301, in render
    self.environment.handle_exception()
  File "/Users/mnann/Documents/Code/PulseFi/venv/lib/python3.8/site-packages/jinja2/environment.py", line 936, in handle_exception
    raise rewrite_traceback_stack(source=source)
  File "/Users/mnann/Documents/Code/PulseFi/src/flask/templates/errors/404.html", line 1, in top-level template code
    {% extends 'layouts/main.html' %}
  File "/Users/mnann/Documents/Code/PulseFi/src/flask/templates/layouts/main.html", line 99, in top-level template code
    {% block content %}{% endblock %}
  File "/Users/mnann/Documents/Code/PulseFi/src/flask/templates/errors/404.html", line 5, in block 'content'
    <p><a href="{{url_for('index')}}">Back</a></p>
  File "/Users/mnann/Documents/Code/PulseFi/venv/lib/python3.8/site-packages/flask/app.py", line 2034, in url_for
    return self.handle_url_build_error(error, endpoint, values)
  File "/Users/mnann/Documents/Code/PulseFi/venv/lib/python3.8/site-packages/flask/app.py", line 2023, in url_for
    rv = url_adapter.build(  # type: ignore[union-attr]
  File "/Users/mnann/Documents/Code/PulseFi/venv/lib/python3.8/site-packages/werkzeug/routing/map.py", line 917, in build
    raise BuildError(endpoint, values, method, self)
werkzeug.routing.exceptions.BuildError: Could not build url for endpoint 'index'. Did you mean 'login' instead?
2023-04-03 17:16:09,803 ERROR: Exception on /heartRat [GET] [in /Users/mnann/Documents/Code/PulseFi/venv/lib/python3.8/site-packages/flask/app.py:1744]
Traceback (most recent call last):
  File "/Users/mnann/Documents/Code/PulseFi/venv/lib/python3.8/site-packages/flask/app.py", line 1823, in full_dispatch_request
    rv = self.dispatch_request()
  File "/Users/mnann/Documents/Code/PulseFi/venv/lib/python3.8/site-packages/flask/app.py", line 1788, in dispatch_request
    self.raise_routing_exception(req)
  File "/Users/mnann/Documents/Code/PulseFi/venv/lib/python3.8/site-packages/flask/app.py", line 1770, in raise_routing_exception
    raise request.routing_exception  # type: ignore
  File "/Users/mnann/Documents/Code/PulseFi/venv/lib/python3.8/site-packages/flask/ctx.py", line 351, in match_request
    result = self.url_adapter.match(return_rule=True)  # type: ignore
  File "/Users/mnann/Documents/Code/PulseFi/venv/lib/python3.8/site-packages/werkzeug/routing/map.py", line 624, in match
    raise NotFound() from None
werkzeug.exceptions.NotFound: 404 Not Found: The requested URL was not found on the server. If you entered the URL manually please check your spelling and try again.

During handling of the above exception, another exception occurred:

Traceback (most recent call last):
  File "/Users/mnann/Documents/Code/PulseFi/venv/lib/python3.8/site-packages/flask/app.py", line 2528, in wsgi_app
    response = self.full_dispatch_request()
  File "/Users/mnann/Documents/Code/PulseFi/venv/lib/python3.8/site-packages/flask/app.py", line 1825, in full_dispatch_request
    rv = self.handle_user_exception(e)
  File "/Users/mnann/Documents/Code/PulseFi/venv/lib/python3.8/site-packages/flask/app.py", line 1669, in handle_user_exception
    return self.handle_http_exception(e)
  File "/Users/mnann/Documents/Code/PulseFi/venv/lib/python3.8/site-packages/flask/app.py", line 1609, in handle_http_exception
    return self.ensure_sync(handler)(e)
  File "/Users/mnann/Documents/Code/PulseFi/src/flask/app.py", line 130, in not_found_error
    return render_template('errors/404.html'), 404
  File "/Users/mnann/Documents/Code/PulseFi/venv/lib/python3.8/site-packages/flask/templating.py", line 147, in render_template
    return _render(app, template, context)
  File "/Users/mnann/Documents/Code/PulseFi/venv/lib/python3.8/site-packages/flask/templating.py", line 130, in _render
    rv = template.render(context)
  File "/Users/mnann/Documents/Code/PulseFi/venv/lib/python3.8/site-packages/jinja2/environment.py", line 1301, in render
    self.environment.handle_exception()
  File "/Users/mnann/Documents/Code/PulseFi/venv/lib/python3.8/site-packages/jinja2/environment.py", line 936, in handle_exception
    raise rewrite_traceback_stack(source=source)
  File "/Users/mnann/Documents/Code/PulseFi/src/flask/templates/errors/404.html", line 1, in top-level template code
    {% extends 'layouts/main.html' %}
  File "/Users/mnann/Documents/Code/PulseFi/src/flask/templates/layouts/main.html", line 99, in top-level template code
    {% block content %}{% endblock %}
  File "/Users/mnann/Documents/Code/PulseFi/src/flask/templates/errors/404.html", line 5, in block 'content'
    <p><a href="{{url_for('index')}}">Back</a></p>
  File "/Users/mnann/Documents/Code/PulseFi/venv/lib/python3.8/site-packages/flask/app.py", line 2034, in url_for
    return self.handle_url_build_error(error, endpoint, values)
  File "/Users/mnann/Documents/Code/PulseFi/venv/lib/python3.8/site-packages/flask/app.py", line 2023, in url_for
    rv = url_adapter.build(  # type: ignore[union-attr]
  File "/Users/mnann/Documents/Code/PulseFi/venv/lib/python3.8/site-packages/werkzeug/routing/map.py", line 917, in build
    raise BuildError(endpoint, values, method, self)
werkzeug.routing.exceptions.BuildError: Could not build url for endpoint 'index'. Did you mean 'login' instead?
2023-04-03 17:17:22,373 ERROR: Exception on /favicon.ico [GET] [in /Users/mnann/Documents/Code/PulseFi/venv/lib/python3.8/site-packages/flask/app.py:1744]
Traceback (most recent call last):
  File "/Users/mnann/Documents/Code/PulseFi/venv/lib/python3.8/site-packages/flask/app.py", line 1823, in full_dispatch_request
    rv = self.dispatch_request()
  File "/Users/mnann/Documents/Code/PulseFi/venv/lib/python3.8/site-packages/flask/app.py", line 1788, in dispatch_request
    self.raise_routing_exception(req)
  File "/Users/mnann/Documents/Code/PulseFi/venv/lib/python3.8/site-packages/flask/app.py", line 1770, in raise_routing_exception
    raise request.routing_exception  # type: ignore
  File "/Users/mnann/Documents/Code/PulseFi/venv/lib/python3.8/site-packages/flask/ctx.py", line 351, in match_request
    result = self.url_adapter.match(return_rule=True)  # type: ignore
  File "/Users/mnann/Documents/Code/PulseFi/venv/lib/python3.8/site-packages/werkzeug/routing/map.py", line 624, in match
    raise NotFound() from None
werkzeug.exceptions.NotFound: 404 Not Found: The requested URL was not found on the server. If you entered the URL manually please check your spelling and try again.

During handling of the above exception, another exception occurred:

Traceback (most recent call last):
  File "/Users/mnann/Documents/Code/PulseFi/venv/lib/python3.8/site-packages/flask/app.py", line 2528, in wsgi_app
    response = self.full_dispatch_request()
  File "/Users/mnann/Documents/Code/PulseFi/venv/lib/python3.8/site-packages/flask/app.py", line 1825, in full_dispatch_request
    rv = self.handle_user_exception(e)
  File "/Users/mnann/Documents/Code/PulseFi/venv/lib/python3.8/site-packages/flask/app.py", line 1669, in handle_user_exception
    return self.handle_http_exception(e)
  File "/Users/mnann/Documents/Code/PulseFi/venv/lib/python3.8/site-packages/flask/app.py", line 1609, in handle_http_exception
    return self.ensure_sync(handler)(e)
  File "/Users/mnann/Documents/Code/PulseFi/src/flask/app.py", line 130, in not_found_error
    return render_template('errors/404.html'), 404
  File "/Users/mnann/Documents/Code/PulseFi/venv/lib/python3.8/site-packages/flask/templating.py", line 147, in render_template
    return _render(app, template, context)
  File "/Users/mnann/Documents/Code/PulseFi/venv/lib/python3.8/site-packages/flask/templating.py", line 130, in _render
    rv = template.render(context)
  File "/Users/mnann/Documents/Code/PulseFi/venv/lib/python3.8/site-packages/jinja2/environment.py", line 1301, in render
    self.environment.handle_exception()
  File "/Users/mnann/Documents/Code/PulseFi/venv/lib/python3.8/site-packages/jinja2/environment.py", line 936, in handle_exception
    raise rewrite_traceback_stack(source=source)
  File "/Users/mnann/Documents/Code/PulseFi/src/flask/templates/errors/404.html", line 1, in top-level template code
    {% extends 'layouts/main.html' %}
  File "/Users/mnann/Documents/Code/PulseFi/src/flask/templates/layouts/main.html", line 99, in top-level template code
    {% block content %}{% endblock %}
  File "/Users/mnann/Documents/Code/PulseFi/src/flask/templates/errors/404.html", line 5, in block 'content'
    <p><a href="{{url_for('index')}}">Back</a></p>
  File "/Users/mnann/Documents/Code/PulseFi/venv/lib/python3.8/site-packages/flask/app.py", line 2034, in url_for
    return self.handle_url_build_error(error, endpoint, values)
  File "/Users/mnann/Documents/Code/PulseFi/venv/lib/python3.8/site-packages/flask/app.py", line 2023, in url_for
    rv = url_adapter.build(  # type: ignore[union-attr]
  File "/Users/mnann/Documents/Code/PulseFi/venv/lib/python3.8/site-packages/werkzeug/routing/map.py", line 917, in build
    raise BuildError(endpoint, values, method, self)
werkzeug.routing.exceptions.BuildError: Could not build url for endpoint 'index'. Did you mean 'login' instead?
2023-04-03 17:17:49,467 ERROR: Exception on /heartRat [GET] [in /Users/mnann/Documents/Code/PulseFi/venv/lib/python3.8/site-packages/flask/app.py:1744]
Traceback (most recent call last):
  File "/Users/mnann/Documents/Code/PulseFi/venv/lib/python3.8/site-packages/flask/app.py", line 1823, in full_dispatch_request
    rv = self.dispatch_request()
  File "/Users/mnann/Documents/Code/PulseFi/venv/lib/python3.8/site-packages/flask/app.py", line 1788, in dispatch_request
    self.raise_routing_exception(req)
  File "/Users/mnann/Documents/Code/PulseFi/venv/lib/python3.8/site-packages/flask/app.py", line 1770, in raise_routing_exception
    raise request.routing_exception  # type: ignore
  File "/Users/mnann/Documents/Code/PulseFi/venv/lib/python3.8/site-packages/flask/ctx.py", line 351, in match_request
    result = self.url_adapter.match(return_rule=True)  # type: ignore
  File "/Users/mnann/Documents/Code/PulseFi/venv/lib/python3.8/site-packages/werkzeug/routing/map.py", line 624, in match
    raise NotFound() from None
werkzeug.exceptions.NotFound: 404 Not Found: The requested URL was not found on the server. If you entered the URL manually please check your spelling and try again.

During handling of the above exception, another exception occurred:

Traceback (most recent call last):
  File "/Users/mnann/Documents/Code/PulseFi/venv/lib/python3.8/site-packages/flask/app.py", line 2528, in wsgi_app
    response = self.full_dispatch_request()
  File "/Users/mnann/Documents/Code/PulseFi/venv/lib/python3.8/site-packages/flask/app.py", line 1825, in full_dispatch_request
    rv = self.handle_user_exception(e)
  File "/Users/mnann/Documents/Code/PulseFi/venv/lib/python3.8/site-packages/flask/app.py", line 1669, in handle_user_exception
    return self.handle_http_exception(e)
  File "/Users/mnann/Documents/Code/PulseFi/venv/lib/python3.8/site-packages/flask/app.py", line 1609, in handle_http_exception
    return self.ensure_sync(handler)(e)
  File "/Users/mnann/Documents/Code/PulseFi/src/flask/app.py", line 130, in not_found_error
    return render_template('errors/404.html'), 404
  File "/Users/mnann/Documents/Code/PulseFi/venv/lib/python3.8/site-packages/flask/templating.py", line 147, in render_template
    return _render(app, template, context)
  File "/Users/mnann/Documents/Code/PulseFi/venv/lib/python3.8/site-packages/flask/templating.py", line 130, in _render
    rv = template.render(context)
  File "/Users/mnann/Documents/Code/PulseFi/venv/lib/python3.8/site-packages/jinja2/environment.py", line 1301, in render
    self.environment.handle_exception()
  File "/Users/mnann/Documents/Code/PulseFi/venv/lib/python3.8/site-packages/jinja2/environment.py", line 936, in handle_exception
    raise rewrite_traceback_stack(source=source)
  File "/Users/mnann/Documents/Code/PulseFi/src/flask/templates/errors/404.html", line 1, in top-level template code
    {% extends 'layouts/main.html' %}
  File "/Users/mnann/Documents/Code/PulseFi/src/flask/templates/layouts/main.html", line 99, in top-level template code
    {% block content %}{% endblock %}
  File "/Users/mnann/Documents/Code/PulseFi/src/flask/templates/errors/404.html", line 5, in block 'content'
    <p><a href="{{url_for('index')}}">Back</a></p>
  File "/Users/mnann/Documents/Code/PulseFi/venv/lib/python3.8/site-packages/flask/app.py", line 2034, in url_for
    return self.handle_url_build_error(error, endpoint, values)
  File "/Users/mnann/Documents/Code/PulseFi/venv/lib/python3.8/site-packages/flask/app.py", line 2023, in url_for
    rv = url_adapter.build(  # type: ignore[union-attr]
  File "/Users/mnann/Documents/Code/PulseFi/venv/lib/python3.8/site-packages/werkzeug/routing/map.py", line 917, in build
    raise BuildError(endpoint, values, method, self)
werkzeug.routing.exceptions.BuildError: Could not build url for endpoint 'index'. Did you mean 'login' instead?
2023-04-03 17:20:00,530 INFO: errors [in /Users/mnann/Documents/Code/PulseFi/src/flask/app.py:145]
2023-04-03 17:20:09,956 ERROR: Exception on /heart [GET] [in /Users/mnann/Documents/Code/PulseFi/venv/lib/python3.8/site-packages/flask/app.py:1744]
Traceback (most recent call last):
  File "/Users/mnann/Documents/Code/PulseFi/venv/lib/python3.8/site-packages/flask/app.py", line 1823, in full_dispatch_request
    rv = self.dispatch_request()
  File "/Users/mnann/Documents/Code/PulseFi/venv/lib/python3.8/site-packages/flask/app.py", line 1788, in dispatch_request
    self.raise_routing_exception(req)
  File "/Users/mnann/Documents/Code/PulseFi/venv/lib/python3.8/site-packages/flask/app.py", line 1770, in raise_routing_exception
    raise request.routing_exception  # type: ignore
  File "/Users/mnann/Documents/Code/PulseFi/venv/lib/python3.8/site-packages/flask/ctx.py", line 351, in match_request
    result = self.url_adapter.match(return_rule=True)  # type: ignore
  File "/Users/mnann/Documents/Code/PulseFi/venv/lib/python3.8/site-packages/werkzeug/routing/map.py", line 624, in match
    raise NotFound() from None
werkzeug.exceptions.NotFound: 404 Not Found: The requested URL was not found on the server. If you entered the URL manually please check your spelling and try again.

During handling of the above exception, another exception occurred:

Traceback (most recent call last):
  File "/Users/mnann/Documents/Code/PulseFi/venv/lib/python3.8/site-packages/flask/app.py", line 2528, in wsgi_app
    response = self.full_dispatch_request()
  File "/Users/mnann/Documents/Code/PulseFi/venv/lib/python3.8/site-packages/flask/app.py", line 1825, in full_dispatch_request
    rv = self.handle_user_exception(e)
  File "/Users/mnann/Documents/Code/PulseFi/venv/lib/python3.8/site-packages/flask/app.py", line 1669, in handle_user_exception
    return self.handle_http_exception(e)
  File "/Users/mnann/Documents/Code/PulseFi/venv/lib/python3.8/site-packages/flask/app.py", line 1609, in handle_http_exception
    return self.ensure_sync(handler)(e)
  File "/Users/mnann/Documents/Code/PulseFi/src/flask/app.py", line 130, in not_found_error
    return render_template('errors/404.html'), 404
  File "/Users/mnann/Documents/Code/PulseFi/venv/lib/python3.8/site-packages/flask/templating.py", line 147, in render_template
    return _render(app, template, context)
  File "/Users/mnann/Documents/Code/PulseFi/venv/lib/python3.8/site-packages/flask/templating.py", line 130, in _render
    rv = template.render(context)
  File "/Users/mnann/Documents/Code/PulseFi/venv/lib/python3.8/site-packages/jinja2/environment.py", line 1301, in render
    self.environment.handle_exception()
  File "/Users/mnann/Documents/Code/PulseFi/venv/lib/python3.8/site-packages/jinja2/environment.py", line 936, in handle_exception
    raise rewrite_traceback_stack(source=source)
  File "/Users/mnann/Documents/Code/PulseFi/src/flask/templates/errors/404.html", line 1, in top-level template code
    {% extends 'layouts/main.html' %}
  File "/Users/mnann/Documents/Code/PulseFi/src/flask/templates/layouts/main.html", line 99, in top-level template code
    {% block content %}{% endblock %}
  File "/Users/mnann/Documents/Code/PulseFi/src/flask/templates/errors/404.html", line 5, in block 'content'
    <p><a href="{{url_for('index')}}">Back</a></p>
  File "/Users/mnann/Documents/Code/PulseFi/venv/lib/python3.8/site-packages/flask/app.py", line 2034, in url_for
    return self.handle_url_build_error(error, endpoint, values)
  File "/Users/mnann/Documents/Code/PulseFi/venv/lib/python3.8/site-packages/flask/app.py", line 2023, in url_for
    rv = url_adapter.build(  # type: ignore[union-attr]
  File "/Users/mnann/Documents/Code/PulseFi/venv/lib/python3.8/site-packages/werkzeug/routing/map.py", line 917, in build
    raise BuildError(endpoint, values, method, self)
werkzeug.routing.exceptions.BuildError: Could not build url for endpoint 'index'. Did you mean 'login' instead?
2023-04-03 17:20:11,135 ERROR: Exception on /heart [GET] [in /Users/mnann/Documents/Code/PulseFi/venv/lib/python3.8/site-packages/flask/app.py:1744]
Traceback (most recent call last):
  File "/Users/mnann/Documents/Code/PulseFi/venv/lib/python3.8/site-packages/flask/app.py", line 1823, in full_dispatch_request
    rv = self.dispatch_request()
  File "/Users/mnann/Documents/Code/PulseFi/venv/lib/python3.8/site-packages/flask/app.py", line 1788, in dispatch_request
    self.raise_routing_exception(req)
  File "/Users/mnann/Documents/Code/PulseFi/venv/lib/python3.8/site-packages/flask/app.py", line 1770, in raise_routing_exception
    raise request.routing_exception  # type: ignore
  File "/Users/mnann/Documents/Code/PulseFi/venv/lib/python3.8/site-packages/flask/ctx.py", line 351, in match_request
    result = self.url_adapter.match(return_rule=True)  # type: ignore
  File "/Users/mnann/Documents/Code/PulseFi/venv/lib/python3.8/site-packages/werkzeug/routing/map.py", line 624, in match
    raise NotFound() from None
werkzeug.exceptions.NotFound: 404 Not Found: The requested URL was not found on the server. If you entered the URL manually please check your spelling and try again.

During handling of the above exception, another exception occurred:

Traceback (most recent call last):
  File "/Users/mnann/Documents/Code/PulseFi/venv/lib/python3.8/site-packages/flask/app.py", line 2528, in wsgi_app
    response = self.full_dispatch_request()
  File "/Users/mnann/Documents/Code/PulseFi/venv/lib/python3.8/site-packages/flask/app.py", line 1825, in full_dispatch_request
    rv = self.handle_user_exception(e)
  File "/Users/mnann/Documents/Code/PulseFi/venv/lib/python3.8/site-packages/flask/app.py", line 1669, in handle_user_exception
    return self.handle_http_exception(e)
  File "/Users/mnann/Documents/Code/PulseFi/venv/lib/python3.8/site-packages/flask/app.py", line 1609, in handle_http_exception
    return self.ensure_sync(handler)(e)
  File "/Users/mnann/Documents/Code/PulseFi/src/flask/app.py", line 130, in not_found_error
    return render_template('errors/404.html'), 404
  File "/Users/mnann/Documents/Code/PulseFi/venv/lib/python3.8/site-packages/flask/templating.py", line 147, in render_template
    return _render(app, template, context)
  File "/Users/mnann/Documents/Code/PulseFi/venv/lib/python3.8/site-packages/flask/templating.py", line 130, in _render
    rv = template.render(context)
  File "/Users/mnann/Documents/Code/PulseFi/venv/lib/python3.8/site-packages/jinja2/environment.py", line 1301, in render
    self.environment.handle_exception()
  File "/Users/mnann/Documents/Code/PulseFi/venv/lib/python3.8/site-packages/jinja2/environment.py", line 936, in handle_exception
    raise rewrite_traceback_stack(source=source)
  File "/Users/mnann/Documents/Code/PulseFi/src/flask/templates/errors/404.html", line 1, in top-level template code
    {% extends 'layouts/main.html' %}
  File "/Users/mnann/Documents/Code/PulseFi/src/flask/templates/layouts/main.html", line 99, in top-level template code
    {% block content %}{% endblock %}
  File "/Users/mnann/Documents/Code/PulseFi/src/flask/templates/errors/404.html", line 5, in block 'content'
    <p><a href="{{url_for('index')}}">Back</a></p>
  File "/Users/mnann/Documents/Code/PulseFi/venv/lib/python3.8/site-packages/flask/app.py", line 2034, in url_for
    return self.handle_url_build_error(error, endpoint, values)
  File "/Users/mnann/Documents/Code/PulseFi/venv/lib/python3.8/site-packages/flask/app.py", line 2023, in url_for
    rv = url_adapter.build(  # type: ignore[union-attr]
  File "/Users/mnann/Documents/Code/PulseFi/venv/lib/python3.8/site-packages/werkzeug/routing/map.py", line 917, in build
    raise BuildError(endpoint, values, method, self)
werkzeug.routing.exceptions.BuildError: Could not build url for endpoint 'index'. Did you mean 'login' instead?
2023-04-03 17:20:16,657 ERROR: Exception on /heartRat [GET] [in /Users/mnann/Documents/Code/PulseFi/venv/lib/python3.8/site-packages/flask/app.py:1744]
Traceback (most recent call last):
  File "/Users/mnann/Documents/Code/PulseFi/venv/lib/python3.8/site-packages/flask/app.py", line 1823, in full_dispatch_request
    rv = self.dispatch_request()
  File "/Users/mnann/Documents/Code/PulseFi/venv/lib/python3.8/site-packages/flask/app.py", line 1788, in dispatch_request
    self.raise_routing_exception(req)
  File "/Users/mnann/Documents/Code/PulseFi/venv/lib/python3.8/site-packages/flask/app.py", line 1770, in raise_routing_exception
    raise request.routing_exception  # type: ignore
  File "/Users/mnann/Documents/Code/PulseFi/venv/lib/python3.8/site-packages/flask/ctx.py", line 351, in match_request
    result = self.url_adapter.match(return_rule=True)  # type: ignore
  File "/Users/mnann/Documents/Code/PulseFi/venv/lib/python3.8/site-packages/werkzeug/routing/map.py", line 624, in match
    raise NotFound() from None
werkzeug.exceptions.NotFound: 404 Not Found: The requested URL was not found on the server. If you entered the URL manually please check your spelling and try again.

During handling of the above exception, another exception occurred:

Traceback (most recent call last):
  File "/Users/mnann/Documents/Code/PulseFi/venv/lib/python3.8/site-packages/flask/app.py", line 2528, in wsgi_app
    response = self.full_dispatch_request()
  File "/Users/mnann/Documents/Code/PulseFi/venv/lib/python3.8/site-packages/flask/app.py", line 1825, in full_dispatch_request
    rv = self.handle_user_exception(e)
  File "/Users/mnann/Documents/Code/PulseFi/venv/lib/python3.8/site-packages/flask/app.py", line 1669, in handle_user_exception
    return self.handle_http_exception(e)
  File "/Users/mnann/Documents/Code/PulseFi/venv/lib/python3.8/site-packages/flask/app.py", line 1609, in handle_http_exception
    return self.ensure_sync(handler)(e)
  File "/Users/mnann/Documents/Code/PulseFi/src/flask/app.py", line 130, in not_found_error
    return render_template('errors/404.html'), 404
  File "/Users/mnann/Documents/Code/PulseFi/venv/lib/python3.8/site-packages/flask/templating.py", line 147, in render_template
    return _render(app, template, context)
  File "/Users/mnann/Documents/Code/PulseFi/venv/lib/python3.8/site-packages/flask/templating.py", line 130, in _render
    rv = template.render(context)
  File "/Users/mnann/Documents/Code/PulseFi/venv/lib/python3.8/site-packages/jinja2/environment.py", line 1301, in render
    self.environment.handle_exception()
  File "/Users/mnann/Documents/Code/PulseFi/venv/lib/python3.8/site-packages/jinja2/environment.py", line 936, in handle_exception
    raise rewrite_traceback_stack(source=source)
  File "/Users/mnann/Documents/Code/PulseFi/src/flask/templates/errors/404.html", line 1, in top-level template code
    {% extends 'layouts/main.html' %}
  File "/Users/mnann/Documents/Code/PulseFi/src/flask/templates/layouts/main.html", line 99, in top-level template code
    {% block content %}{% endblock %}
  File "/Users/mnann/Documents/Code/PulseFi/src/flask/templates/errors/404.html", line 5, in block 'content'
    <p><a href="{{url_for('index')}}">Back</a></p>
  File "/Users/mnann/Documents/Code/PulseFi/venv/lib/python3.8/site-packages/flask/app.py", line 2034, in url_for
    return self.handle_url_build_error(error, endpoint, values)
  File "/Users/mnann/Documents/Code/PulseFi/venv/lib/python3.8/site-packages/flask/app.py", line 2023, in url_for
    rv = url_adapter.build(  # type: ignore[union-attr]
  File "/Users/mnann/Documents/Code/PulseFi/venv/lib/python3.8/site-packages/werkzeug/routing/map.py", line 917, in build
    raise BuildError(endpoint, values, method, self)
werkzeug.routing.exceptions.BuildError: Could not build url for endpoint 'index'. Did you mean 'login' instead?
2023-04-03 17:22:47,040 INFO: errors [in /Users/mnann/Documents/Code/PulseFi/src/flask/app.py:145]
2023-04-03 17:22:51,215 ERROR: Exception on / [GET] [in /Users/mnann/Documents/Code/PulseFi/venv/lib/python3.8/site-packages/flask/app.py:1744]
Traceback (most recent call last):
  File "/Users/mnann/Documents/Code/PulseFi/venv/lib/python3.8/site-packages/flask/app.py", line 2528, in wsgi_app
    response = self.full_dispatch_request()
  File "/Users/mnann/Documents/Code/PulseFi/venv/lib/python3.8/site-packages/flask/app.py", line 1825, in full_dispatch_request
    rv = self.handle_user_exception(e)
  File "/Users/mnann/Documents/Code/PulseFi/venv/lib/python3.8/site-packages/flask/app.py", line 1823, in full_dispatch_request
    rv = self.dispatch_request()
  File "/Users/mnann/Documents/Code/PulseFi/venv/lib/python3.8/site-packages/flask/app.py", line 1799, in dispatch_request
    return self.ensure_sync(self.view_functions[rule.endpoint])(**view_args)
  File "/Users/mnann/Documents/Code/PulseFi/src/flask/app.py", line 72, in home
    return render_template('pages/placeholder.home.html')
  File "/Users/mnann/Documents/Code/PulseFi/venv/lib/python3.8/site-packages/flask/templating.py", line 147, in render_template
    return _render(app, template, context)
  File "/Users/mnann/Documents/Code/PulseFi/venv/lib/python3.8/site-packages/flask/templating.py", line 130, in _render
    rv = template.render(context)
  File "/Users/mnann/Documents/Code/PulseFi/venv/lib/python3.8/site-packages/jinja2/environment.py", line 1301, in render
    self.environment.handle_exception()
  File "/Users/mnann/Documents/Code/PulseFi/venv/lib/python3.8/site-packages/jinja2/environment.py", line 936, in handle_exception
    raise rewrite_traceback_stack(source=source)
  File "/Users/mnann/Documents/Code/PulseFi/src/flask/templates/pages/placeholder.home.html", line 1, in top-level template code
    {% extends 'layouts/main.html' %}
  File "/Users/mnann/Documents/Code/PulseFi/src/flask/templates/layouts/main.html", line 107, in top-level template code
    <link rel="prerender" href="{{ url_for('heartRate') }}">
  File "/Users/mnann/Documents/Code/PulseFi/venv/lib/python3.8/site-packages/flask/app.py", line 2034, in url_for
    return self.handle_url_build_error(error, endpoint, values)
  File "/Users/mnann/Documents/Code/PulseFi/venv/lib/python3.8/site-packages/flask/app.py", line 2023, in url_for
    rv = url_adapter.build(  # type: ignore[union-attr]
  File "/Users/mnann/Documents/Code/PulseFi/venv/lib/python3.8/site-packages/werkzeug/routing/map.py", line 917, in build
    raise BuildError(endpoint, values, method, self)
werkzeug.routing.exceptions.BuildError: Could not build url for endpoint 'heartRate' with values ['random']. Did you mean 'heart_rate_bp.heartRate' instead?
2023-04-03 17:22:53,581 ERROR: Exception on / [GET] [in /Users/mnann/Documents/Code/PulseFi/venv/lib/python3.8/site-packages/flask/app.py:1744]
Traceback (most recent call last):
  File "/Users/mnann/Documents/Code/PulseFi/venv/lib/python3.8/site-packages/flask/app.py", line 2528, in wsgi_app
    response = self.full_dispatch_request()
  File "/Users/mnann/Documents/Code/PulseFi/venv/lib/python3.8/site-packages/flask/app.py", line 1825, in full_dispatch_request
    rv = self.handle_user_exception(e)
  File "/Users/mnann/Documents/Code/PulseFi/venv/lib/python3.8/site-packages/flask/app.py", line 1823, in full_dispatch_request
    rv = self.dispatch_request()
  File "/Users/mnann/Documents/Code/PulseFi/venv/lib/python3.8/site-packages/flask/app.py", line 1799, in dispatch_request
    return self.ensure_sync(self.view_functions[rule.endpoint])(**view_args)
  File "/Users/mnann/Documents/Code/PulseFi/src/flask/app.py", line 72, in home
    return render_template('pages/placeholder.home.html')
  File "/Users/mnann/Documents/Code/PulseFi/venv/lib/python3.8/site-packages/flask/templating.py", line 147, in render_template
    return _render(app, template, context)
  File "/Users/mnann/Documents/Code/PulseFi/venv/lib/python3.8/site-packages/flask/templating.py", line 130, in _render
    rv = template.render(context)
  File "/Users/mnann/Documents/Code/PulseFi/venv/lib/python3.8/site-packages/jinja2/environment.py", line 1301, in render
    self.environment.handle_exception()
  File "/Users/mnann/Documents/Code/PulseFi/venv/lib/python3.8/site-packages/jinja2/environment.py", line 936, in handle_exception
    raise rewrite_traceback_stack(source=source)
  File "/Users/mnann/Documents/Code/PulseFi/src/flask/templates/pages/placeholder.home.html", line 1, in top-level template code
    {% extends 'layouts/main.html' %}
  File "/Users/mnann/Documents/Code/PulseFi/src/flask/templates/layouts/main.html", line 107, in top-level template code
    <link rel="prerender" href="{{ url_for('heartRate') }}">
  File "/Users/mnann/Documents/Code/PulseFi/venv/lib/python3.8/site-packages/flask/app.py", line 2034, in url_for
    return self.handle_url_build_error(error, endpoint, values)
  File "/Users/mnann/Documents/Code/PulseFi/venv/lib/python3.8/site-packages/flask/app.py", line 2023, in url_for
    rv = url_adapter.build(  # type: ignore[union-attr]
  File "/Users/mnann/Documents/Code/PulseFi/venv/lib/python3.8/site-packages/werkzeug/routing/map.py", line 917, in build
    raise BuildError(endpoint, values, method, self)
werkzeug.routing.exceptions.BuildError: Could not build url for endpoint 'heartRate' with values ['random']. Did you mean 'heart_rate_bp.heartRate' instead?
2023-04-03 17:23:15,020 INFO: errors [in /Users/mnann/Documents/Code/PulseFi/src/flask/app.py:145]
2023-04-03 17:23:15,614 ERROR: Exception on / [GET] [in /Users/mnann/Documents/Code/PulseFi/venv/lib/python3.8/site-packages/flask/app.py:1744]
Traceback (most recent call last):
  File "/Users/mnann/Documents/Code/PulseFi/venv/lib/python3.8/site-packages/flask/app.py", line 2528, in wsgi_app
    response = self.full_dispatch_request()
  File "/Users/mnann/Documents/Code/PulseFi/venv/lib/python3.8/site-packages/flask/app.py", line 1825, in full_dispatch_request
    rv = self.handle_user_exception(e)
  File "/Users/mnann/Documents/Code/PulseFi/venv/lib/python3.8/site-packages/flask/app.py", line 1823, in full_dispatch_request
    rv = self.dispatch_request()
  File "/Users/mnann/Documents/Code/PulseFi/venv/lib/python3.8/site-packages/flask/app.py", line 1799, in dispatch_request
    return self.ensure_sync(self.view_functions[rule.endpoint])(**view_args)
  File "/Users/mnann/Documents/Code/PulseFi/src/flask/app.py", line 72, in home
    return render_template('pages/placeholder.home.html')
  File "/Users/mnann/Documents/Code/PulseFi/venv/lib/python3.8/site-packages/flask/templating.py", line 147, in render_template
    return _render(app, template, context)
  File "/Users/mnann/Documents/Code/PulseFi/venv/lib/python3.8/site-packages/flask/templating.py", line 130, in _render
    rv = template.render(context)
  File "/Users/mnann/Documents/Code/PulseFi/venv/lib/python3.8/site-packages/jinja2/environment.py", line 1301, in render
    self.environment.handle_exception()
  File "/Users/mnann/Documents/Code/PulseFi/venv/lib/python3.8/site-packages/jinja2/environment.py", line 936, in handle_exception
    raise rewrite_traceback_stack(source=source)
  File "/Users/mnann/Documents/Code/PulseFi/src/flask/templates/pages/placeholder.home.html", line 1, in top-level template code
    {% extends 'layouts/main.html' %}
  File "/Users/mnann/Documents/Code/PulseFi/src/flask/templates/layouts/main.html", line 107, in top-level template code
    <link rel="prerender" href="{{ url_for('heartRate') }}">
  File "/Users/mnann/Documents/Code/PulseFi/venv/lib/python3.8/site-packages/flask/app.py", line 2034, in url_for
    return self.handle_url_build_error(error, endpoint, values)
  File "/Users/mnann/Documents/Code/PulseFi/venv/lib/python3.8/site-packages/flask/app.py", line 2023, in url_for
    rv = url_adapter.build(  # type: ignore[union-attr]
  File "/Users/mnann/Documents/Code/PulseFi/venv/lib/python3.8/site-packages/werkzeug/routing/map.py", line 917, in build
    raise BuildError(endpoint, values, method, self)
werkzeug.routing.exceptions.BuildError: Could not build url for endpoint 'heartRate'. Did you mean 'heart_rate_bp.heartRate' instead?
2023-04-03 17:23:17,343 ERROR: Exception on / [GET] [in /Users/mnann/Documents/Code/PulseFi/venv/lib/python3.8/site-packages/flask/app.py:1744]
Traceback (most recent call last):
  File "/Users/mnann/Documents/Code/PulseFi/venv/lib/python3.8/site-packages/flask/app.py", line 2528, in wsgi_app
    response = self.full_dispatch_request()
  File "/Users/mnann/Documents/Code/PulseFi/venv/lib/python3.8/site-packages/flask/app.py", line 1825, in full_dispatch_request
    rv = self.handle_user_exception(e)
  File "/Users/mnann/Documents/Code/PulseFi/venv/lib/python3.8/site-packages/flask/app.py", line 1823, in full_dispatch_request
    rv = self.dispatch_request()
  File "/Users/mnann/Documents/Code/PulseFi/venv/lib/python3.8/site-packages/flask/app.py", line 1799, in dispatch_request
    return self.ensure_sync(self.view_functions[rule.endpoint])(**view_args)
  File "/Users/mnann/Documents/Code/PulseFi/src/flask/app.py", line 72, in home
    return render_template('pages/placeholder.home.html')
  File "/Users/mnann/Documents/Code/PulseFi/venv/lib/python3.8/site-packages/flask/templating.py", line 147, in render_template
    return _render(app, template, context)
  File "/Users/mnann/Documents/Code/PulseFi/venv/lib/python3.8/site-packages/flask/templating.py", line 130, in _render
    rv = template.render(context)
  File "/Users/mnann/Documents/Code/PulseFi/venv/lib/python3.8/site-packages/jinja2/environment.py", line 1301, in render
    self.environment.handle_exception()
  File "/Users/mnann/Documents/Code/PulseFi/venv/lib/python3.8/site-packages/jinja2/environment.py", line 936, in handle_exception
    raise rewrite_traceback_stack(source=source)
  File "/Users/mnann/Documents/Code/PulseFi/src/flask/templates/pages/placeholder.home.html", line 1, in top-level template code
    {% extends 'layouts/main.html' %}
  File "/Users/mnann/Documents/Code/PulseFi/src/flask/templates/layouts/main.html", line 107, in top-level template code
    <link rel="prerender" href="{{ url_for('heartRate') }}">
  File "/Users/mnann/Documents/Code/PulseFi/venv/lib/python3.8/site-packages/flask/app.py", line 2034, in url_for
    return self.handle_url_build_error(error, endpoint, values)
  File "/Users/mnann/Documents/Code/PulseFi/venv/lib/python3.8/site-packages/flask/app.py", line 2023, in url_for
    rv = url_adapter.build(  # type: ignore[union-attr]
  File "/Users/mnann/Documents/Code/PulseFi/venv/lib/python3.8/site-packages/werkzeug/routing/map.py", line 917, in build
    raise BuildError(endpoint, values, method, self)
werkzeug.routing.exceptions.BuildError: Could not build url for endpoint 'heartRate'. Did you mean 'heart_rate_bp.heartRate' instead?
2023-04-03 17:23:43,275 INFO: errors [in /Users/mnann/Documents/Code/PulseFi/src/flask/app.py:145]
2023-04-03 17:24:20,545 INFO: errors [in /Users/mnann/Documents/Code/PulseFi/src/flask/app.py:145]
2023-04-03 17:25:06,324 INFO: errors [in /Users/mnann/Documents/Code/PulseFi/src/flask/app.py:145]
2023-04-03 17:25:42,048 INFO: errors [in /Users/mnann/Documents/Code/PulseFi/src/flask/app.py:145]
2023-04-03 17:26:10,687 INFO: errors [in /Users/mnann/Documents/Code/PulseFi/src/flask/app.py:145]
2023-04-03 17:26:17,759 ERROR: Exception on /heartRat [GET] [in /Users/mnann/Documents/Code/PulseFi/venv/lib/python3.8/site-packages/flask/app.py:1744]
Traceback (most recent call last):
  File "/Users/mnann/Documents/Code/PulseFi/venv/lib/python3.8/site-packages/flask/app.py", line 1823, in full_dispatch_request
    rv = self.dispatch_request()
  File "/Users/mnann/Documents/Code/PulseFi/venv/lib/python3.8/site-packages/flask/app.py", line 1788, in dispatch_request
    self.raise_routing_exception(req)
  File "/Users/mnann/Documents/Code/PulseFi/venv/lib/python3.8/site-packages/flask/app.py", line 1770, in raise_routing_exception
    raise request.routing_exception  # type: ignore
  File "/Users/mnann/Documents/Code/PulseFi/venv/lib/python3.8/site-packages/flask/ctx.py", line 351, in match_request
    result = self.url_adapter.match(return_rule=True)  # type: ignore
  File "/Users/mnann/Documents/Code/PulseFi/venv/lib/python3.8/site-packages/werkzeug/routing/map.py", line 624, in match
    raise NotFound() from None
werkzeug.exceptions.NotFound: 404 Not Found: The requested URL was not found on the server. If you entered the URL manually please check your spelling and try again.

During handling of the above exception, another exception occurred:

Traceback (most recent call last):
  File "/Users/mnann/Documents/Code/PulseFi/venv/lib/python3.8/site-packages/flask/app.py", line 2528, in wsgi_app
    response = self.full_dispatch_request()
  File "/Users/mnann/Documents/Code/PulseFi/venv/lib/python3.8/site-packages/flask/app.py", line 1825, in full_dispatch_request
    rv = self.handle_user_exception(e)
  File "/Users/mnann/Documents/Code/PulseFi/venv/lib/python3.8/site-packages/flask/app.py", line 1669, in handle_user_exception
    return self.handle_http_exception(e)
  File "/Users/mnann/Documents/Code/PulseFi/venv/lib/python3.8/site-packages/flask/app.py", line 1609, in handle_http_exception
    return self.ensure_sync(handler)(e)
  File "/Users/mnann/Documents/Code/PulseFi/src/flask/app.py", line 130, in not_found_error
    return render_template('errors/404.html'), 404
  File "/Users/mnann/Documents/Code/PulseFi/venv/lib/python3.8/site-packages/flask/templating.py", line 147, in render_template
    return _render(app, template, context)
  File "/Users/mnann/Documents/Code/PulseFi/venv/lib/python3.8/site-packages/flask/templating.py", line 130, in _render
    rv = template.render(context)
  File "/Users/mnann/Documents/Code/PulseFi/venv/lib/python3.8/site-packages/jinja2/environment.py", line 1301, in render
    self.environment.handle_exception()
  File "/Users/mnann/Documents/Code/PulseFi/venv/lib/python3.8/site-packages/jinja2/environment.py", line 936, in handle_exception
    raise rewrite_traceback_stack(source=source)
  File "/Users/mnann/Documents/Code/PulseFi/src/flask/templates/errors/404.html", line 1, in top-level template code
    {% extends 'layouts/main.html' %}
  File "/Users/mnann/Documents/Code/PulseFi/src/flask/templates/layouts/main.html", line 99, in top-level template code
    {% block content %}{% endblock %}
  File "/Users/mnann/Documents/Code/PulseFi/src/flask/templates/errors/404.html", line 5, in block 'content'
    <p><a href="{{url_for('index')}}">Back</a></p>
  File "/Users/mnann/Documents/Code/PulseFi/venv/lib/python3.8/site-packages/flask/app.py", line 2034, in url_for
    return self.handle_url_build_error(error, endpoint, values)
  File "/Users/mnann/Documents/Code/PulseFi/venv/lib/python3.8/site-packages/flask/app.py", line 2023, in url_for
    rv = url_adapter.build(  # type: ignore[union-attr]
  File "/Users/mnann/Documents/Code/PulseFi/venv/lib/python3.8/site-packages/werkzeug/routing/map.py", line 917, in build
    raise BuildError(endpoint, values, method, self)
werkzeug.routing.exceptions.BuildError: Could not build url for endpoint 'index'. Did you mean 'login' instead?
2023-04-03 17:30:23,321 INFO: errors [in /Users/mnann/Documents/Code/PulseFi/src/flask/app.py:145]
2023-04-03 17:31:47,688 INFO: errors [in /Users/mnann/Documents/Code/PulseFi/src/flask/app.py:145]
2023-04-03 17:31:56,448 ERROR: Exception on /heart [GET] [in /Users/mnann/Documents/Code/PulseFi/venv/lib/python3.8/site-packages/flask/app.py:1744]
Traceback (most recent call last):
  File "/Users/mnann/Documents/Code/PulseFi/venv/lib/python3.8/site-packages/flask/app.py", line 1823, in full_dispatch_request
    rv = self.dispatch_request()
  File "/Users/mnann/Documents/Code/PulseFi/venv/lib/python3.8/site-packages/flask/app.py", line 1788, in dispatch_request
    self.raise_routing_exception(req)
  File "/Users/mnann/Documents/Code/PulseFi/venv/lib/python3.8/site-packages/flask/app.py", line 1770, in raise_routing_exception
    raise request.routing_exception  # type: ignore
  File "/Users/mnann/Documents/Code/PulseFi/venv/lib/python3.8/site-packages/flask/ctx.py", line 351, in match_request
    result = self.url_adapter.match(return_rule=True)  # type: ignore
  File "/Users/mnann/Documents/Code/PulseFi/venv/lib/python3.8/site-packages/werkzeug/routing/map.py", line 624, in match
    raise NotFound() from None
werkzeug.exceptions.NotFound: 404 Not Found: The requested URL was not found on the server. If you entered the URL manually please check your spelling and try again.

During handling of the above exception, another exception occurred:

Traceback (most recent call last):
  File "/Users/mnann/Documents/Code/PulseFi/venv/lib/python3.8/site-packages/flask/app.py", line 2528, in wsgi_app
    response = self.full_dispatch_request()
  File "/Users/mnann/Documents/Code/PulseFi/venv/lib/python3.8/site-packages/flask/app.py", line 1825, in full_dispatch_request
    rv = self.handle_user_exception(e)
  File "/Users/mnann/Documents/Code/PulseFi/venv/lib/python3.8/site-packages/flask/app.py", line 1669, in handle_user_exception
    return self.handle_http_exception(e)
  File "/Users/mnann/Documents/Code/PulseFi/venv/lib/python3.8/site-packages/flask/app.py", line 1609, in handle_http_exception
    return self.ensure_sync(handler)(e)
  File "/Users/mnann/Documents/Code/PulseFi/src/flask/app.py", line 130, in not_found_error
    return render_template('errors/404.html'), 404
  File "/Users/mnann/Documents/Code/PulseFi/venv/lib/python3.8/site-packages/flask/templating.py", line 147, in render_template
    return _render(app, template, context)
  File "/Users/mnann/Documents/Code/PulseFi/venv/lib/python3.8/site-packages/flask/templating.py", line 130, in _render
    rv = template.render(context)
  File "/Users/mnann/Documents/Code/PulseFi/venv/lib/python3.8/site-packages/jinja2/environment.py", line 1301, in render
    self.environment.handle_exception()
  File "/Users/mnann/Documents/Code/PulseFi/venv/lib/python3.8/site-packages/jinja2/environment.py", line 936, in handle_exception
    raise rewrite_traceback_stack(source=source)
  File "/Users/mnann/Documents/Code/PulseFi/src/flask/templates/errors/404.html", line 1, in top-level template code
    {% extends 'layouts/main.html' %}
  File "/Users/mnann/Documents/Code/PulseFi/src/flask/templates/layouts/main.html", line 99, in top-level template code
    {% block content %}{% endblock %}
  File "/Users/mnann/Documents/Code/PulseFi/src/flask/templates/errors/404.html", line 5, in block 'content'
    <p><a href="{{url_for('index')}}">Back</a></p>
  File "/Users/mnann/Documents/Code/PulseFi/venv/lib/python3.8/site-packages/flask/app.py", line 2034, in url_for
    return self.handle_url_build_error(error, endpoint, values)
  File "/Users/mnann/Documents/Code/PulseFi/venv/lib/python3.8/site-packages/flask/app.py", line 2023, in url_for
    rv = url_adapter.build(  # type: ignore[union-attr]
  File "/Users/mnann/Documents/Code/PulseFi/venv/lib/python3.8/site-packages/werkzeug/routing/map.py", line 917, in build
    raise BuildError(endpoint, values, method, self)
werkzeug.routing.exceptions.BuildError: Could not build url for endpoint 'index'. Did you mean 'login' instead?
2023-04-03 17:32:01,927 ERROR: Exception on /heartRat [GET] [in /Users/mnann/Documents/Code/PulseFi/venv/lib/python3.8/site-packages/flask/app.py:1744]
Traceback (most recent call last):
  File "/Users/mnann/Documents/Code/PulseFi/venv/lib/python3.8/site-packages/flask/app.py", line 1823, in full_dispatch_request
    rv = self.dispatch_request()
  File "/Users/mnann/Documents/Code/PulseFi/venv/lib/python3.8/site-packages/flask/app.py", line 1788, in dispatch_request
    self.raise_routing_exception(req)
  File "/Users/mnann/Documents/Code/PulseFi/venv/lib/python3.8/site-packages/flask/app.py", line 1770, in raise_routing_exception
    raise request.routing_exception  # type: ignore
  File "/Users/mnann/Documents/Code/PulseFi/venv/lib/python3.8/site-packages/flask/ctx.py", line 351, in match_request
    result = self.url_adapter.match(return_rule=True)  # type: ignore
  File "/Users/mnann/Documents/Code/PulseFi/venv/lib/python3.8/site-packages/werkzeug/routing/map.py", line 624, in match
    raise NotFound() from None
werkzeug.exceptions.NotFound: 404 Not Found: The requested URL was not found on the server. If you entered the URL manually please check your spelling and try again.

During handling of the above exception, another exception occurred:

Traceback (most recent call last):
  File "/Users/mnann/Documents/Code/PulseFi/venv/lib/python3.8/site-packages/flask/app.py", line 2528, in wsgi_app
    response = self.full_dispatch_request()
  File "/Users/mnann/Documents/Code/PulseFi/venv/lib/python3.8/site-packages/flask/app.py", line 1825, in full_dispatch_request
    rv = self.handle_user_exception(e)
  File "/Users/mnann/Documents/Code/PulseFi/venv/lib/python3.8/site-packages/flask/app.py", line 1669, in handle_user_exception
    return self.handle_http_exception(e)
  File "/Users/mnann/Documents/Code/PulseFi/venv/lib/python3.8/site-packages/flask/app.py", line 1609, in handle_http_exception
    return self.ensure_sync(handler)(e)
  File "/Users/mnann/Documents/Code/PulseFi/src/flask/app.py", line 130, in not_found_error
    return render_template('errors/404.html'), 404
  File "/Users/mnann/Documents/Code/PulseFi/venv/lib/python3.8/site-packages/flask/templating.py", line 147, in render_template
    return _render(app, template, context)
  File "/Users/mnann/Documents/Code/PulseFi/venv/lib/python3.8/site-packages/flask/templating.py", line 130, in _render
    rv = template.render(context)
  File "/Users/mnann/Documents/Code/PulseFi/venv/lib/python3.8/site-packages/jinja2/environment.py", line 1301, in render
    self.environment.handle_exception()
  File "/Users/mnann/Documents/Code/PulseFi/venv/lib/python3.8/site-packages/jinja2/environment.py", line 936, in handle_exception
    raise rewrite_traceback_stack(source=source)
  File "/Users/mnann/Documents/Code/PulseFi/src/flask/templates/errors/404.html", line 1, in top-level template code
    {% extends 'layouts/main.html' %}
  File "/Users/mnann/Documents/Code/PulseFi/src/flask/templates/layouts/main.html", line 99, in top-level template code
    {% block content %}{% endblock %}
  File "/Users/mnann/Documents/Code/PulseFi/src/flask/templates/errors/404.html", line 5, in block 'content'
    <p><a href="{{url_for('index')}}">Back</a></p>
  File "/Users/mnann/Documents/Code/PulseFi/venv/lib/python3.8/site-packages/flask/app.py", line 2034, in url_for
    return self.handle_url_build_error(error, endpoint, values)
  File "/Users/mnann/Documents/Code/PulseFi/venv/lib/python3.8/site-packages/flask/app.py", line 2023, in url_for
    rv = url_adapter.build(  # type: ignore[union-attr]
  File "/Users/mnann/Documents/Code/PulseFi/venv/lib/python3.8/site-packages/werkzeug/routing/map.py", line 917, in build
    raise BuildError(endpoint, values, method, self)
werkzeug.routing.exceptions.BuildError: Could not build url for endpoint 'index'. Did you mean 'login' instead?
2023-04-03 17:33:44,555 INFO: errors [in /Users/mnann/Documents/Code/PulseFi/src/flask/app.py:145]
2023-04-03 17:33:55,216 ERROR: Exception on /heartRat [GET] [in /Users/mnann/Documents/Code/PulseFi/venv/lib/python3.8/site-packages/flask/app.py:1744]
Traceback (most recent call last):
  File "/Users/mnann/Documents/Code/PulseFi/venv/lib/python3.8/site-packages/flask/app.py", line 1823, in full_dispatch_request
    rv = self.dispatch_request()
  File "/Users/mnann/Documents/Code/PulseFi/venv/lib/python3.8/site-packages/flask/app.py", line 1788, in dispatch_request
    self.raise_routing_exception(req)
  File "/Users/mnann/Documents/Code/PulseFi/venv/lib/python3.8/site-packages/flask/app.py", line 1770, in raise_routing_exception
    raise request.routing_exception  # type: ignore
  File "/Users/mnann/Documents/Code/PulseFi/venv/lib/python3.8/site-packages/flask/ctx.py", line 351, in match_request
    result = self.url_adapter.match(return_rule=True)  # type: ignore
  File "/Users/mnann/Documents/Code/PulseFi/venv/lib/python3.8/site-packages/werkzeug/routing/map.py", line 624, in match
    raise NotFound() from None
werkzeug.exceptions.NotFound: 404 Not Found: The requested URL was not found on the server. If you entered the URL manually please check your spelling and try again.

During handling of the above exception, another exception occurred:

Traceback (most recent call last):
  File "/Users/mnann/Documents/Code/PulseFi/venv/lib/python3.8/site-packages/flask/app.py", line 2528, in wsgi_app
    response = self.full_dispatch_request()
  File "/Users/mnann/Documents/Code/PulseFi/venv/lib/python3.8/site-packages/flask/app.py", line 1825, in full_dispatch_request
    rv = self.handle_user_exception(e)
  File "/Users/mnann/Documents/Code/PulseFi/venv/lib/python3.8/site-packages/flask/app.py", line 1669, in handle_user_exception
    return self.handle_http_exception(e)
  File "/Users/mnann/Documents/Code/PulseFi/venv/lib/python3.8/site-packages/flask/app.py", line 1609, in handle_http_exception
    return self.ensure_sync(handler)(e)
  File "/Users/mnann/Documents/Code/PulseFi/src/flask/app.py", line 130, in not_found_error
    return render_template('errors/404.html'), 404
  File "/Users/mnann/Documents/Code/PulseFi/venv/lib/python3.8/site-packages/flask/templating.py", line 147, in render_template
    return _render(app, template, context)
  File "/Users/mnann/Documents/Code/PulseFi/venv/lib/python3.8/site-packages/flask/templating.py", line 130, in _render
    rv = template.render(context)
  File "/Users/mnann/Documents/Code/PulseFi/venv/lib/python3.8/site-packages/jinja2/environment.py", line 1301, in render
    self.environment.handle_exception()
  File "/Users/mnann/Documents/Code/PulseFi/venv/lib/python3.8/site-packages/jinja2/environment.py", line 936, in handle_exception
    raise rewrite_traceback_stack(source=source)
  File "/Users/mnann/Documents/Code/PulseFi/src/flask/templates/errors/404.html", line 1, in top-level template code
    {% extends 'layouts/main.html' %}
  File "/Users/mnann/Documents/Code/PulseFi/src/flask/templates/layouts/main.html", line 99, in top-level template code
    {% block content %}{% endblock %}
  File "/Users/mnann/Documents/Code/PulseFi/src/flask/templates/errors/404.html", line 5, in block 'content'
    <p><a href="{{url_for('index')}}">Back</a></p>
  File "/Users/mnann/Documents/Code/PulseFi/venv/lib/python3.8/site-packages/flask/app.py", line 2034, in url_for
    return self.handle_url_build_error(error, endpoint, values)
  File "/Users/mnann/Documents/Code/PulseFi/venv/lib/python3.8/site-packages/flask/app.py", line 2023, in url_for
    rv = url_adapter.build(  # type: ignore[union-attr]
  File "/Users/mnann/Documents/Code/PulseFi/venv/lib/python3.8/site-packages/werkzeug/routing/map.py", line 917, in build
    raise BuildError(endpoint, values, method, self)
werkzeug.routing.exceptions.BuildError: Could not build url for endpoint 'index'. Did you mean 'login' instead?
2023-04-03 17:38:44,620 INFO: errors [in /Users/mnann/Documents/Code/PulseFi/src/flask/app.py:145]
2023-04-10 13:33:25,902 INFO: errors [in /Users/mnann/Documents/Code/PulseFi/src/flask/app.py:145]
2023-04-10 15:09:45,666 INFO: errors [in /Users/mnann/Documents/Code/PulseFi/src/flask/app.py:149]
2023-04-10 15:09:59,496 INFO: errors [in /Users/mnann/Documents/Code/PulseFi/src/flask/app.py:149]
2023-04-10 15:10:16,818 INFO: errors [in /Users/mnann/Documents/Code/PulseFi/src/flask/app.py:149]
2023-04-10 15:10:56,362 ERROR: Exception on /heartRate [GET] [in /Users/mnann/Documents/Code/PulseFi/venv/lib/python3.8/site-packages/flask/app.py:1744]
Traceback (most recent call last):
  File "/Users/mnann/Documents/Code/PulseFi/venv/lib/python3.8/site-packages/flask/app.py", line 2528, in wsgi_app
    response = self.full_dispatch_request()
  File "/Users/mnann/Documents/Code/PulseFi/venv/lib/python3.8/site-packages/flask/app.py", line 1825, in full_dispatch_request
    rv = self.handle_user_exception(e)
  File "/Users/mnann/Documents/Code/PulseFi/venv/lib/python3.8/site-packages/flask/app.py", line 1823, in full_dispatch_request
    rv = self.dispatch_request()
  File "/Users/mnann/Documents/Code/PulseFi/venv/lib/python3.8/site-packages/flask/app.py", line 1799, in dispatch_request
    return self.ensure_sync(self.view_functions[rule.endpoint])(**view_args)
TypeError: wrapper() missing 1 required positional argument: 'self'
2023-04-10 15:15:01,707 INFO: errors [in /Users/mnann/Documents/Code/PulseFi/src/flask/app.py:149]
2023-04-10 15:15:05,367 ERROR: Exception on /heartRate [GET] [in /Users/mnann/Documents/Code/PulseFi/venv/lib/python3.8/site-packages/flask/app.py:1744]
Traceback (most recent call last):
  File "/Users/mnann/Documents/Code/PulseFi/venv/lib/python3.8/site-packages/flask/app.py", line 2528, in wsgi_app
    response = self.full_dispatch_request()
  File "/Users/mnann/Documents/Code/PulseFi/venv/lib/python3.8/site-packages/flask/app.py", line 1825, in full_dispatch_request
    rv = self.handle_user_exception(e)
  File "/Users/mnann/Documents/Code/PulseFi/venv/lib/python3.8/site-packages/flask/app.py", line 1823, in full_dispatch_request
    rv = self.dispatch_request()
  File "/Users/mnann/Documents/Code/PulseFi/venv/lib/python3.8/site-packages/flask/app.py", line 1799, in dispatch_request
    return self.ensure_sync(self.view_functions[rule.endpoint])(**view_args)
TypeError: _impl() missing 1 required positional argument: 'self'
2023-04-10 15:15:56,508 INFO: errors [in /Users/mnann/Documents/Code/PulseFi/src/flask/app.py:149]
2023-04-10 15:15:59,451 ERROR: Exception on /heartRate [GET] [in /Users/mnann/Documents/Code/PulseFi/venv/lib/python3.8/site-packages/flask/app.py:1744]
Traceback (most recent call last):
  File "/Users/mnann/Documents/Code/PulseFi/venv/lib/python3.8/site-packages/flask/app.py", line 2528, in wsgi_app
    response = self.full_dispatch_request()
  File "/Users/mnann/Documents/Code/PulseFi/venv/lib/python3.8/site-packages/flask/app.py", line 1825, in full_dispatch_request
    rv = self.handle_user_exception(e)
  File "/Users/mnann/Documents/Code/PulseFi/venv/lib/python3.8/site-packages/flask/app.py", line 1823, in full_dispatch_request
    rv = self.dispatch_request()
  File "/Users/mnann/Documents/Code/PulseFi/venv/lib/python3.8/site-packages/flask/app.py", line 1799, in dispatch_request
    return self.ensure_sync(self.view_functions[rule.endpoint])(**view_args)
TypeError: _impl() missing 1 required positional argument: 'self'
2023-04-10 15:18:02,249 INFO: errors [in /Users/mnann/Documents/Code/PulseFi/src/flask/app.py:149]
2023-04-10 15:21:48,184 INFO: errors [in /Users/mnann/Documents/Code/PulseFi/src/flask/app.py:149]
