2023-04-11 11:18:09,508 INFO: errors [in /Users/mnann/Documents/Code/PulseFi/src/flaskServer/app.py:149]
2023-04-11 11:18:21,843 ERROR: Exception on /heartRate [GET] [in /Users/mnann/Documents/Code/PulseFi/venv/lib/python3.8/site-packages/flask/app.py:1744]
Traceback (most recent call last):
  File "/Users/mnann/Documents/Code/PulseFi/venv/lib/python3.8/site-packages/flask/app.py", line 2528, in wsgi_app
    response = self.full_dispatch_request()
  File "/Users/mnann/Documents/Code/PulseFi/venv/lib/python3.8/site-packages/flask/app.py", line 1825, in full_dispatch_request
    rv = self.handle_user_exception(e)
  File "/Users/mnann/Documents/Code/PulseFi/venv/lib/python3.8/site-packages/flask/app.py", line 1823, in full_dispatch_request
    rv = self.dispatch_request()
  File "/Users/mnann/Documents/Code/PulseFi/venv/lib/python3.8/site-packages/flask/app.py", line 1799, in dispatch_request
    return self.ensure_sync(self.view_functions[rule.endpoint])(**view_args)
  File "/Users/mnann/Documents/Code/PulseFi/src/data/callbacks.py", line 108, in heartRate
    app.layout = html.Div([
NameError: name 'html' is not defined
2023-04-11 11:18:34,249 INFO: errors [in /Users/mnann/Documents/Code/PulseFi/src/flaskServer/app.py:149]
2023-04-11 11:18:44,907 ERROR: Exception on /heartRate [GET] [in /Users/mnann/Documents/Code/PulseFi/venv/lib/python3.8/site-packages/flask/app.py:1744]
Traceback (most recent call last):
  File "/Users/mnann/Documents/Code/PulseFi/venv/lib/python3.8/site-packages/flask/app.py", line 2528, in wsgi_app
    response = self.full_dispatch_request()
  File "/Users/mnann/Documents/Code/PulseFi/venv/lib/python3.8/site-packages/flask/app.py", line 1826, in full_dispatch_request
    return self.finalize_request(rv)
  File "/Users/mnann/Documents/Code/PulseFi/venv/lib/python3.8/site-packages/flask/app.py", line 1845, in finalize_request
    response = self.make_response(rv)
  File "/Users/mnann/Documents/Code/PulseFi/venv/lib/python3.8/site-packages/flask/app.py", line 2173, in make_response
    raise TypeError(
TypeError: The view function did not return a valid response. The return type must be a string, dict, list, tuple with headers or status, Response instance, or WSGI callable, but it was a DataFrame.
2023-04-11 11:28:44,122 INFO: errors [in /Users/mnann/Documents/Code/PulseFi/src/flaskServer/app.py:149]
2023-04-11 11:29:03,374 ERROR: Exception on /heartRate [GET] [in /Users/mnann/Documents/Code/PulseFi/venv/lib/python3.8/site-packages/flask/app.py:1744]
Traceback (most recent call last):
  File "/Users/mnann/Documents/Code/PulseFi/venv/lib/python3.8/site-packages/flask/app.py", line 2528, in wsgi_app
    response = self.full_dispatch_request()
  File "/Users/mnann/Documents/Code/PulseFi/venv/lib/python3.8/site-packages/flask/app.py", line 1826, in full_dispatch_request
    return self.finalize_request(rv)
  File "/Users/mnann/Documents/Code/PulseFi/venv/lib/python3.8/site-packages/flask/app.py", line 1845, in finalize_request
    response = self.make_response(rv)
  File "/Users/mnann/Documents/Code/PulseFi/venv/lib/python3.8/site-packages/flask/app.py", line 2173, in make_response
    raise TypeError(
TypeError: The view function did not return a valid response. The return type must be a string, dict, list, tuple with headers or status, Response instance, or WSGI callable, but it was a DataFrame.
2023-04-11 11:29:51,443 ERROR: Exception on /heartRate [GET] [in /Users/mnann/Documents/Code/PulseFi/venv/lib/python3.8/site-packages/flask/app.py:1744]
Traceback (most recent call last):
  File "/Users/mnann/Documents/Code/PulseFi/venv/lib/python3.8/site-packages/flask/app.py", line 2528, in wsgi_app
    response = self.full_dispatch_request()
  File "/Users/mnann/Documents/Code/PulseFi/venv/lib/python3.8/site-packages/flask/app.py", line 1826, in full_dispatch_request
    return self.finalize_request(rv)
  File "/Users/mnann/Documents/Code/PulseFi/venv/lib/python3.8/site-packages/flask/app.py", line 1845, in finalize_request
    response = self.make_response(rv)
  File "/Users/mnann/Documents/Code/PulseFi/venv/lib/python3.8/site-packages/flask/app.py", line 2173, in make_response
    raise TypeError(
TypeError: The view function did not return a valid response. The return type must be a string, dict, list, tuple with headers or status, Response instance, or WSGI callable, but it was a DataFrame.
2023-04-11 11:29:56,003 INFO: errors [in /Users/mnann/Documents/Code/PulseFi/src/flaskServer/app.py:149]
2023-04-11 11:30:09,889 ERROR: Exception on /favicon.ico [GET] [in /Users/mnann/Documents/Code/PulseFi/venv/lib/python3.8/site-packages/flask/app.py:1744]
Traceback (most recent call last):
  File "/Users/mnann/Documents/Code/PulseFi/venv/lib/python3.8/site-packages/flask/app.py", line 1823, in full_dispatch_request
    rv = self.dispatch_request()
  File "/Users/mnann/Documents/Code/PulseFi/venv/lib/python3.8/site-packages/flask/app.py", line 1788, in dispatch_request
    self.raise_routing_exception(req)
  File "/Users/mnann/Documents/Code/PulseFi/venv/lib/python3.8/site-packages/flask/app.py", line 1770, in raise_routing_exception
    raise request.routing_exception  # type: ignore
  File "/Users/mnann/Documents/Code/PulseFi/venv/lib/python3.8/site-packages/flask/ctx.py", line 351, in match_request
    result = self.url_adapter.match(return_rule=True)  # type: ignore
  File "/Users/mnann/Documents/Code/PulseFi/venv/lib/python3.8/site-packages/werkzeug/routing/map.py", line 624, in match
    raise NotFound() from None
werkzeug.exceptions.NotFound: 404 Not Found: The requested URL was not found on the server. If you entered the URL manually please check your spelling and try again.

During handling of the above exception, another exception occurred:

Traceback (most recent call last):
  File "/Users/mnann/Documents/Code/PulseFi/venv/lib/python3.8/site-packages/flask/app.py", line 2528, in wsgi_app
    response = self.full_dispatch_request()
  File "/Users/mnann/Documents/Code/PulseFi/venv/lib/python3.8/site-packages/flask/app.py", line 1825, in full_dispatch_request
    rv = self.handle_user_exception(e)
  File "/Users/mnann/Documents/Code/PulseFi/venv/lib/python3.8/site-packages/flask/app.py", line 1669, in handle_user_exception
    return self.handle_http_exception(e)
  File "/Users/mnann/Documents/Code/PulseFi/venv/lib/python3.8/site-packages/flask/app.py", line 1609, in handle_http_exception
    return self.ensure_sync(handler)(e)
  File "/Users/mnann/Documents/Code/PulseFi/src/flaskServer/app.py", line 130, in not_found_error
    return render_template('errors/404.html'), 404
  File "/Users/mnann/Documents/Code/PulseFi/venv/lib/python3.8/site-packages/flask/templating.py", line 147, in render_template
    return _render(app, template, context)
  File "/Users/mnann/Documents/Code/PulseFi/venv/lib/python3.8/site-packages/flask/templating.py", line 130, in _render
    rv = template.render(context)
  File "/Users/mnann/Documents/Code/PulseFi/venv/lib/python3.8/site-packages/jinja2/environment.py", line 1301, in render
    self.environment.handle_exception()
  File "/Users/mnann/Documents/Code/PulseFi/venv/lib/python3.8/site-packages/jinja2/environment.py", line 936, in handle_exception
    raise rewrite_traceback_stack(source=source)
  File "/Users/mnann/Documents/Code/PulseFi/src/flaskServer/templates/errors/404.html", line 1, in top-level template code
    {% extends 'layouts/main.html' %}
  File "/Users/mnann/Documents/Code/PulseFi/src/flaskServer/templates/layouts/main.html", line 99, in top-level template code
    {% block content %}{% endblock %}
  File "/Users/mnann/Documents/Code/PulseFi/src/flaskServer/templates/errors/404.html", line 5, in block 'content'
    <p><a href="{{url_for('index')}}">Back</a></p>
  File "/Users/mnann/Documents/Code/PulseFi/venv/lib/python3.8/site-packages/flask/app.py", line 2034, in url_for
    return self.handle_url_build_error(error, endpoint, values)
  File "/Users/mnann/Documents/Code/PulseFi/venv/lib/python3.8/site-packages/flask/app.py", line 2023, in url_for
    rv = url_adapter.build(  # type: ignore[union-attr]
  File "/Users/mnann/Documents/Code/PulseFi/venv/lib/python3.8/site-packages/werkzeug/routing/map.py", line 917, in build
    raise BuildError(endpoint, values, method, self)
werkzeug.routing.exceptions.BuildError: Could not build url for endpoint 'index'. Did you mean 'login' instead?
2023-04-11 11:35:01,078 INFO: errors [in /Users/mnann/Documents/Code/PulseFi/src/flaskServer/app.py:149]
2023-04-11 11:35:08,231 ERROR: Exception on /heartRate [GET] [in /Users/mnann/Documents/Code/PulseFi/venv/lib/python3.8/site-packages/flask/app.py:1744]
Traceback (most recent call last):
  File "/Users/mnann/Documents/Code/PulseFi/venv/lib/python3.8/site-packages/flask/app.py", line 2528, in wsgi_app
    response = self.full_dispatch_request()
  File "/Users/mnann/Documents/Code/PulseFi/venv/lib/python3.8/site-packages/flask/app.py", line 1825, in full_dispatch_request
    rv = self.handle_user_exception(e)
  File "/Users/mnann/Documents/Code/PulseFi/venv/lib/python3.8/site-packages/flask/app.py", line 1823, in full_dispatch_request
    rv = self.dispatch_request()
  File "/Users/mnann/Documents/Code/PulseFi/venv/lib/python3.8/site-packages/flask/app.py", line 1799, in dispatch_request
    return self.ensure_sync(self.view_functions[rule.endpoint])(**view_args)
  File "/Users/mnann/Documents/Code/PulseFi/src/data/callbacks.py", line 104, in heartRate
    df_heartRate = self.requestMultipleDays()
  File "/Users/mnann/Documents/Code/PulseFi/src/data/callbacks.py", line 45, in requestMultipleDays
    oneDayData = self.auth2_client.intraday_time_series('activities/heart', base_date=oneDate, detail_level='1sec')
  File "/Users/mnann/Documents/Code/PulseFi/venv/lib/python3.8/site-packages/fitbit/api.py", line 592, in intraday_time_series
    return self.make_request(url)
  File "/Users/mnann/Documents/Code/PulseFi/venv/lib/python3.8/site-packages/fitbit/api.py", line 256, in make_request
    response = self.client.make_request(*args, **kwargs)
  File "/Users/mnann/Documents/Code/PulseFi/venv/lib/python3.8/site-packages/fitbit/api.py", line 99, in make_request
    exceptions.detect_and_raise_error(response)
  File "/Users/mnann/Documents/Code/PulseFi/venv/lib/python3.8/site-packages/fitbit/exceptions.py", line 92, in detect_and_raise_error
    raise exc
fitbit.exceptions.HTTPTooManyRequests: Too Many Requests
2023-04-11 11:35:24,407 ERROR: Exception on /heartRate [GET] [in /Users/mnann/Documents/Code/PulseFi/venv/lib/python3.8/site-packages/flask/app.py:1744]
Traceback (most recent call last):
  File "/Users/mnann/Documents/Code/PulseFi/venv/lib/python3.8/site-packages/flask/app.py", line 2528, in wsgi_app
    response = self.full_dispatch_request()
  File "/Users/mnann/Documents/Code/PulseFi/venv/lib/python3.8/site-packages/flask/app.py", line 1825, in full_dispatch_request
    rv = self.handle_user_exception(e)
  File "/Users/mnann/Documents/Code/PulseFi/venv/lib/python3.8/site-packages/flask/app.py", line 1823, in full_dispatch_request
    rv = self.dispatch_request()
  File "/Users/mnann/Documents/Code/PulseFi/venv/lib/python3.8/site-packages/flask/app.py", line 1799, in dispatch_request
    return self.ensure_sync(self.view_functions[rule.endpoint])(**view_args)
  File "/Users/mnann/Documents/Code/PulseFi/src/data/callbacks.py", line 104, in heartRate
    df_heartRate = self.requestMultipleDays()
  File "/Users/mnann/Documents/Code/PulseFi/src/data/callbacks.py", line 45, in requestMultipleDays
    oneDayData = self.auth2_client.intraday_time_series('activities/heart', base_date=oneDate, detail_level='1sec')
  File "/Users/mnann/Documents/Code/PulseFi/venv/lib/python3.8/site-packages/fitbit/api.py", line 592, in intraday_time_series
    return self.make_request(url)
  File "/Users/mnann/Documents/Code/PulseFi/venv/lib/python3.8/site-packages/fitbit/api.py", line 256, in make_request
    response = self.client.make_request(*args, **kwargs)
  File "/Users/mnann/Documents/Code/PulseFi/venv/lib/python3.8/site-packages/fitbit/api.py", line 99, in make_request
    exceptions.detect_and_raise_error(response)
  File "/Users/mnann/Documents/Code/PulseFi/venv/lib/python3.8/site-packages/fitbit/exceptions.py", line 92, in detect_and_raise_error
    raise exc
fitbit.exceptions.HTTPTooManyRequests: Too Many Requests
2023-04-11 11:36:16,517 ERROR: Exception on /heartRate [GET] [in /Users/mnann/Documents/Code/PulseFi/venv/lib/python3.8/site-packages/flask/app.py:1744]
Traceback (most recent call last):
  File "/Users/mnann/Documents/Code/PulseFi/venv/lib/python3.8/site-packages/flask/app.py", line 2528, in wsgi_app
    response = self.full_dispatch_request()
  File "/Users/mnann/Documents/Code/PulseFi/venv/lib/python3.8/site-packages/flask/app.py", line 1825, in full_dispatch_request
    rv = self.handle_user_exception(e)
  File "/Users/mnann/Documents/Code/PulseFi/venv/lib/python3.8/site-packages/flask/app.py", line 1823, in full_dispatch_request
    rv = self.dispatch_request()
  File "/Users/mnann/Documents/Code/PulseFi/venv/lib/python3.8/site-packages/flask/app.py", line 1799, in dispatch_request
    return self.ensure_sync(self.view_functions[rule.endpoint])(**view_args)
  File "/Users/mnann/Documents/Code/PulseFi/src/data/callbacks.py", line 104, in heartRate
    df_heartRate = self.requestMultipleDays()
  File "/Users/mnann/Documents/Code/PulseFi/src/data/callbacks.py", line 45, in requestMultipleDays
    oneDayData = self.auth2_client.intraday_time_series('activities/heart', base_date=oneDate, detail_level='1sec')
  File "/Users/mnann/Documents/Code/PulseFi/venv/lib/python3.8/site-packages/fitbit/api.py", line 592, in intraday_time_series
    return self.make_request(url)
  File "/Users/mnann/Documents/Code/PulseFi/venv/lib/python3.8/site-packages/fitbit/api.py", line 256, in make_request
    response = self.client.make_request(*args, **kwargs)
  File "/Users/mnann/Documents/Code/PulseFi/venv/lib/python3.8/site-packages/fitbit/api.py", line 99, in make_request
    exceptions.detect_and_raise_error(response)
  File "/Users/mnann/Documents/Code/PulseFi/venv/lib/python3.8/site-packages/fitbit/exceptions.py", line 92, in detect_and_raise_error
    raise exc
fitbit.exceptions.HTTPTooManyRequests: Too Many Requests
2023-04-11 11:37:26,993 INFO: errors [in /Users/mnann/Documents/Code/PulseFi/src/flaskServer/app.py:149]
2023-04-11 11:37:33,382 ERROR: Exception on /heartRate [GET] [in /Users/mnann/Documents/Code/PulseFi/venv/lib/python3.8/site-packages/flask/app.py:1744]
Traceback (most recent call last):
  File "/Users/mnann/Documents/Code/PulseFi/venv/lib/python3.8/site-packages/flask/app.py", line 2528, in wsgi_app
    response = self.full_dispatch_request()
  File "/Users/mnann/Documents/Code/PulseFi/venv/lib/python3.8/site-packages/flask/app.py", line 1825, in full_dispatch_request
    rv = self.handle_user_exception(e)
  File "/Users/mnann/Documents/Code/PulseFi/venv/lib/python3.8/site-packages/flask/app.py", line 1823, in full_dispatch_request
    rv = self.dispatch_request()
  File "/Users/mnann/Documents/Code/PulseFi/venv/lib/python3.8/site-packages/flask/app.py", line 1799, in dispatch_request
    return self.ensure_sync(self.view_functions[rule.endpoint])(**view_args)
  File "/Users/mnann/Documents/Code/PulseFi/src/data/callbacks.py", line 104, in heartRate
    df_heartRate = self.requestMultipleDays()
  File "/Users/mnann/Documents/Code/PulseFi/src/data/callbacks.py", line 45, in requestMultipleDays
    oneDayData = self.auth2_client.intraday_time_series('activities/heart', base_date=oneDate, detail_level='1sec')
  File "/Users/mnann/Documents/Code/PulseFi/venv/lib/python3.8/site-packages/fitbit/api.py", line 592, in intraday_time_series
    return self.make_request(url)
  File "/Users/mnann/Documents/Code/PulseFi/venv/lib/python3.8/site-packages/fitbit/api.py", line 256, in make_request
    response = self.client.make_request(*args, **kwargs)
  File "/Users/mnann/Documents/Code/PulseFi/venv/lib/python3.8/site-packages/fitbit/api.py", line 99, in make_request
    exceptions.detect_and_raise_error(response)
  File "/Users/mnann/Documents/Code/PulseFi/venv/lib/python3.8/site-packages/fitbit/exceptions.py", line 92, in detect_and_raise_error
    raise exc
fitbit.exceptions.HTTPTooManyRequests: Too Many Requests
2023-04-11 11:55:00,581 INFO: errors [in /Users/mnann/Documents/Code/PulseFi/src/flaskServer/app.py:149]
2023-04-11 11:55:06,755 ERROR: Exception on /heartRate [GET] [in /Users/mnann/Documents/Code/PulseFi/venv/lib/python3.8/site-packages/flask/app.py:1744]
Traceback (most recent call last):
  File "/Users/mnann/Documents/Code/PulseFi/venv/lib/python3.8/site-packages/flask/app.py", line 2528, in wsgi_app
    response = self.full_dispatch_request()
  File "/Users/mnann/Documents/Code/PulseFi/venv/lib/python3.8/site-packages/flask/app.py", line 1825, in full_dispatch_request
    rv = self.handle_user_exception(e)
  File "/Users/mnann/Documents/Code/PulseFi/venv/lib/python3.8/site-packages/flask/app.py", line 1823, in full_dispatch_request
    rv = self.dispatch_request()
  File "/Users/mnann/Documents/Code/PulseFi/venv/lib/python3.8/site-packages/flask/app.py", line 1799, in dispatch_request
    return self.ensure_sync(self.view_functions[rule.endpoint])(**view_args)
  File "/Users/mnann/Documents/Code/PulseFi/src/data/callbacks.py", line 104, in heartRate
    df_heartRate = self.requestMultipleDays()
  File "/Users/mnann/Documents/Code/PulseFi/src/data/callbacks.py", line 45, in requestMultipleDays
    oneDayData = self.auth2_client.intraday_time_series('activities/heart', base_date=oneDate, detail_level='1sec')
  File "/Users/mnann/Documents/Code/PulseFi/venv/lib/python3.8/site-packages/fitbit/api.py", line 592, in intraday_time_series
    return self.make_request(url)
  File "/Users/mnann/Documents/Code/PulseFi/venv/lib/python3.8/site-packages/fitbit/api.py", line 256, in make_request
    response = self.client.make_request(*args, **kwargs)
  File "/Users/mnann/Documents/Code/PulseFi/venv/lib/python3.8/site-packages/fitbit/api.py", line 99, in make_request
    exceptions.detect_and_raise_error(response)
  File "/Users/mnann/Documents/Code/PulseFi/venv/lib/python3.8/site-packages/fitbit/exceptions.py", line 92, in detect_and_raise_error
    raise exc
fitbit.exceptions.HTTPTooManyRequests: Too Many Requests
2023-04-11 12:25:29,186 INFO: errors [in /Users/mnann/Documents/Code/PulseFi/src/flaskServer/app.py:149]
2023-04-11 12:25:52,046 INFO: errors [in /Users/mnann/Documents/Code/PulseFi/src/flaskServer/app.py:149]
2023-04-11 12:42:11,965 INFO: errors [in /Users/mnann/Documents/Code/PulseFi/src/flaskServer/app.py:153]
2023-04-11 13:06:39,147 INFO: errors [in /Users/mnann/Documents/Code/PulseFi/src/flaskServer/app.py:154]
2023-04-11 13:22:55,708 INFO: errors [in /Users/mnann/Documents/Code/PulseFi/src/flaskServer/app.py:154]
2023-04-11 13:23:00,997 ERROR: Exception on /heartRate [GET] [in /Users/mnann/Documents/Code/PulseFi/venv/lib/python3.8/site-packages/flask/app.py:1744]
Traceback (most recent call last):
  File "/Users/mnann/Documents/Code/PulseFi/venv/lib/python3.8/site-packages/flask/app.py", line 2528, in wsgi_app
    response = self.full_dispatch_request()
  File "/Users/mnann/Documents/Code/PulseFi/venv/lib/python3.8/site-packages/flask/app.py", line 1825, in full_dispatch_request
    rv = self.handle_user_exception(e)
  File "/Users/mnann/Documents/Code/PulseFi/venv/lib/python3.8/site-packages/flask/app.py", line 1823, in full_dispatch_request
    rv = self.dispatch_request()
  File "/Users/mnann/Documents/Code/PulseFi/venv/lib/python3.8/site-packages/flask/app.py", line 1799, in dispatch_request
    return self.ensure_sync(self.view_functions[rule.endpoint])(**view_args)
  File "/Users/mnann/Documents/Code/PulseFi/src/data/callbacks.py", line 104, in heartRate
    self.authorize()
  File "/Users/mnann/Documents/Code/PulseFi/src/data/callbacks.py", line 30, in authorize
    self.ACCESS_TOKEN, self.REFRESH_TOKEN = self.retrieve_OAuth_FitBit_Tokens()
  File "/Users/mnann/Documents/Code/PulseFi/src/data/callbacks.py", line 24, in retrieve_OAuth_FitBit_Tokens
    ACCESS_TOKEN=str(self.server.fitbit.client.session.token['access_token'])
KeyError: 'access_token'
2023-04-11 13:24:05,691 INFO: errors [in /Users/mnann/Documents/Code/PulseFi/src/flaskServer/app.py:154]
2023-04-11 13:39:57,179 INFO: errors [in /Users/mnann/Documents/Code/PulseFi/src/flaskServer/app.py:154]
2023-04-11 13:40:21,521 ERROR: Exception on /heartRate [GET] [in /Users/mnann/Documents/Code/PulseFi/venv/lib/python3.8/site-packages/flask/app.py:1744]
Traceback (most recent call last):
  File "/Users/mnann/Documents/Code/PulseFi/venv/lib/python3.8/site-packages/flask/app.py", line 2528, in wsgi_app
    response = self.full_dispatch_request()
  File "/Users/mnann/Documents/Code/PulseFi/venv/lib/python3.8/site-packages/flask/app.py", line 1825, in full_dispatch_request
    rv = self.handle_user_exception(e)
  File "/Users/mnann/Documents/Code/PulseFi/venv/lib/python3.8/site-packages/flask/app.py", line 1823, in full_dispatch_request
    rv = self.dispatch_request()
  File "/Users/mnann/Documents/Code/PulseFi/venv/lib/python3.8/site-packages/flask/app.py", line 1799, in dispatch_request
    return self.ensure_sync(self.view_functions[rule.endpoint])(**view_args)
  File "/Users/mnann/Documents/Code/PulseFi/src/data/callbacks.py", line 174, in heartRate
    self.authorize()
  File "/Users/mnann/Documents/Code/PulseFi/src/data/callbacks.py", line 97, in authorize
    self.auth2_client=Fitbit(self.client_id,self.client_secret,oauth2=True,access_token=self.ACCESS_TOKEN,refresh_token=self.REFRESH_TOKEN)
AttributeError: 'FitbitAuth' object has no attribute 'ACCESS_TOKEN'
2023-04-11 13:40:56,383 INFO: errors [in /Users/mnann/Documents/Code/PulseFi/src/flaskServer/app.py:154]
2023-04-11 13:41:21,687 INFO: errors [in /Users/mnann/Documents/Code/PulseFi/src/flaskServer/app.py:154]
2023-04-11 13:41:47,259 ERROR: Exception on /heartRate [GET] [in /Users/mnann/Documents/Code/PulseFi/venv/lib/python3.8/site-packages/flask/app.py:1744]
Traceback (most recent call last):
  File "/Users/mnann/Documents/Code/PulseFi/venv/lib/python3.8/site-packages/flask/app.py", line 2528, in wsgi_app
    response = self.full_dispatch_request()
  File "/Users/mnann/Documents/Code/PulseFi/venv/lib/python3.8/site-packages/flask/app.py", line 1825, in full_dispatch_request
    rv = self.handle_user_exception(e)
  File "/Users/mnann/Documents/Code/PulseFi/venv/lib/python3.8/site-packages/flask/app.py", line 1823, in full_dispatch_request
    rv = self.dispatch_request()
  File "/Users/mnann/Documents/Code/PulseFi/venv/lib/python3.8/site-packages/flask/app.py", line 1799, in dispatch_request
    return self.ensure_sync(self.view_functions[rule.endpoint])(**view_args)
  File "/Users/mnann/Documents/Code/PulseFi/src/data/callbacks.py", line 174, in heartRate
    self.authorize()
  File "/Users/mnann/Documents/Code/PulseFi/src/data/callbacks.py", line 97, in authorize
    self.auth2_client=Fitbit(self.client_id,self.client_secret,oauth2=True,access_token=self.ACCESS_TOKEN,refresh_token=self.REFRESH_TOKEN)
AttributeError: 'FitbitAuth' object has no attribute 'ACCESS_TOKEN'
2023-04-11 13:42:34,564 INFO: errors [in /Users/mnann/Documents/Code/PulseFi/src/flaskServer/app.py:154]
2023-04-11 13:42:57,479 ERROR: Exception on /heartRate [GET] [in /Users/mnann/Documents/Code/PulseFi/venv/lib/python3.8/site-packages/flask/app.py:1744]
Traceback (most recent call last):
  File "/Users/mnann/Documents/Code/PulseFi/venv/lib/python3.8/site-packages/flask/app.py", line 2528, in wsgi_app
    response = self.full_dispatch_request()
  File "/Users/mnann/Documents/Code/PulseFi/venv/lib/python3.8/site-packages/flask/app.py", line 1825, in full_dispatch_request
    rv = self.handle_user_exception(e)
  File "/Users/mnann/Documents/Code/PulseFi/venv/lib/python3.8/site-packages/flask/app.py", line 1823, in full_dispatch_request
    rv = self.dispatch_request()
  File "/Users/mnann/Documents/Code/PulseFi/venv/lib/python3.8/site-packages/flask/app.py", line 1799, in dispatch_request
    return self.ensure_sync(self.view_functions[rule.endpoint])(**view_args)
  File "/Users/mnann/Documents/Code/PulseFi/src/data/callbacks.py", line 174, in heartRate
    self.authorize()
  File "/Users/mnann/Documents/Code/PulseFi/src/data/callbacks.py", line 97, in authorize
    self.auth2_client=Fitbit(self.client_id,self.client_secret,oauth2=True,access_token=self.ACCESS_TOKEN,refresh_token=self.REFRESH_TOKEN)
AttributeError: 'FitbitAuth' object has no attribute 'ACCESS_TOKEN'
2023-04-11 13:43:07,365 ERROR: Exception on /heartRate [GET] [in /Users/mnann/Documents/Code/PulseFi/venv/lib/python3.8/site-packages/flask/app.py:1744]
Traceback (most recent call last):
  File "/Users/mnann/Documents/Code/PulseFi/venv/lib/python3.8/site-packages/flask/app.py", line 2528, in wsgi_app
    response = self.full_dispatch_request()
  File "/Users/mnann/Documents/Code/PulseFi/venv/lib/python3.8/site-packages/flask/app.py", line 1825, in full_dispatch_request
    rv = self.handle_user_exception(e)
  File "/Users/mnann/Documents/Code/PulseFi/venv/lib/python3.8/site-packages/flask/app.py", line 1823, in full_dispatch_request
    rv = self.dispatch_request()
  File "/Users/mnann/Documents/Code/PulseFi/venv/lib/python3.8/site-packages/flask/app.py", line 1799, in dispatch_request
    return self.ensure_sync(self.view_functions[rule.endpoint])(**view_args)
  File "/Users/mnann/Documents/Code/PulseFi/src/data/callbacks.py", line 175, in heartRate
    df_heartRate = self.requestMultipleDays()
  File "/Users/mnann/Documents/Code/PulseFi/src/data/callbacks.py", line 111, in requestMultipleDays
    oneDayData = self.auth2_client.intraday_time_series('activities/heart', base_date=oneDate, detail_level='1sec')
AttributeError: 'NoneType' object has no attribute 'intraday_time_series'
2023-04-11 13:43:15,220 ERROR: Exception on /heartRate [GET] [in /Users/mnann/Documents/Code/PulseFi/venv/lib/python3.8/site-packages/flask/app.py:1744]
Traceback (most recent call last):
  File "/Users/mnann/Documents/Code/PulseFi/venv/lib/python3.8/site-packages/flask/app.py", line 2528, in wsgi_app
    response = self.full_dispatch_request()
  File "/Users/mnann/Documents/Code/PulseFi/venv/lib/python3.8/site-packages/flask/app.py", line 1825, in full_dispatch_request
    rv = self.handle_user_exception(e)
  File "/Users/mnann/Documents/Code/PulseFi/venv/lib/python3.8/site-packages/flask/app.py", line 1823, in full_dispatch_request
    rv = self.dispatch_request()
  File "/Users/mnann/Documents/Code/PulseFi/venv/lib/python3.8/site-packages/flask/app.py", line 1799, in dispatch_request
    return self.ensure_sync(self.view_functions[rule.endpoint])(**view_args)
  File "/Users/mnann/Documents/Code/PulseFi/src/data/callbacks.py", line 175, in heartRate
    df_heartRate = self.requestMultipleDays()
  File "/Users/mnann/Documents/Code/PulseFi/src/data/callbacks.py", line 111, in requestMultipleDays
    oneDayData = self.auth2_client.intraday_time_series('activities/heart', base_date=oneDate, detail_level='1sec')
AttributeError: 'NoneType' object has no attribute 'intraday_time_series'
2023-04-11 13:43:19,121 INFO: errors [in /Users/mnann/Documents/Code/PulseFi/src/flaskServer/app.py:154]
2023-04-11 13:43:23,133 ERROR: Exception on /authorize [GET] [in /Users/mnann/Documents/Code/PulseFi/venv/lib/python3.8/site-packages/flask/app.py:1744]
Traceback (most recent call last):
  File "/Users/mnann/Documents/Code/PulseFi/venv/lib/python3.8/site-packages/flask/app.py", line 2528, in wsgi_app
    response = self.full_dispatch_request()
  File "/Users/mnann/Documents/Code/PulseFi/venv/lib/python3.8/site-packages/flask/app.py", line 1825, in full_dispatch_request
    rv = self.handle_user_exception(e)
  File "/Users/mnann/Documents/Code/PulseFi/venv/lib/python3.8/site-packages/flask/app.py", line 1823, in full_dispatch_request
    rv = self.dispatch_request()
  File "/Users/mnann/Documents/Code/PulseFi/venv/lib/python3.8/site-packages/flask/app.py", line 1799, in dispatch_request
    return self.ensure_sync(self.view_functions[rule.endpoint])(**view_args)
  File "/Users/mnann/Documents/Code/PulseFi/src/data/callbacks.py", line 136, in fitbit_auth
    state = requests.args.get('state')
AttributeError: module 'requests' has no attribute 'args'
2023-04-11 13:43:41,632 ERROR: Exception on /heartRate [GET] [in /Users/mnann/Documents/Code/PulseFi/venv/lib/python3.8/site-packages/flask/app.py:1744]
Traceback (most recent call last):
  File "/Users/mnann/Documents/Code/PulseFi/venv/lib/python3.8/site-packages/flask/app.py", line 2528, in wsgi_app
    response = self.full_dispatch_request()
  File "/Users/mnann/Documents/Code/PulseFi/venv/lib/python3.8/site-packages/flask/app.py", line 1825, in full_dispatch_request
    rv = self.handle_user_exception(e)
  File "/Users/mnann/Documents/Code/PulseFi/venv/lib/python3.8/site-packages/flask/app.py", line 1823, in full_dispatch_request
    rv = self.dispatch_request()
  File "/Users/mnann/Documents/Code/PulseFi/venv/lib/python3.8/site-packages/flask/app.py", line 1799, in dispatch_request
    return self.ensure_sync(self.view_functions[rule.endpoint])(**view_args)
  File "/Users/mnann/Documents/Code/PulseFi/src/data/callbacks.py", line 174, in heartRate
    self.authorize()
  File "/Users/mnann/Documents/Code/PulseFi/src/data/callbacks.py", line 97, in authorize
    self.auth2_client=Fitbit(self.client_id,self.client_secret,oauth2=True,access_token=self.ACCESS_TOKEN,refresh_token=self.REFRESH_TOKEN)
AttributeError: 'FitbitAuth' object has no attribute 'ACCESS_TOKEN'
2023-04-11 13:47:50,260 INFO: errors [in /Users/mnann/Documents/Code/PulseFi/src/flaskServer/app.py:154]
2023-04-11 14:16:00,615 INFO: errors [in /Users/mnann/Documents/Code/PulseFi/src/flaskServer/app.py:152]
2023-04-11 14:16:04,078 ERROR: Exception on /heartRate [GET] [in /Users/mnann/Documents/Code/PulseFi/venv/lib/python3.8/site-packages/flask/app.py:1744]
Traceback (most recent call last):
  File "/Users/mnann/Documents/Code/PulseFi/venv/lib/python3.8/site-packages/flask/app.py", line 2528, in wsgi_app
    response = self.full_dispatch_request()
  File "/Users/mnann/Documents/Code/PulseFi/venv/lib/python3.8/site-packages/flask/app.py", line 1825, in full_dispatch_request
    rv = self.handle_user_exception(e)
  File "/Users/mnann/Documents/Code/PulseFi/venv/lib/python3.8/site-packages/flask/app.py", line 1823, in full_dispatch_request
    rv = self.dispatch_request()
  File "/Users/mnann/Documents/Code/PulseFi/venv/lib/python3.8/site-packages/flask/app.py", line 1799, in dispatch_request
    return self.ensure_sync(self.view_functions[rule.endpoint])(**view_args)
  File "/Users/mnann/Documents/Code/PulseFi/src/data/callbacks.py", line 192, in heartRate
    df_heartRate = self.requestMultipleDays()
  File "/Users/mnann/Documents/Code/PulseFi/src/data/callbacks.py", line 145, in requestMultipleDays
    oneDayData = self.auth2_client.intraday_time_series('activities/heart', base_date=oneDate, detail_level='1sec')
AttributeError: 'NoneType' object has no attribute 'intraday_time_series'
2023-04-11 14:16:36,257 INFO: errors [in /Users/mnann/Documents/Code/PulseFi/src/flaskServer/app.py:152]
2023-04-11 14:16:39,048 ERROR: Exception on /heartRate [GET] [in /Users/mnann/Documents/Code/PulseFi/venv/lib/python3.8/site-packages/flask/app.py:1744]
Traceback (most recent call last):
  File "/Users/mnann/Documents/Code/PulseFi/venv/lib/python3.8/site-packages/flask/app.py", line 2528, in wsgi_app
    response = self.full_dispatch_request()
  File "/Users/mnann/Documents/Code/PulseFi/venv/lib/python3.8/site-packages/flask/app.py", line 1825, in full_dispatch_request
    rv = self.handle_user_exception(e)
  File "/Users/mnann/Documents/Code/PulseFi/venv/lib/python3.8/site-packages/flask/app.py", line 1823, in full_dispatch_request
    rv = self.dispatch_request()
  File "/Users/mnann/Documents/Code/PulseFi/venv/lib/python3.8/site-packages/flask/app.py", line 1799, in dispatch_request
    return self.ensure_sync(self.view_functions[rule.endpoint])(**view_args)
  File "/Users/mnann/Documents/Code/PulseFi/src/data/callbacks.py", line 193, in heartRate
    df_heartRate = self.requestMultipleDays()
  File "/Users/mnann/Documents/Code/PulseFi/src/data/callbacks.py", line 146, in requestMultipleDays
    oneDayData = self.auth2_client.intraday_time_series('activities/heart', base_date=oneDate, detail_level='1sec')
AttributeError: 'NoneType' object has no attribute 'intraday_time_series'
2023-04-11 14:16:48,763 ERROR: Exception on /heartRate [GET] [in /Users/mnann/Documents/Code/PulseFi/venv/lib/python3.8/site-packages/flask/app.py:1744]
Traceback (most recent call last):
  File "/Users/mnann/Documents/Code/PulseFi/venv/lib/python3.8/site-packages/flask/app.py", line 2528, in wsgi_app
    response = self.full_dispatch_request()
  File "/Users/mnann/Documents/Code/PulseFi/venv/lib/python3.8/site-packages/flask/app.py", line 1825, in full_dispatch_request
    rv = self.handle_user_exception(e)
  File "/Users/mnann/Documents/Code/PulseFi/venv/lib/python3.8/site-packages/flask/app.py", line 1823, in full_dispatch_request
    rv = self.dispatch_request()
  File "/Users/mnann/Documents/Code/PulseFi/venv/lib/python3.8/site-packages/flask/app.py", line 1799, in dispatch_request
    return self.ensure_sync(self.view_functions[rule.endpoint])(**view_args)
  File "/Users/mnann/Documents/Code/PulseFi/src/data/callbacks.py", line 193, in heartRate
    df_heartRate = self.requestMultipleDays()
  File "/Users/mnann/Documents/Code/PulseFi/src/data/callbacks.py", line 146, in requestMultipleDays
    oneDayData = self.auth2_client.intraday_time_series('activities/heart', base_date=oneDate, detail_level='1sec')
AttributeError: 'NoneType' object has no attribute 'intraday_time_series'
2023-04-11 14:17:58,656 INFO: errors [in /Users/mnann/Documents/Code/PulseFi/src/flaskServer/app.py:152]
2023-04-11 14:18:01,634 ERROR: Exception on /heartRate [GET] [in /Users/mnann/Documents/Code/PulseFi/venv/lib/python3.8/site-packages/flask/app.py:1744]
Traceback (most recent call last):
  File "/Users/mnann/Documents/Code/PulseFi/venv/lib/python3.8/site-packages/flask/app.py", line 2528, in wsgi_app
    response = self.full_dispatch_request()
  File "/Users/mnann/Documents/Code/PulseFi/venv/lib/python3.8/site-packages/flask/app.py", line 1825, in full_dispatch_request
    rv = self.handle_user_exception(e)
  File "/Users/mnann/Documents/Code/PulseFi/venv/lib/python3.8/site-packages/flask/app.py", line 1823, in full_dispatch_request
    rv = self.dispatch_request()
  File "/Users/mnann/Documents/Code/PulseFi/venv/lib/python3.8/site-packages/flask/app.py", line 1799, in dispatch_request
    return self.ensure_sync(self.view_functions[rule.endpoint])(**view_args)
  File "/Users/mnann/Documents/Code/PulseFi/src/data/callbacks.py", line 200, in heartRate
    df_heartRate = self.requestMultipleDays()
  File "/Users/mnann/Documents/Code/PulseFi/src/data/callbacks.py", line 146, in requestMultipleDays
    oneDayData = self.auth2_client.intraday_time_series('activities/heart', base_date=oneDate, detail_level='1sec')
AttributeError: 'NoneType' object has no attribute 'intraday_time_series'
2023-04-11 14:18:22,520 INFO: errors [in /Users/mnann/Documents/Code/PulseFi/src/flaskServer/app.py:152]
2023-04-11 14:18:26,889 ERROR: Exception on /heartRate [GET] [in /Users/mnann/Documents/Code/PulseFi/venv/lib/python3.8/site-packages/flask/app.py:1744]
Traceback (most recent call last):
  File "/Users/mnann/Documents/Code/PulseFi/venv/lib/python3.8/site-packages/flask/app.py", line 2528, in wsgi_app
    response = self.full_dispatch_request()
  File "/Users/mnann/Documents/Code/PulseFi/venv/lib/python3.8/site-packages/flask/app.py", line 1825, in full_dispatch_request
    rv = self.handle_user_exception(e)
  File "/Users/mnann/Documents/Code/PulseFi/venv/lib/python3.8/site-packages/flask/app.py", line 1823, in full_dispatch_request
    rv = self.dispatch_request()
  File "/Users/mnann/Documents/Code/PulseFi/venv/lib/python3.8/site-packages/flask/app.py", line 1799, in dispatch_request
    return self.ensure_sync(self.view_functions[rule.endpoint])(**view_args)
  File "/Users/mnann/Documents/Code/PulseFi/src/data/callbacks.py", line 201, in heartRate
    df_heartRate = self.requestMultipleDays()
  File "/Users/mnann/Documents/Code/PulseFi/src/data/callbacks.py", line 146, in requestMultipleDays
    oneDayData = self.auth2_client.intraday_time_series('activities/heart', base_date=oneDate, detail_level='1sec')
AttributeError: 'NoneType' object has no attribute 'intraday_time_series'
2023-04-11 14:20:41,706 INFO: errors [in /Users/mnann/Documents/Code/PulseFi/src/flaskServer/app.py:152]
2023-04-11 14:21:41,729 INFO: errors [in /Users/mnann/Documents/Code/PulseFi/src/flaskServer/app.py:152]
2023-04-11 14:29:53,959 INFO: errors [in /Users/mnann/Documents/Code/PulseFi/src/flaskServer/app.py:152]
2023-04-11 14:32:28,171 INFO: errors [in /Users/mnann/Documents/Code/PulseFi/src/flaskServer/app.py:152]
2023-04-11 14:32:32,475 ERROR: Exception on /('https://www.fitbit.com/oauth2/authorize [GET] [in /Users/mnann/Documents/Code/PulseFi/venv/lib/python3.8/site-packages/flask/app.py:1744]
Traceback (most recent call last):
  File "/Users/mnann/Documents/Code/PulseFi/venv/lib/python3.8/site-packages/flask/app.py", line 1823, in full_dispatch_request
    rv = self.dispatch_request()
  File "/Users/mnann/Documents/Code/PulseFi/venv/lib/python3.8/site-packages/flask/app.py", line 1788, in dispatch_request
    self.raise_routing_exception(req)
  File "/Users/mnann/Documents/Code/PulseFi/venv/lib/python3.8/site-packages/flask/app.py", line 1770, in raise_routing_exception
    raise request.routing_exception  # type: ignore
  File "/Users/mnann/Documents/Code/PulseFi/venv/lib/python3.8/site-packages/flask/ctx.py", line 351, in match_request
    result = self.url_adapter.match(return_rule=True)  # type: ignore
  File "/Users/mnann/Documents/Code/PulseFi/venv/lib/python3.8/site-packages/werkzeug/routing/map.py", line 624, in match
    raise NotFound() from None
werkzeug.exceptions.NotFound: 404 Not Found: The requested URL was not found on the server. If you entered the URL manually please check your spelling and try again.

During handling of the above exception, another exception occurred:

Traceback (most recent call last):
  File "/Users/mnann/Documents/Code/PulseFi/venv/lib/python3.8/site-packages/flask/app.py", line 2528, in wsgi_app
    response = self.full_dispatch_request()
  File "/Users/mnann/Documents/Code/PulseFi/venv/lib/python3.8/site-packages/flask/app.py", line 1825, in full_dispatch_request
    rv = self.handle_user_exception(e)
  File "/Users/mnann/Documents/Code/PulseFi/venv/lib/python3.8/site-packages/flask/app.py", line 1669, in handle_user_exception
    return self.handle_http_exception(e)
  File "/Users/mnann/Documents/Code/PulseFi/venv/lib/python3.8/site-packages/flask/app.py", line 1609, in handle_http_exception
    return self.ensure_sync(handler)(e)
  File "/Users/mnann/Documents/Code/PulseFi/src/flaskServer/app.py", line 135, in not_found_error
    return render_template('errors/404.html'), 404
  File "/Users/mnann/Documents/Code/PulseFi/venv/lib/python3.8/site-packages/flask/templating.py", line 147, in render_template
    return _render(app, template, context)
  File "/Users/mnann/Documents/Code/PulseFi/venv/lib/python3.8/site-packages/flask/templating.py", line 130, in _render
    rv = template.render(context)
  File "/Users/mnann/Documents/Code/PulseFi/venv/lib/python3.8/site-packages/jinja2/environment.py", line 1301, in render
    self.environment.handle_exception()
  File "/Users/mnann/Documents/Code/PulseFi/venv/lib/python3.8/site-packages/jinja2/environment.py", line 936, in handle_exception
    raise rewrite_traceback_stack(source=source)
  File "/Users/mnann/Documents/Code/PulseFi/src/flaskServer/templates/errors/404.html", line 1, in top-level template code
    {% extends 'layouts/main.html' %}
  File "/Users/mnann/Documents/Code/PulseFi/src/flaskServer/templates/layouts/main.html", line 99, in top-level template code
    {% block content %}{% endblock %}
  File "/Users/mnann/Documents/Code/PulseFi/src/flaskServer/templates/errors/404.html", line 5, in block 'content'
    <p><a href="{{url_for('index')}}">Back</a></p>
  File "/Users/mnann/Documents/Code/PulseFi/venv/lib/python3.8/site-packages/flask/app.py", line 2034, in url_for
    return self.handle_url_build_error(error, endpoint, values)
  File "/Users/mnann/Documents/Code/PulseFi/venv/lib/python3.8/site-packages/flask/app.py", line 2023, in url_for
    rv = url_adapter.build(  # type: ignore[union-attr]
  File "/Users/mnann/Documents/Code/PulseFi/venv/lib/python3.8/site-packages/werkzeug/routing/map.py", line 917, in build
    raise BuildError(endpoint, values, method, self)
werkzeug.routing.exceptions.BuildError: Could not build url for endpoint 'index'. Did you mean 'login' instead?
2023-04-11 14:34:03,070 INFO: errors [in /Users/mnann/Documents/Code/PulseFi/src/flaskServer/app.py:152]
2023-04-11 14:34:36,143 ERROR: Exception on /favicon.ico [GET] [in /Users/mnann/Documents/Code/PulseFi/venv/lib/python3.8/site-packages/flask/app.py:1744]
Traceback (most recent call last):
  File "/Users/mnann/Documents/Code/PulseFi/venv/lib/python3.8/site-packages/flask/app.py", line 1823, in full_dispatch_request
    rv = self.dispatch_request()
  File "/Users/mnann/Documents/Code/PulseFi/venv/lib/python3.8/site-packages/flask/app.py", line 1788, in dispatch_request
    self.raise_routing_exception(req)
  File "/Users/mnann/Documents/Code/PulseFi/venv/lib/python3.8/site-packages/flask/app.py", line 1770, in raise_routing_exception
    raise request.routing_exception  # type: ignore
  File "/Users/mnann/Documents/Code/PulseFi/venv/lib/python3.8/site-packages/flask/ctx.py", line 351, in match_request
    result = self.url_adapter.match(return_rule=True)  # type: ignore
  File "/Users/mnann/Documents/Code/PulseFi/venv/lib/python3.8/site-packages/werkzeug/routing/map.py", line 624, in match
    raise NotFound() from None
werkzeug.exceptions.NotFound: 404 Not Found: The requested URL was not found on the server. If you entered the URL manually please check your spelling and try again.

During handling of the above exception, another exception occurred:

Traceback (most recent call last):
  File "/Users/mnann/Documents/Code/PulseFi/venv/lib/python3.8/site-packages/flask/app.py", line 2528, in wsgi_app
    response = self.full_dispatch_request()
  File "/Users/mnann/Documents/Code/PulseFi/venv/lib/python3.8/site-packages/flask/app.py", line 1825, in full_dispatch_request
    rv = self.handle_user_exception(e)
  File "/Users/mnann/Documents/Code/PulseFi/venv/lib/python3.8/site-packages/flask/app.py", line 1669, in handle_user_exception
    return self.handle_http_exception(e)
  File "/Users/mnann/Documents/Code/PulseFi/venv/lib/python3.8/site-packages/flask/app.py", line 1609, in handle_http_exception
    return self.ensure_sync(handler)(e)
  File "/Users/mnann/Documents/Code/PulseFi/src/flaskServer/app.py", line 135, in not_found_error
    return render_template('errors/404.html'), 404
  File "/Users/mnann/Documents/Code/PulseFi/venv/lib/python3.8/site-packages/flask/templating.py", line 147, in render_template
    return _render(app, template, context)
  File "/Users/mnann/Documents/Code/PulseFi/venv/lib/python3.8/site-packages/flask/templating.py", line 130, in _render
    rv = template.render(context)
  File "/Users/mnann/Documents/Code/PulseFi/venv/lib/python3.8/site-packages/jinja2/environment.py", line 1301, in render
    self.environment.handle_exception()
  File "/Users/mnann/Documents/Code/PulseFi/venv/lib/python3.8/site-packages/jinja2/environment.py", line 936, in handle_exception
    raise rewrite_traceback_stack(source=source)
  File "/Users/mnann/Documents/Code/PulseFi/src/flaskServer/templates/errors/404.html", line 1, in top-level template code
    {% extends 'layouts/main.html' %}
  File "/Users/mnann/Documents/Code/PulseFi/src/flaskServer/templates/layouts/main.html", line 99, in top-level template code
    {% block content %}{% endblock %}
  File "/Users/mnann/Documents/Code/PulseFi/src/flaskServer/templates/errors/404.html", line 5, in block 'content'
    <p><a href="{{url_for('index')}}">Back</a></p>
  File "/Users/mnann/Documents/Code/PulseFi/venv/lib/python3.8/site-packages/flask/app.py", line 2034, in url_for
    return self.handle_url_build_error(error, endpoint, values)
  File "/Users/mnann/Documents/Code/PulseFi/venv/lib/python3.8/site-packages/flask/app.py", line 2023, in url_for
    rv = url_adapter.build(  # type: ignore[union-attr]
  File "/Users/mnann/Documents/Code/PulseFi/venv/lib/python3.8/site-packages/werkzeug/routing/map.py", line 917, in build
    raise BuildError(endpoint, values, method, self)
werkzeug.routing.exceptions.BuildError: Could not build url for endpoint 'index'. Did you mean 'login' instead?
2023-04-11 14:35:00,570 INFO: errors [in /Users/mnann/Documents/Code/PulseFi/src/flaskServer/app.py:152]
2023-04-11 17:04:09,150 INFO: errors [in /Users/mnann/Documents/Code/PulseFi/src/flaskServer/app.py:157]
2023-04-11 17:04:45,726 INFO: errors [in /Users/mnann/Documents/Code/PulseFi/src/flaskServer/app.py:157]
2023-04-11 17:06:20,392 INFO: errors [in /Users/mnann/Documents/Code/PulseFi/src/flaskServer/app.py:157]
2023-04-11 17:06:27,744 ERROR: Exception on /authorize_spotify [GET] [in /Users/mnann/Documents/Code/PulseFi/venv/lib/python3.8/site-packages/flask/app.py:1744]
Traceback (most recent call last):
  File "/Users/mnann/Documents/Code/PulseFi/venv/lib/python3.8/site-packages/flask/app.py", line 2528, in wsgi_app
    response = self.full_dispatch_request()
  File "/Users/mnann/Documents/Code/PulseFi/venv/lib/python3.8/site-packages/flask/app.py", line 1826, in full_dispatch_request
    return self.finalize_request(rv)
  File "/Users/mnann/Documents/Code/PulseFi/venv/lib/python3.8/site-packages/flask/app.py", line 1845, in finalize_request
    response = self.make_response(rv)
  File "/Users/mnann/Documents/Code/PulseFi/venv/lib/python3.8/site-packages/flask/app.py", line 2137, in make_response
    raise TypeError(
TypeError: The view function for 'authorize_spotify' did not return a valid response. The function either returned None or ended without a return statement.
2023-04-11 17:06:27,790 ERROR: Exception on /recentlyPlayed [GET] [in /Users/mnann/Documents/Code/PulseFi/venv/lib/python3.8/site-packages/flask/app.py:1744]
Traceback (most recent call last):
  File "/Users/mnann/Documents/Code/PulseFi/venv/lib/python3.8/site-packages/flask/app.py", line 2528, in wsgi_app
    response = self.full_dispatch_request()
  File "/Users/mnann/Documents/Code/PulseFi/venv/lib/python3.8/site-packages/flask/app.py", line 1825, in full_dispatch_request
    rv = self.handle_user_exception(e)
  File "/Users/mnann/Documents/Code/PulseFi/venv/lib/python3.8/site-packages/flask/app.py", line 1823, in full_dispatch_request
    rv = self.dispatch_request()
  File "/Users/mnann/Documents/Code/PulseFi/venv/lib/python3.8/site-packages/flask/app.py", line 1799, in dispatch_request
    return self.ensure_sync(self.view_functions[rule.endpoint])(**view_args)
  File "/Users/mnann/Documents/Code/PulseFi/src/data/spotifyData.py", line 91, in recentlyPlayed
    return self.recentlyPlayed().to_html()
  File "/Users/mnann/Documents/Code/PulseFi/src/data/spotifyData.py", line 57, in recentlyPlayed
    results = self.sp.current_user_recently_played(limit=50)
  File "/Users/mnann/Documents/Code/PulseFi/venv/lib/python3.8/site-packages/spotipy/client.py", line 1496, in current_user_recently_played
    return self._get(
  File "/Users/mnann/Documents/Code/PulseFi/venv/lib/python3.8/site-packages/spotipy/client.py", line 321, in _get
    return self._internal_call("GET", url, payload, kwargs)
  File "/Users/mnann/Documents/Code/PulseFi/venv/lib/python3.8/site-packages/spotipy/client.py", line 245, in _internal_call
    headers = self._auth_headers()
  File "/Users/mnann/Documents/Code/PulseFi/venv/lib/python3.8/site-packages/spotipy/client.py", line 236, in _auth_headers
    token = self.auth_manager.get_access_token(as_dict=False)
  File "/Users/mnann/Documents/Code/PulseFi/venv/lib/python3.8/site-packages/spotipy/oauth2.py", line 535, in get_access_token
    "code": code or self.get_auth_response(),
  File "/Users/mnann/Documents/Code/PulseFi/venv/lib/python3.8/site-packages/spotipy/oauth2.py", line 490, in get_auth_response
    return self._get_auth_response_local_server(redirect_port)
  File "/Users/mnann/Documents/Code/PulseFi/venv/lib/python3.8/site-packages/spotipy/oauth2.py", line 468, in _get_auth_response_local_server
    raise SpotifyOauthError("Server listening on localhost has not been accessed")
spotipy.oauth2.SpotifyOauthError: Server listening on localhost has not been accessed
2023-04-11 17:08:02,990 INFO: errors [in /Users/mnann/Documents/Code/PulseFi/src/flaskServer/app.py:157]
2023-04-11 17:08:10,374 ERROR: Exception on /recentlyPlayed [GET] [in /Users/mnann/Documents/Code/PulseFi/venv/lib/python3.8/site-packages/flask/app.py:1744]
Traceback (most recent call last):
  File "/Users/mnann/Documents/Code/PulseFi/venv/lib/python3.8/site-packages/flask/app.py", line 2528, in wsgi_app
    response = self.full_dispatch_request()
  File "/Users/mnann/Documents/Code/PulseFi/venv/lib/python3.8/site-packages/flask/app.py", line 1825, in full_dispatch_request
    rv = self.handle_user_exception(e)
  File "/Users/mnann/Documents/Code/PulseFi/venv/lib/python3.8/site-packages/flask/app.py", line 1823, in full_dispatch_request
    rv = self.dispatch_request()
  File "/Users/mnann/Documents/Code/PulseFi/venv/lib/python3.8/site-packages/flask/app.py", line 1799, in dispatch_request
    return self.ensure_sync(self.view_functions[rule.endpoint])(**view_args)
  File "/Users/mnann/Documents/Code/PulseFi/src/data/spotifyData.py", line 91, in recentlyPlayed
    return self.recentlyPlayed().to_html()
  File "/Users/mnann/Documents/Code/PulseFi/src/data/spotifyData.py", line 57, in recentlyPlayed
    results = self.sp.current_user_recently_played(limit=50)
  File "/Users/mnann/Documents/Code/PulseFi/venv/lib/python3.8/site-packages/spotipy/client.py", line 1496, in current_user_recently_played
    return self._get(
  File "/Users/mnann/Documents/Code/PulseFi/venv/lib/python3.8/site-packages/spotipy/client.py", line 321, in _get
    return self._internal_call("GET", url, payload, kwargs)
  File "/Users/mnann/Documents/Code/PulseFi/venv/lib/python3.8/site-packages/spotipy/client.py", line 245, in _internal_call
    headers = self._auth_headers()
  File "/Users/mnann/Documents/Code/PulseFi/venv/lib/python3.8/site-packages/spotipy/client.py", line 236, in _auth_headers
    token = self.auth_manager.get_access_token(as_dict=False)
  File "/Users/mnann/Documents/Code/PulseFi/venv/lib/python3.8/site-packages/spotipy/oauth2.py", line 535, in get_access_token
    "code": code or self.get_auth_response(),
  File "/Users/mnann/Documents/Code/PulseFi/venv/lib/python3.8/site-packages/spotipy/oauth2.py", line 490, in get_auth_response
    return self._get_auth_response_local_server(redirect_port)
  File "/Users/mnann/Documents/Code/PulseFi/venv/lib/python3.8/site-packages/spotipy/oauth2.py", line 468, in _get_auth_response_local_server
    raise SpotifyOauthError("Server listening on localhost has not been accessed")
spotipy.oauth2.SpotifyOauthError: Server listening on localhost has not been accessed
2023-04-11 17:09:24,649 INFO: errors [in /Users/mnann/Documents/Code/PulseFi/src/flaskServer/app.py:157]
2023-04-11 17:09:30,277 ERROR: Exception on /recentlyPlayed [GET] [in /Users/mnann/Documents/Code/PulseFi/venv/lib/python3.8/site-packages/flask/app.py:1744]
Traceback (most recent call last):
  File "/Users/mnann/Documents/Code/PulseFi/venv/lib/python3.8/site-packages/flask/app.py", line 2528, in wsgi_app
    response = self.full_dispatch_request()
  File "/Users/mnann/Documents/Code/PulseFi/venv/lib/python3.8/site-packages/flask/app.py", line 1825, in full_dispatch_request
    rv = self.handle_user_exception(e)
  File "/Users/mnann/Documents/Code/PulseFi/venv/lib/python3.8/site-packages/flask/app.py", line 1823, in full_dispatch_request
    rv = self.dispatch_request()
  File "/Users/mnann/Documents/Code/PulseFi/venv/lib/python3.8/site-packages/flask/app.py", line 1799, in dispatch_request
    return self.ensure_sync(self.view_functions[rule.endpoint])(**view_args)
  File "/Users/mnann/Documents/Code/PulseFi/src/data/spotifyData.py", line 92, in recentlyPlayed
    return self.recentlyPlayed().to_html()
  File "/Users/mnann/Documents/Code/PulseFi/src/data/spotifyData.py", line 58, in recentlyPlayed
    results = self.sp.current_user_recently_played(limit=50)
  File "/Users/mnann/Documents/Code/PulseFi/venv/lib/python3.8/site-packages/spotipy/client.py", line 1496, in current_user_recently_played
    return self._get(
  File "/Users/mnann/Documents/Code/PulseFi/venv/lib/python3.8/site-packages/spotipy/client.py", line 321, in _get
    return self._internal_call("GET", url, payload, kwargs)
  File "/Users/mnann/Documents/Code/PulseFi/venv/lib/python3.8/site-packages/spotipy/client.py", line 245, in _internal_call
    headers = self._auth_headers()
  File "/Users/mnann/Documents/Code/PulseFi/venv/lib/python3.8/site-packages/spotipy/client.py", line 236, in _auth_headers
    token = self.auth_manager.get_access_token(as_dict=False)
  File "/Users/mnann/Documents/Code/PulseFi/venv/lib/python3.8/site-packages/spotipy/oauth2.py", line 535, in get_access_token
    "code": code or self.get_auth_response(),
  File "/Users/mnann/Documents/Code/PulseFi/venv/lib/python3.8/site-packages/spotipy/oauth2.py", line 490, in get_auth_response
    return self._get_auth_response_local_server(redirect_port)
  File "/Users/mnann/Documents/Code/PulseFi/venv/lib/python3.8/site-packages/spotipy/oauth2.py", line 468, in _get_auth_response_local_server
    raise SpotifyOauthError("Server listening on localhost has not been accessed")
spotipy.oauth2.SpotifyOauthError: Server listening on localhost has not been accessed
2023-04-11 17:13:11,577 INFO: errors [in /Users/mnann/Documents/Code/PulseFi/src/flaskServer/app.py:157]
2023-04-11 17:13:14,526 ERROR: Exception on /recentlyPlayed [GET] [in /Users/mnann/Documents/Code/PulseFi/venv/lib/python3.8/site-packages/flask/app.py:1744]
Traceback (most recent call last):
  File "/Users/mnann/Documents/Code/PulseFi/venv/lib/python3.8/site-packages/flask/app.py", line 2528, in wsgi_app
    response = self.full_dispatch_request()
  File "/Users/mnann/Documents/Code/PulseFi/venv/lib/python3.8/site-packages/flask/app.py", line 1825, in full_dispatch_request
    rv = self.handle_user_exception(e)
  File "/Users/mnann/Documents/Code/PulseFi/venv/lib/python3.8/site-packages/flask/app.py", line 1823, in full_dispatch_request
    rv = self.dispatch_request()
  File "/Users/mnann/Documents/Code/PulseFi/venv/lib/python3.8/site-packages/flask/app.py", line 1799, in dispatch_request
    return self.ensure_sync(self.view_functions[rule.endpoint])(**view_args)
  File "/Users/mnann/Documents/Code/PulseFi/src/data/spotifyData.py", line 93, in recentlyPlayed
    return self.recentlyPlayed().to_html()
  File "/Users/mnann/Documents/Code/PulseFi/src/data/spotifyData.py", line 59, in recentlyPlayed
    results = self.sp.current_user_recently_played(limit=50)
  File "/Users/mnann/Documents/Code/PulseFi/venv/lib/python3.8/site-packages/spotipy/client.py", line 1496, in current_user_recently_played
    return self._get(
  File "/Users/mnann/Documents/Code/PulseFi/venv/lib/python3.8/site-packages/spotipy/client.py", line 321, in _get
    return self._internal_call("GET", url, payload, kwargs)
  File "/Users/mnann/Documents/Code/PulseFi/venv/lib/python3.8/site-packages/spotipy/client.py", line 245, in _internal_call
    headers = self._auth_headers()
  File "/Users/mnann/Documents/Code/PulseFi/venv/lib/python3.8/site-packages/spotipy/client.py", line 236, in _auth_headers
    token = self.auth_manager.get_access_token(as_dict=False)
  File "/Users/mnann/Documents/Code/PulseFi/venv/lib/python3.8/site-packages/spotipy/oauth2.py", line 535, in get_access_token
    "code": code or self.get_auth_response(),
  File "/Users/mnann/Documents/Code/PulseFi/venv/lib/python3.8/site-packages/spotipy/oauth2.py", line 490, in get_auth_response
    return self._get_auth_response_local_server(redirect_port)
  File "/Users/mnann/Documents/Code/PulseFi/venv/lib/python3.8/site-packages/spotipy/oauth2.py", line 468, in _get_auth_response_local_server
    raise SpotifyOauthError("Server listening on localhost has not been accessed")
spotipy.oauth2.SpotifyOauthError: Server listening on localhost has not been accessed
2023-04-11 17:17:28,048 INFO: errors [in /Users/mnann/Documents/Code/PulseFi/src/flaskServer/app.py:157]
2023-04-11 17:18:17,112 INFO: errors [in /Users/mnann/Documents/Code/PulseFi/src/flaskServer/app.py:157]
2023-04-11 17:18:38,799 INFO: errors [in /Users/mnann/Documents/Code/PulseFi/src/flaskServer/app.py:157]
2023-04-11 17:19:11,856 INFO: errors [in /Users/mnann/Documents/Code/PulseFi/src/flaskServer/app.py:157]
2023-04-11 17:20:33,675 INFO: errors [in /Users/mnann/Documents/Code/PulseFi/src/flaskServer/app.py:157]
2023-04-11 17:20:50,143 INFO: errors [in /Users/mnann/Documents/Code/PulseFi/src/flaskServer/app.py:157]
2023-04-11 17:29:50,099 INFO: errors [in /Users/mnann/Documents/Code/PulseFi/src/flaskServer/app.py:158]
